Workbook

Sheet Léeme
B2: LafroX — Carta Gantt del Subdocumento 7 (Formulario T-14)
B3: Licitación TFEP-01/2026, Caso 02 — Logística, Distribuidora Puelche S.A. Versión del 9 de octubre de 2026, generada desde el Formulario T-14 (EDT y carta Gantt, sección 3.1) y el Formulario T-15 (programación por paquete, secciones 4.2, 5 y 6).
B4: 1. Qué es una carta Gantt
B5: Una carta Gantt es un cronograma dibujado como barras sobre una línea de tiempo: cada fila es un trabajo y cada barra muestra cuándo empieza y cuándo termina. Sirve para ver de un vistazo qué se hace en paralelo, qué viene después de qué y cuánto falta para cada fecha comprometida. No muestra por sí sola las dependencias entre trabajos ni las horas: esos datos están en las hojas «Gantt paquetes» y «Actividades hasta H2».
B6: 2. Cómo está organizada esta planilla
B7: • Parámetros: la fecha de inicio del contrato (supuesto: febrero de 2027). Es la única celda que se edita; todas las fechas de la planilla se recalculan a partir de ella.
B8: • Períodos Art. 17: los períodos contractuales fijos de las Bases Administrativas (desarrollo, marcha blanca, producción y operación de cada etapa).
B9: • Hitos: los doce hitos del Formulario E-25, con su mes contractual, su fecha calendario, la fecha en que LafroX entrega, la fecha límite para que el CLIENTE alcance a revisar y la reserva entre ambas.
B10: • Gantt cuentas: la carta Gantt resumida, una fila por cuenta de control (49 filas), sobre los 56 meses del contrato.
B11: • Gantt paquetes: la carta Gantt detallada, una fila por paquete de trabajo de la EDT (222 filas), con su clase, su responsable y sus horas hombre.
B12: • Actividades hasta H2: las 108 actividades de los paquetes que terminan hasta el H2 (mes 4), con personas, horas, fechas y predecesoras. Los demás paquetes tienen fecha en la hoja «Gantt paquetes» y se detallan en actividades por planificación gradual antes de cada fase (H2, H4, H8 y H9).
B13: • Glosario: la definición de cada término usado (hito, cuenta de control, paquete, actividad, marcha blanca, reserva, P80, etc.).
... B27: • Texto azul sobre fondo amarillo: dato que se puede editar (sólo la fecha de inicio). Texto negro: fórmula o dato tomado de los formularios. Fondo naranja claro en la fila de meses: mes de congelamiento.

Sheet Parámetros
A1: Parámetros de la planilla
A3: Fecha de inicio del contrato (mes 1) | B3: 46419 | C3: Supuesto de calendario del SD7, Anexo 7.A: inicio en febrero de 2027. Editar sólo esta celda; debe ser un día 1 de mes.
A4: Días hábiles de revisión del CLIENTE | B4: 10 | C4: Bases Administrativas, Art. 18.3: el CLIENTE dispone de diez días hábiles para revisar cada entregable.
A5: Duración del contrato (meses) | B5: 56 | C5: Bases Administrativas, Art. 17°.

Sheet Hitos
A1: Hito | B1: Descripción y entregable que lo gatilla (Formulario E-25) | C1: Etapa | D1: Mes contractual | E1: Mes calendario | F1: % de pago (sobre la implementación) | G1: Paquetes que lo gatillan | H1: Entrega programada de LafroX | I1: Fecha límite de entrega (último día hábil del mes − revisión) | J1: Reserva (días hábiles) | K1: Probabilidad de entrega a tiempo (simulación SD8) | L1: Fecha P80 simulada | M1: Día hábil n.º de la entrega (dato del T-15)
A2: H1 | B2: Cierre del levantamiento y aprobación de la línea base de alcance y de la matriz de trazabilidad de requerimientos. | C2: Etapa 1 | D2: 2 | E2: =EDATE('Parámetros'!$B$3,D2-1) | F2: 0.08 | G2: 1.2.1, 1.2.4 | H2: =WORKDAY('Parámetros'!$B$3-1,M2+1) | I2: =WORKDAY(EOMONTH(E2,0)+1,-1-'Parámetros'!$B$4) | J2: =NETWORKDAYS(H2,I2)-1 | K2: 1 | L2: =WORKDAY('Parámetros'!$B$3-1,29) | M2: 26
A3: H2 | B3: Aprobación del documento de arquitectura, del plan de seguridad y del modelo de datos. | C3: Etapa 1 | D3: 4 | E3: =EDATE('Parámetros'!$B$3,D3-1) | F3: 0.07 | G3: 2.1.1–2.1.3, 2.2.1, 2.2.3, 2.2.4 (acta 2.4.1) | H3: =WORKDAY('Parámetros'!$B$3-1,M3+1) | I3: =WORKDAY(EOMONTH(E3,0)+1,-1-'Parámetros'!$B$4) | J3: =NETWORKDAYS(H3,I3)-1 | K3: 0.9736 | L3: =WORKDAY('Parámetros'!$B$3-1,71) | M3: 63
A4: H3 | B4: Entrega de la infraestructura híbrida y habilitación de los ambientes de Desarrollo, QA, Preproducción y Producción, con observabilidad operativa. | C4: Etapa 1 | D4: 6 | E4: =EDATE('Parámetros'!$B$3,D4-1) | F4: 0.1 | G4: 3.1.1–3.1.3, 3.1.5, 6.6.3 | H4: =WORKDAY('Parámetros'!$B$3-1,M4+1) | I4: =WORKDAY(EOMONTH(E4,0)+1,-1-'Parámetros'!$B$4) | J4: =NETWORKDAYS(H4,I4)-1 | K4: 0.8832 | L4: =WORKDAY('Parámetros'!$B$3-1,117) | M4: 100
A5: H4 | B5: Entrega del software de la Etapa 1 para pruebas, con QA superado y evidencia de cobertura. | C5: Etapa 1 | D5: 10 | E5: =EDATE('Parámetros'!$B$3,D5-1) | F5: 0.1 | G5: 3.4, 3.6.1–3.6.4 → 3.8.1 | H5: =WORKDAY('Parámetros'!$B$3-1,M5+1) | I5: =WORKDAY(EOMONTH(E5,0)+1,-1-'Parámetros'!$B$4) | J5: =NETWORKDAYS(H5,I5)-1 | K5: 0.8654 | L5: =WORKDAY('Parámetros'!$B$3-1,206) | M5: 187
A6: H5 | B6: Certificación de la solución de la Etapa 1: pruebas de aceptación de usuario, de carga, de resiliencia y de seguridad ofensiva aprobadas. | C6: Etapa 1 | D6: 12 | E6: =EDATE('Parámetros'!$B$3,D6-1) | F6: 0.1 | G6: 3.8.2–3.8.8 | H6: =WORKDAY('Parámetros'!$B$3-1,M6+1) | I6: =WORKDAY(EOMONTH(E6,0)+1,-1-'Parámetros'!$B$4) | J6: =NETWORKDAYS(H6,I6)-1 | K6: 0.8884 | L6: =WORKDAY('Parámetros'!$B$3-1,249) | M6: 215
A7: H6 | B7: Inicio de la marcha blanca de la Etapa 1, con plan de reversión activo y usuarios capacitados. | C7: Etapa 1 | D7: 13 | E7: =EDATE('Parámetros'!$B$3,D7-1) | F7: 0.05 | G7: 4.2.1 | H7: Fecha fija del Art. 17° | I7: — | J7: — | K7: — | L7: —
A8: H7 | B8: Paso a producción de la Etapa 1 y cierre conforme de la marcha blanca. | C8: Etapa 1 | D8: 16 | E8: =EDATE('Parámetros'!$B$3,D8-1) | F8: 0.1 | G8: 4.2.3 | H8: Fecha fija del Art. 17° | I8: — | J8: — | K8: — | L8: —
A9: H8 | B9: Aprobación de la línea base de alcance de la Etapa 2 y de su diseño detallado. | C9: Etapa 2 | D9: 14 | E9: =EDATE('Parámetros'!$B$3,D9-1) | F9: 0.05 | G9: 1.2.5, 2.1.4 (acta 2.4.2) | H9: =WORKDAY('Parámetros'!$B$3-1,M9+1) | I9: =WORKDAY(EOMONTH(E9,0)+1,-1-'Parámetros'!$B$4) | J9: =NETWORKDAYS(H9,I9)-1 | K9: 0.9108 | L9: =WORKDAY('Parámetros'!$B$3-1,294) | M9: 290
A10: H9 | B10: Entrega del software de la Etapa 2 para pruebas, con QA superado. | C10: Etapa 2 | D10: 17 | E10: =EDATE('Parámetros'!$B$3,D10-1) | F10: 0.1 | G10: 3.9.1 | H10: =WORKDAY('Parámetros'!$B$3-1,M10+1) | I10: =WORKDAY(EOMONTH(E10,0)+1,-1-'Parámetros'!$B$4) | J10: =NETWORKDAYS(H10,I10)-1 | K10: 1 | L10: =WORKDAY('Parámetros'!$B$3-1,346) | M10: 338
A11: H10 | B11: Certificación de la solución de la Etapa 2 y cierre del desarrollo. | C11: Etapa 2 | D11: 18 | E11: =EDATE('Parámetros'!$B$3,D11-1) | F11: 0.1 | G11: 3.9.2–3.9.7 (acta 3.9.6) | H11: =WORKDAY('Parámetros'!$B$3-1,M11+1) | I11: =WORKDAY(EOMONTH(E11,0)+1,-1-'Parámetros'!$B$4) | J11: =NETWORKDAYS(H11,I11)-1 | K11: 1 | L11: =WORKDAY('Parámetros'!$B$3-1,369) | M11: 355
A12: H11 | B12: Inicio de la marcha blanca de la Etapa 2 en convivencia con la Etapa 1 en producción. | C12: Etapa 2 | D12: 19 | E12: =EDATE('Parámetros'!$B$3,D12-1) | F12: 0.05 | G12: 4.3.1 | H12: Fecha fija del Art. 17° | I12: — | J12: — | K12: — | L12: —
A13: H12 | B13: Paso a producción de la Etapa 2 y aceptación final del proyecto de implementación. | C13: Etapa 2 | D13: 21 | E13: =EDATE('Parámetros'!$B$3,D13-1) | F13: 0.1 | G13: 4.3.3, 4.3.4 | H13: Fecha fija del Art. 17° | I13: — | J13: — | K13: — | L13: —
B14: Total implementación | F14: =SUM(F2:F13)
B16: Cómo leer esta hoja:
B17: • Mes contractual: mes del contrato en que se firma el acta del hito (Formulario E-25). Mes calendario: ese mes según la fecha de inicio de la hoja «Parámetros».
B18: • Entrega programada: día en que LafroX termina y presenta el último entregable que gatilla el hito (Formulario T-15, Tabla 5.2).
B19: • Fecha límite de entrega: último día hábil del mes del hito menos los diez días hábiles que el CLIENTE tiene para revisar (Art. 18.3). Si LafroX entrega después de esa fecha, el acta no alcanza a firmarse dentro del mes.
B20: • Reserva: días hábiles entre la entrega programada y la fecha límite. Absorbe atrasos sin mover el hito.
B21: • Probabilidad y P80: resultado de la simulación de Monte Carlo del SD8 (Anexo 8.C). P80 es la fecha de entrega que se alcanza en el 80 % de los escenarios; queda antes de la fecha límite en todos los hitos. El H4 exige además todas las integraciones externas de la Etapa 1.
B22: • H6, H7, H11 y H12 no tienen entrega previa calculada: son el inicio o el cierre de una marcha blanca, en fechas fijas del Art. 17°. H7 y H12 se firman en un día permitido del mes, después de los tres primeros días hábiles.
B23: • Además de estos doce hitos, la Operación tiene un hito mensual en producción (36 pagos, meses 21 a 56), con descuentos por incumplimiento de niveles de servicio.

Sheet Períodos Art. 17
A1: Período contractual | B1: Mes inicio | C1: Mes fin | D1: Duración (meses) | E1: Inicio calendario | F1: Fin calendario | G1: Qué ocurre
A2: Etapa 1 · Desarrollo | B2: 1 | C2: 12 | D2: =C2-B2+1 | E2: =EDATE('Parámetros'!$B$3,B2-1) | F2: =EOMONTH(EDATE('Parámetros'!$B$3,C2-1),0) | G2: Se diseña, construye y certifica la Etapa 1 (recepción, inventario, preparación, preventa, rutas, reparto, cobranza, devoluciones, calidad, telemetría e indicadores).
A3: Etapa 1 · Marcha blanca | B3: 13 | C3: 15 | D3: =C3-B3+1 | E3: =EDATE('Parámetros'!$B$3,B3-1) | F3: =EOMONTH(EDATE('Parámetros'!$B$3,C3-1),0) | G3: La Etapa 1 opera con usuarios reales en convivencia con la forma actual de trabajo; se mide diariamente hasta cumplir las seis condiciones del Art. 17.3.
A4: Etapa 1 · Producción | B4: 16 | C4: 56 | D4: =C4-B4+1 | E4: =EDATE('Parámetros'!$B$3,B4-1) | F4: =EOMONTH(EDATE('Parámetros'!$B$3,C4-1),0) | G4: La Etapa 1 queda en producción desde el H7; hasta el mes 20 recibe soporte puente y estabilización.
A5: Etapa 2 · Desarrollo | B5: 13 | C5: 18 | D5: =C5-B5+1 | E5: =EDATE('Parámetros'!$B$3,B5-1) | F5: =EOMONTH(EDATE('Parámetros'!$B$3,C5-1),0) | G5: Se diseña, construye y certifica la Etapa 2 (canal moderno, portales y costo de servir), en paralelo con la marcha blanca de la Etapa 1 (solapamiento de los meses 13 a 15, Art. 17.2).
A6: Etapa 2 · Marcha blanca | B6: 19 | C6: 20 | D6: =C6-B6+1 | E6: =EDATE('Parámetros'!$B$3,B6-1) | F6: =EOMONTH(EDATE('Parámetros'!$B$3,C6-1),0) | G6: La Etapa 2 opera con usuarios reales en convivencia con la Etapa 1 en producción.
A7: Etapa 2 · Producción y aceptación final | B7: 21 | C7: 21 | D7: =C7-B7+1 | E7: =EDATE('Parámetros'!$B$3,B7-1) | F7: =EOMONTH(EDATE('Parámetros'!$B$3,C7-1),0) | G7: Paso a producción de la Etapa 2 y aceptación final de la implementación (H12).
A8: Operación (36 meses) | B8: 21 | C8: 56 | D8: =C8-B8+1 | E8: =EDATE('Parámetros'!$B$3,B8-1) | F8: =EOMONTH(EDATE('Parámetros'!$B$3,C8-1),0) | G8: Servicio de operación, soporte y mantenimiento con niveles de servicio, pagado con el hito mensual.
A10: Fuente: Bases Administrativas, Art. 17° (cronograma contractual obligatorio). Estos períodos no se mueven: el plan de trabajo se ajusta a ellos.

Sheet Gantt cuentas
A1: Carta Gantt por cuenta de control (49 cuentas) y períodos del Art. 17°
A2: Leyenda de colores (fase de la EDT): | I2: 1 Inicio | Q2: 2 Elaboración | Y2: 3 Construcción | AG2: 4 Transición | AO2: 5 Adquisiciones y contrataciones
I3: 6 Infraestructura física y sitios | Q3: 7 Capacitación y gestión del cambio | Y3: 8 Operación y soporte | AG3: 9 Cierre
H4: «C» y fondo naranja = mes de congelamiento (septiembre y diciembre): sin pasos a producción. Fila «Hitos E-25» = mes del acta de cada hito.
A5: Fase | B5: Cuenta | C5: Nombre | D5: Inicio (mes) | E5: Fin (mes) | F5: Duración (meses) | G5: HH (E) | H5: 1 | I5: 2 | J5: 3 | K5: 4 | L5: 5 | M5: 6 | N5: 7 | O5: 8 | P5: 9 | Q5: 10 | R5: 11 | S5: 12 | T5: 13 | U5: 14 | V5: 15 | W5: 16 | X5: 17 | Y5: 18 | Z5: 19 | AA5: 20 | AB5: 21 | AC5: 22 | AD5: 23 | AE5: 24 | AF5: 25 | AG5: 26 | AH5: 27 | AI5: 28 | AJ5: 29 | AK5: 30 | AL5: 31 | AM5: 32 | AN5: 33 | AO5: 34 | AP5: 35 | AQ5: 36 | AR5: 37 | AS5: 38 | AT5: 39 | AU5: 40 | AV5: 41 | AW5: 42 | AX5: 43 | AY5: 44 | AZ5: 45 | BA5: 46 | BB5: 47 | BC5: 48 | BD5: 49 | BE5: 50 | BF5: 51 | BG5: 52 | BH5: 53 | BI5: 54 | BJ5: 55 | BK5: 56
G6: Mes calendario | H6: =EDATE('Parámetros'!$B$3,H5-1) | I6: =EDATE('Parámetros'!$B$3,I5-1) | J6: =EDATE('Parámetros'!$B$3,J5-1) | K6: =EDATE('Parámetros'!$B$3,K5-1) | L6: =EDATE('Parámetros'!$B$3,L5-1) | M6: =EDATE('Parámetros'!$B$3,M5-1) | N6: =EDATE('Parámetros'!$B$3,N5-1) | O6: =EDATE('Parámetros'!$B$3,O5-1) | ... BK6: =EDATE('Parámetros'!$B$3,BK5-1)
G7: Congelamiento | H7: =IF(OR(MONTH(H6)=9,MONTH(H6)=12),"C","") | I7: =IF(OR(MONTH(I6)=9,MONTH(I6)=12),"C","") | J7: =IF(OR(MONTH(J6)=9,MONTH(J6)=12),"C","") | K7: =IF(OR(MONTH(K6)=9,MONTH(K6)=12),"C","") | L7: =IF(OR(MONTH(L6)=9,MONTH(L6)=12),"C","") | M7: =IF(OR(MONTH(M6)=9,MONTH(M6)=12),"C","") | N7: =IF(OR(MONTH(N6)=9,MONTH(N6)=12),"C","") | O7: =IF(OR(MONTH(O6)=9,MONTH(O6)=12),"C","") | ... BK7: =IF(OR(MONTH(BK6)=9,MONTH(BK6)=12),"C","")
G8: Hitos E-25 | H8: {=IFERROR(INDEX(Hitos!$A$2:$A$13,MATCH(H5,Hitos!$D$2:$D$13,0)),"")} | I8: {=IFERROR(INDEX(Hitos!$A$2:$A$13,MATCH(I5,Hitos!$D$2:$D$13,0)),"")} | J8: {=IFERROR(INDEX(Hitos!$A$2:$A$13,MATCH(J5,Hitos!$D$2:$D$13,0)),"")} | K8: {=IFERROR(INDEX(Hitos!$A$2:$A$13,MATCH(K5,Hitos!$D$2:$D$13,0)),"")} | L8: {=IFERROR(INDEX(Hitos!$A$2:$A$13,MATCH(L5,Hitos!$D$2:$D$13,0)),"")} | M8: {=IFERROR(INDEX(Hitos!$A$2:$A$13,MATCH(M5,Hitos!$D$2:$D$13,0)),"")} | N8: {=IFERROR(INDEX(Hitos!$A$2:$A$13,MATCH(N5,Hitos!$D$2:$D$13,0)),"")} | O8: {=IFERROR(INDEX(Hitos!$A$2:$A$13,MATCH(O5,Hitos!$D$2:$D$13,0)),"")} | ... BK8: {=IFERROR(INDEX(Hitos!$A$2:$A$13,MATCH(BK5,Hitos!$D$2:$D$13,0)),"")}
A9: Período | B9: Art. 17 | C9: Etapa 1 · Desarrollo | D9: 1 | E9: 12 | F9: =E9-D9+1 | H9: =IF(AND(H$5>=$D9,H$5<=$E9),0,"") | I9: =IF(AND(I$5>=$D9,I$5<=$E9),0,"") | J9: =IF(AND(J$5>=$D9,J$5<=$E9),0,"") | K9: =IF(AND(K$5>=$D9,K$5<=$E9),0,"") | L9: =IF(AND(L$5>=$D9,L$5<=$E9),0,"") | M9: =IF(AND(M$5>=$D9,M$5<=$E9),0,"") | N9: =IF(AND(N$5>=$D9,N$5<=$E9),0,"") | O9: =IF(AND(O$5>=$D9,O$5<=$E9),0,"") | ... BK9: =IF(AND(BK$5>=$D9,BK$5<=$E9),0,"")
A10: Período | B10: Art. 17 | C10: Etapa 1 · Marcha blanca | D10: 13 | E10: 15 | F10: =E10-D10+1 | H10: =IF(AND(H$5>=$D10,H$5<=$E10),0,"") | I10: =IF(AND(I$5>=$D10,I$5<=$E10),0,"") | J10: =IF(AND(J$5>=$D10,J$5<=$E10),0,"") | K10: =IF(AND(K$5>=$D10,K$5<=$E10),0,"") | L10: =IF(AND(L$5>=$D10,L$5<=$E10),0,"") | M10: =IF(AND(M$5>=$D10,M$5<=$E10),0,"") | N10: =IF(AND(N$5>=$D10,N$5<=$E10),0,"") | O10: =IF(AND(O$5>=$D10,O$5<=$E10),0,"") | ... BK10: =IF(AND(BK$5>=$D10,BK$5<=$E10),0,"")
A11: Período | B11: Art. 17 | C11: Etapa 1 · Producción | D11: 16 | E11: 56 | F11: =E11-D11+1 | H11: =IF(AND(H$5>=$D11,H$5<=$E11),0,"") | I11: =IF(AND(I$5>=$D11,I$5<=$E11),0,"") | J11: =IF(AND(J$5>=$D11,J$5<=$E11),0,"") | K11: =IF(AND(K$5>=$D11,K$5<=$E11),0,"") | L11: =IF(AND(L$5>=$D11,L$5<=$E11),0,"") | M11: =IF(AND(M$5>=$D11,M$5<=$E11),0,"") | N11: =IF(AND(N$5>=$D11,N$5<=$E11),0,"") | O11: =IF(AND(O$5>=$D11,O$5<=$E11),0,"") | ... BK11: =IF(AND(BK$5>=$D11,BK$5<=$E11),0,"")
A12: Período | B12: Art. 17 | C12: Etapa 2 · Desarrollo | D12: 13 | E12: 18 | F12: =E12-D12+1 | H12: =IF(AND(H$5>=$D12,H$5<=$E12),0,"") | I12: =IF(AND(I$5>=$D12,I$5<=$E12),0,"") | J12: =IF(AND(J$5>=$D12,J$5<=$E12),0,"") | K12: =IF(AND(K$5>=$D12,K$5<=$E12),0,"") | L12: =IF(AND(L$5>=$D12,L$5<=$E12),0,"") | M12: =IF(AND(M$5>=$D12,M$5<=$E12),0,"") | N12: =IF(AND(N$5>=$D12,N$5<=$E12),0,"") | O12: =IF(AND(O$5>=$D12,O$5<=$E12),0,"") | ... BK12: =IF(AND(BK$5>=$D12,BK$5<=$E12),0,"")
A13: Período | B13: Art. 17 | C13: Etapa 2 · Marcha blanca | D13: 19 | E13: 20 | F13: =E13-D13+1 | H13: =IF(AND(H$5>=$D13,H$5<=$E13),0,"") | I13: =IF(AND(I$5>=$D13,I$5<=$E13),0,"") | J13: =IF(AND(J$5>=$D13,J$5<=$E13),0,"") | K13: =IF(AND(K$5>=$D13,K$5<=$E13),0,"") | L13: =IF(AND(L$5>=$D13,L$5<=$E13),0,"") | M13: =IF(AND(M$5>=$D13,M$5<=$E13),0,"") | N13: =IF(AND(N$5>=$D13,N$5<=$E13),0,"") | O13: =IF(AND(O$5>=$D13,O$5<=$E13),0,"") | ... BK13: =IF(AND(BK$5>=$D13,BK$5<=$E13),0,"")
A14: Período | B14: Art. 17 | C14: Etapa 2 · Producción y aceptación final | D14: 21 | E14: 21 | F14: =E14-D14+1 | H14: =IF(AND(H$5>=$D14,H$5<=$E14),0,"") | I14: =IF(AND(I$5>=$D14,I$5<=$E14),0,"") | J14: =IF(AND(J$5>=$D14,J$5<=$E14),0,"") | K14: =IF(AND(K$5>=$D14,K$5<=$E14),0,"") | L14: =IF(AND(L$5>=$D14,L$5<=$E14),0,"") | M14: =IF(AND(M$5>=$D14,M$5<=$E14),0,"") | N14: =IF(AND(N$5>=$D14,N$5<=$E14),0,"") | O14: =IF(AND(O$5>=$D14,O$5<=$E14),0,"") | ... BK14: =IF(AND(BK$5>=$D14,BK$5<=$E14),0,"")
A15: Período | B15: Art. 17 | C15: Operación (36 meses) | D15: 21 | E15: 56 | F15: =E15-D15+1 | H15: =IF(AND(H$5>=$D15,H$5<=$E15),0,"") | I15: =IF(AND(I$5>=$D15,I$5<=$E15),0,"") | J15: =IF(AND(J$5>=$D15,J$5<=$E15),0,"") | K15: =IF(AND(K$5>=$D15,K$5<=$E15),0,"") | L15: =IF(AND(L$5>=$D15,L$5<=$E15),0,"") | M15: =IF(AND(M$5>=$D15,M$5<=$E15),0,"") | N15: =IF(AND(N$5>=$D15,N$5<=$E15),0,"") | O15: =IF(AND(O$5>=$D15,O$5<=$E15),0,"") | ... BK15: =IF(AND(BK$5>=$D15,BK$5<=$E15),0,"")
A16: 1 Inicio | B16: 1.1 | C16: Definición inicial del proyecto | D16: 1 | E16: 1 | F16: =E16-D16+1 | G16: 240 | H16: =IF(AND(H$5>=$D16,H$5<=$E16),1,"") | I16: =IF(AND(I$5>=$D16,I$5<=$E16),1,"") | J16: =IF(AND(J$5>=$D16,J$5<=$E16),1,"") | K16: =IF(AND(K$5>=$D16,K$5<=$E16),1,"") | L16: =IF(AND(L$5>=$D16,L$5<=$E16),1,"") | M16: =IF(AND(M$5>=$D16,M$5<=$E16),1,"") | N16: =IF(AND(N$5>=$D16,N$5<=$E16),1,"") | O16: =IF(AND(O$5>=$D16,O$5<=$E16),1,"") | ... BK16: =IF(AND(BK$5>=$D16,BK$5<=$E16),1,"")
A17: 1 Inicio | B17: 1.2 | C17: Alcance del proyecto | D17: 1 | E17: 13 | F17: =E17-D17+1 | G17: 400 | H17: =IF(AND(H$5>=$D17,H$5<=$E17),1,"") | I17: =IF(AND(I$5>=$D17,I$5<=$E17),1,"") | J17: =IF(AND(J$5>=$D17,J$5<=$E17),1,"") | K17: =IF(AND(K$5>=$D17,K$5<=$E17),1,"") | L17: =IF(AND(L$5>=$D17,L$5<=$E17),1,"") | M17: =IF(AND(M$5>=$D17,M$5<=$E17),1,"") | N17: =IF(AND(N$5>=$D17,N$5<=$E17),1,"") | O17: =IF(AND(O$5>=$D17,O$5<=$E17),1,"") | ... BK17: =IF(AND(BK$5>=$D17,BK$5<=$E17),1,"")
A18: 1 Inicio | B18: 1.3 | C18: Planificación del proyecto | D18: 1 | E18: 20 | F18: =E18-D18+1 | G18: 800 | H18: =IF(AND(H$5>=$D18,H$5<=$E18),1,"") | I18: =IF(AND(I$5>=$D18,I$5<=$E18),1,"") | J18: =IF(AND(J$5>=$D18,J$5<=$E18),1,"") | K18: =IF(AND(K$5>=$D18,K$5<=$E18),1,"") | L18: =IF(AND(L$5>=$D18,L$5<=$E18),1,"") | M18: =IF(AND(M$5>=$D18,M$5<=$E18),1,"") | N18: =IF(AND(N$5>=$D18,N$5<=$E18),1,"") | O18: =IF(AND(O$5>=$D18,O$5<=$E18),1,"") | ... BK18: =IF(AND(BK$5>=$D18,BK$5<=$E18),1,"")
A19: 1 Inicio | B19: 1.4 | C19: Gestión de interesados y comunicaciones | D19: 1 | E19: 56 | F19: =E19-D19+1 | G19: 1056 | H19: =IF(AND(H$5>=$D19,H$5<=$E19),1,"") | I19: =IF(AND(I$5>=$D19,I$5<=$E19),1,"") | J19: =IF(AND(J$5>=$D19,J$5<=$E19),1,"") | K19: =IF(AND(K$5>=$D19,K$5<=$E19),1,"") | L19: =IF(AND(L$5>=$D19,L$5<=$E19),1,"") | M19: =IF(AND(M$5>=$D19,M$5<=$E19),1,"") | N19: =IF(AND(N$5>=$D19,N$5<=$E19),1,"") | O19: =IF(AND(O$5>=$D19,O$5<=$E19),1,"") | ... BK19: =IF(AND(BK$5>=$D19,BK$5<=$E19),1,"")
A20: 1 Inicio | B20: 1.5 | C20: Gestión de calidad | D20: 2 | E20: 20 | F20: =E20-D20+1 | G20: 160 | H20: =IF(AND(H$5>=$D20,H$5<=$E20),1,"") | I20: =IF(AND(I$5>=$D20,I$5<=$E20),1,"") | J20: =IF(AND(J$5>=$D20,J$5<=$E20),1,"") | K20: =IF(AND(K$5>=$D20,K$5<=$E20),1,"") | L20: =IF(AND(L$5>=$D20,L$5<=$E20),1,"") | M20: =IF(AND(M$5>=$D20,M$5<=$E20),1,"") | N20: =IF(AND(N$5>=$D20,N$5<=$E20),1,"") | O20: =IF(AND(O$5>=$D20,O$5<=$E20),1,"") | ... BK20: =IF(AND(BK$5>=$D20,BK$5<=$E20),1,"")
A21: 1 Inicio | B21: 1.6 | C21: Gestión de riesgos | D21: 1 | E21: 20 | F21: =E21-D21+1 | G21: 240 | H21: =IF(AND(H$5>=$D21,H$5<=$E21),1,"") | I21: =IF(AND(I$5>=$D21,I$5<=$E21),1,"") | J21: =IF(AND(J$5>=$D21,J$5<=$E21),1,"") | K21: =IF(AND(K$5>=$D21,K$5<=$E21),1,"") | L21: =IF(AND(L$5>=$D21,L$5<=$E21),1,"") | M21: =IF(AND(M$5>=$D21,M$5<=$E21),1,"") | N21: =IF(AND(N$5>=$D21,N$5<=$E21),1,"") | O21: =IF(AND(O$5>=$D21,O$5<=$E21),1,"") | ... BK21: =IF(AND(BK$5>=$D21,BK$5<=$E21),1,"")
A22: 1 Inicio | B22: 1.7 | C22: Plan de Reversibilidad | D22: 3 | E22: 15 | F22: =E22-D22+1 | G22: 160 | H22: =IF(AND(H$5>=$D22,H$5<=$E22),1,"") | I22: =IF(AND(I$5>=$D22,I$5<=$E22),1,"") | J22: =IF(AND(J$5>=$D22,J$5<=$E22),1,"") | K22: =IF(AND(K$5>=$D22,K$5<=$E22),1,"") | L22: =IF(AND(L$5>=$D22,L$5<=$E22),1,"") | M22: =IF(AND(M$5>=$D22,M$5<=$E22),1,"") | N22: =IF(AND(N$5>=$D22,N$5<=$E22),1,"") | O22: =IF(AND(O$5>=$D22,O$5<=$E22),1,"") | ... BK22: =IF(AND(BK$5>=$D22,BK$5<=$E22),1,"")
A23: 1 Inicio | B23: 1.8 | C23: Gobierno y control del proyecto | D23: 1 | E23: 56 | F23: =E23-D23+1 | G23: 3176 | H23: =IF(AND(H$5>=$D23,H$5<=$E23),1,"") | I23: =IF(AND(I$5>=$D23,I$5<=$E23),1,"") | J23: =IF(AND(J$5>=$D23,J$5<=$E23),1,"") | K23: =IF(AND(K$5>=$D23,K$5<=$E23),1,"") | L23: =IF(AND(L$5>=$D23,L$5<=$E23),1,"") | M23: =IF(AND(M$5>=$D23,M$5<=$E23),1,"") | N23: =IF(AND(N$5>=$D23,N$5<=$E23),1,"") | O23: =IF(AND(O$5>=$D23,O$5<=$E23),1,"") | ... BK23: =IF(AND(BK$5>=$D23,BK$5<=$E23),1,"")
A24: 1 Inicio | B24: 1.9 | C24: Cumplimiento normativo y contractual | D24: 1 | E24: 56 | F24: =E24-D24+1 | G24: 688 | H24: =IF(AND(H$5>=$D24,H$5<=$E24),1,"") | I24: =IF(AND(I$5>=$D24,I$5<=$E24),1,"") | J24: =IF(AND(J$5>=$D24,J$5<=$E24),1,"") | K24: =IF(AND(K$5>=$D24,K$5<=$E24),1,"") | L24: =IF(AND(L$5>=$D24,L$5<=$E24),1,"") | M24: =IF(AND(M$5>=$D24,M$5<=$E24),1,"") | N24: =IF(AND(N$5>=$D24,N$5<=$E24),1,"") | O24: =IF(AND(O$5>=$D24,O$5<=$E24),1,"") | ... BK24: =IF(AND(BK$5>=$D24,BK$5<=$E24),1,"")
A25: 2 Elaboración | B25: 2.1 | C25: Arquitectura de la solución | D25: 2 | E25: 13 | F25: =E25-D25+1 | G25: 960 | H25: =IF(AND(H$5>=$D25,H$5<=$E25),2,"") | I25: =IF(AND(I$5>=$D25,I$5<=$E25),2,"") | J25: =IF(AND(J$5>=$D25,J$5<=$E25),2,"") | K25: =IF(AND(K$5>=$D25,K$5<=$E25),2,"") | L25: =IF(AND(L$5>=$D25,L$5<=$E25),2,"") | M25: =IF(AND(M$5>=$D25,M$5<=$E25),2,"") | N25: =IF(AND(N$5>=$D25,N$5<=$E25),2,"") | O25: =IF(AND(O$5>=$D25,O$5<=$E25),2,"") | ... BK25: =IF(AND(BK$5>=$D25,BK$5<=$E25),2,"")
A26: 2 Elaboración | B26: 2.2 | C26: Diseño de la seguridad | D26: 2 | E26: 10 | F26: =E26-D26+1 | G26: 960 | H26: =IF(AND(H$5>=$D26,H$5<=$E26),2,"") | I26: =IF(AND(I$5>=$D26,I$5<=$E26),2,"") | J26: =IF(AND(J$5>=$D26,J$5<=$E26),2,"") | K26: =IF(AND(K$5>=$D26,K$5<=$E26),2,"") | L26: =IF(AND(L$5>=$D26,L$5<=$E26),2,"") | M26: =IF(AND(M$5>=$D26,M$5<=$E26),2,"") | N26: =IF(AND(N$5>=$D26,N$5<=$E26),2,"") | O26: =IF(AND(O$5>=$D26,O$5<=$E26),2,"") | ... BK26: =IF(AND(BK$5>=$D26,BK$5<=$E26),2,"")
A27: 2 Elaboración | B27: 2.3 | C27: Diseño de la sala técnica y de los racks | D27: 1 | E27: 2 | F27: =E27-D27+1 | G27: 720 | H27: =IF(AND(H$5>=$D27,H$5<=$E27),2,"") | I27: =IF(AND(I$5>=$D27,I$5<=$E27),2,"") | J27: =IF(AND(J$5>=$D27,J$5<=$E27),2,"") | K27: =IF(AND(K$5>=$D27,K$5<=$E27),2,"") | L27: =IF(AND(L$5>=$D27,L$5<=$E27),2,"") | M27: =IF(AND(M$5>=$D27,M$5<=$E27),2,"") | N27: =IF(AND(N$5>=$D27,N$5<=$E27),2,"") | O27: =IF(AND(O$5>=$D27,O$5<=$E27),2,"") | ... BK27: =IF(AND(BK$5>=$D27,BK$5<=$E27),2,"")
A28: 2 Elaboración | B28: 2.4 | C28: Validación de diseños | D28: 3 | E28: 14 | F28: =E28-D28+1 | G28: 480 | H28: =IF(AND(H$5>=$D28,H$5<=$E28),2,"") | I28: =IF(AND(I$5>=$D28,I$5<=$E28),2,"") | J28: =IF(AND(J$5>=$D28,J$5<=$E28),2,"") | K28: =IF(AND(K$5>=$D28,K$5<=$E28),2,"") | L28: =IF(AND(L$5>=$D28,L$5<=$E28),2,"") | M28: =IF(AND(M$5>=$D28,M$5<=$E28),2,"") | N28: =IF(AND(N$5>=$D28,N$5<=$E28),2,"") | O28: =IF(AND(O$5>=$D28,O$5<=$E28),2,"") | ... BK28: =IF(AND(BK$5>=$D28,BK$5<=$E28),2,"")
A29: 2 Elaboración | B29: 2.5 | C29: Continuidad del negocio | D29: 3 | E29: 3 | F29: =E29-D29+1 | G29: 480 | H29: =IF(AND(H$5>=$D29,H$5<=$E29),2,"") | I29: =IF(AND(I$5>=$D29,I$5<=$E29),2,"") | J29: =IF(AND(J$5>=$D29,J$5<=$E29),2,"") | K29: =IF(AND(K$5>=$D29,K$5<=$E29),2,"") | L29: =IF(AND(L$5>=$D29,L$5<=$E29),2,"") | M29: =IF(AND(M$5>=$D29,M$5<=$E29),2,"") | N29: =IF(AND(N$5>=$D29,N$5<=$E29),2,"") | O29: =IF(AND(O$5>=$D29,O$5<=$E29),2,"") | ... BK29: =IF(AND(BK$5>=$D29,BK$5<=$E29),2,"")
A30: 2 Elaboración | B30: 2.6 | C30: Experiencia de usuario | D30: 2 | E30: 4 | F30: =E30-D30+1 | G30: 720 | H30: =IF(AND(H$5>=$D30,H$5<=$E30),2,"") | I30: =IF(AND(I$5>=$D30,I$5<=$E30),2,"") | J30: =IF(AND(J$5>=$D30,J$5<=$E30),2,"") | K30: =IF(AND(K$5>=$D30,K$5<=$E30),2,"") | L30: =IF(AND(L$5>=$D30,L$5<=$E30),2,"") | M30: =IF(AND(M$5>=$D30,M$5<=$E30),2,"") | N30: =IF(AND(N$5>=$D30,N$5<=$E30),2,"") | O30: =IF(AND(O$5>=$D30,O$5<=$E30),2,"") | ... BK30: =IF(AND(BK$5>=$D30,BK$5<=$E30),2,"")
A31: 3 Construcción | B31: 3.1 | C31: Ambientes y cadena de desarrollo | D31: 4 | E31: 5 | F31: =E31-D31+1 | G31: 1200 | H31: =IF(AND(H$5>=$D31,H$5<=$E31),3,"") | I31: =IF(AND(I$5>=$D31,I$5<=$E31),3,"") | J31: =IF(AND(J$5>=$D31,J$5<=$E31),3,"") | K31: =IF(AND(K$5>=$D31,K$5<=$E31),3,"") | L31: =IF(AND(L$5>=$D31,L$5<=$E31),3,"") | M31: =IF(AND(M$5>=$D31,M$5<=$E31),3,"") | N31: =IF(AND(N$5>=$D31,N$5<=$E31),3,"") | O31: =IF(AND(O$5>=$D31,O$5<=$E31),3,"") | ... BK31: =IF(AND(BK$5>=$D31,BK$5<=$E31),3,"")
A32: 3 Construcción | B32: 3.2 | C32: Servicios de nube de la plataforma | D32: 4 | E32: 5 | F32: =E32-D32+1 | G32: 1440 | H32: =IF(AND(H$5>=$D32,H$5<=$E32),3,"") | I32: =IF(AND(I$5>=$D32,I$5<=$E32),3,"") | J32: =IF(AND(J$5>=$D32,J$5<=$E32),3,"") | K32: =IF(AND(K$5>=$D32,K$5<=$E32),3,"") | L32: =IF(AND(L$5>=$D32,L$5<=$E32),3,"") | M32: =IF(AND(M$5>=$D32,M$5<=$E32),3,"") | N32: =IF(AND(N$5>=$D32,N$5<=$E32),3,"") | O32: =IF(AND(O$5>=$D32,O$5<=$E32),3,"") | ... BK32: =IF(AND(BK$5>=$D32,BK$5<=$E32),3,"")
A33: 3 Construcción | B33: 3.3 | C33: Base compartida | D33: 5 | E33: 7 | F33: =E33-D33+1 | G33: 2880 | H33: =IF(AND(H$5>=$D33,H$5<=$E33),3,"") | I33: =IF(AND(I$5>=$D33,I$5<=$E33),3,"") | J33: =IF(AND(J$5>=$D33,J$5<=$E33),3,"") | K33: =IF(AND(K$5>=$D33,K$5<=$E33),3,"") | L33: =IF(AND(L$5>=$D33,L$5<=$E33),3,"") | M33: =IF(AND(M$5>=$D33,M$5<=$E33),3,"") | N33: =IF(AND(N$5>=$D33,N$5<=$E33),3,"") | O33: =IF(AND(O$5>=$D33,O$5<=$E33),3,"") | ... BK33: =IF(AND(BK$5>=$D33,BK$5<=$E33),3,"")
A34: 3 Construcción | B34: 3.4 | C34: Módulos de la Etapa 1 | D34: 5 | E34: 8 | F34: =E34-D34+1 | G34: 10560 | H34: =IF(AND(H$5>=$D34,H$5<=$E34),3,"") | I34: =IF(AND(I$5>=$D34,I$5<=$E34),3,"") | J34: =IF(AND(J$5>=$D34,J$5<=$E34),3,"") | K34: =IF(AND(K$5>=$D34,K$5<=$E34),3,"") | L34: =IF(AND(L$5>=$D34,L$5<=$E34),3,"") | M34: =IF(AND(M$5>=$D34,M$5<=$E34),3,"") | N34: =IF(AND(N$5>=$D34,N$5<=$E34),3,"") | O34: =IF(AND(O$5>=$D34,O$5<=$E34),3,"") | ... BK34: =IF(AND(BK$5>=$D34,BK$5<=$E34),3,"")
A35: 3 Construcción | B35: 3.5 | C35: Módulos de la Etapa 2 | D35: 15 | E35: 15 | F35: =E35-D35+1 | G35: 3840 | H35: =IF(AND(H$5>=$D35,H$5<=$E35),3,"") | I35: =IF(AND(I$5>=$D35,I$5<=$E35),3,"") | J35: =IF(AND(J$5>=$D35,J$5<=$E35),3,"") | K35: =IF(AND(K$5>=$D35,K$5<=$E35),3,"") | L35: =IF(AND(L$5>=$D35,L$5<=$E35),3,"") | M35: =IF(AND(M$5>=$D35,M$5<=$E35),3,"") | N35: =IF(AND(N$5>=$D35,N$5<=$E35),3,"") | O35: =IF(AND(O$5>=$D35,O$5<=$E35),3,"") | ... BK35: =IF(AND(BK$5>=$D35,BK$5<=$E35),3,"")
A36: 3 Construcción | B36: 3.6 | C36: Integraciones externas | D36: 6 | E36: 19 | F36: =E36-D36+1 | G36: 2880 | H36: =IF(AND(H$5>=$D36,H$5<=$E36),3,"") | I36: =IF(AND(I$5>=$D36,I$5<=$E36),3,"") | J36: =IF(AND(J$5>=$D36,J$5<=$E36),3,"") | K36: =IF(AND(K$5>=$D36,K$5<=$E36),3,"") | L36: =IF(AND(L$5>=$D36,L$5<=$E36),3,"") | M36: =IF(AND(M$5>=$D36,M$5<=$E36),3,"") | N36: =IF(AND(N$5>=$D36,N$5<=$E36),3,"") | O36: =IF(AND(O$5>=$D36,O$5<=$E36),3,"") | ... BK36: =IF(AND(BK$5>=$D36,BK$5<=$E36),3,"")
A37: 3 Construcción | B37: 3.7 | C37: Migración de datos | D37: 7 | E37: 12 | F37: =E37-D37+1 | G37: 2400 | H37: =IF(AND(H$5>=$D37,H$5<=$E37),3,"") | I37: =IF(AND(I$5>=$D37,I$5<=$E37),3,"") | J37: =IF(AND(J$5>=$D37,J$5<=$E37),3,"") | K37: =IF(AND(K$5>=$D37,K$5<=$E37),3,"") | L37: =IF(AND(L$5>=$D37,L$5<=$E37),3,"") | M37: =IF(AND(M$5>=$D37,M$5<=$E37),3,"") | N37: =IF(AND(N$5>=$D37,N$5<=$E37),3,"") | O37: =IF(AND(O$5>=$D37,O$5<=$E37),3,"") | ... BK37: =IF(AND(BK$5>=$D37,BK$5<=$E37),3,"")
A38: 3 Construcción | B38: 3.8 | C38: Pruebas de la Etapa 1 | D38: 9 | E38: 10 | F38: =E38-D38+1 | G38: 2080 | H38: =IF(AND(H$5>=$D38,H$5<=$E38),3,"") | I38: =IF(AND(I$5>=$D38,I$5<=$E38),3,"") | J38: =IF(AND(J$5>=$D38,J$5<=$E38),3,"") | K38: =IF(AND(K$5>=$D38,K$5<=$E38),3,"") | L38: =IF(AND(L$5>=$D38,L$5<=$E38),3,"") | M38: =IF(AND(M$5>=$D38,M$5<=$E38),3,"") | N38: =IF(AND(N$5>=$D38,N$5<=$E38),3,"") | O38: =IF(AND(O$5>=$D38,O$5<=$E38),3,"") | ... BK38: =IF(AND(BK$5>=$D38,BK$5<=$E38),3,"")
A39: 3 Construcción | B39: 3.9 | C39: Pruebas de la Etapa 2 | D39: 16 | E39: 17 | F39: =E39-D39+1 | G39: 1760 | H39: =IF(AND(H$5>=$D39,H$5<=$E39),3,"") | I39: =IF(AND(I$5>=$D39,I$5<=$E39),3,"") | J39: =IF(AND(J$5>=$D39,J$5<=$E39),3,"") | K39: =IF(AND(K$5>=$D39,K$5<=$E39),3,"") | L39: =IF(AND(L$5>=$D39,L$5<=$E39),3,"") | M39: =IF(AND(M$5>=$D39,M$5<=$E39),3,"") | N39: =IF(AND(N$5>=$D39,N$5<=$E39),3,"") | O39: =IF(AND(O$5>=$D39,O$5<=$E39),3,"") | ... BK39: =IF(AND(BK$5>=$D39,BK$5<=$E39),3,"")
A40: 3 Construcción | B40: 3.10 | C40: Innovaciones | D40: 2 | E40: 21 | F40: =E40-D40+1 | G40: 3840 | H40: =IF(AND(H$5>=$D40,H$5<=$E40),3,"") | I40: =IF(AND(I$5>=$D40,I$5<=$E40),3,"") | J40: =IF(AND(J$5>=$D40,J$5<=$E40),3,"") | K40: =IF(AND(K$5>=$D40,K$5<=$E40),3,"") | L40: =IF(AND(L$5>=$D40,L$5<=$E40),3,"") | M40: =IF(AND(M$5>=$D40,M$5<=$E40),3,"") | N40: =IF(AND(N$5>=$D40,N$5<=$E40),3,"") | O40: =IF(AND(O$5>=$D40,O$5<=$E40),3,"") | ... BK40: =IF(AND(BK$5>=$D40,BK$5<=$E40),3,"")
...

Sheet Gantt paquetes
A1: Carta Gantt por paquete de trabajo (222 paquetes de la EDT)
A2: Leyenda de colores (fase de la EDT): | L2: 1 Inicio | T2: 2 Elaboración | AB2: 3 Construcción | AJ2: 4 Transición | AR2: 5 Adquisiciones y contrataciones
L3: 6 Infraestructura física y sitios | T3: 7 Capacitación y gestión del cambio | AB3: 8 Operación y soporte | AJ3: 9 Cierre
K4: «C» y fondo naranja = mes de congelamiento (septiembre y diciembre): sin pasos a producción. Fila «Hitos E-25» = mes del acta de cada hito.
A5: Fase | B5: Paquete | C5: Nombre del paquete | D5: Clase | E5: Responsable (familia de rol) | F5: Inicio (mes) | G5: Fin (mes) | H5: Duración (meses) | I5: HH esperadas (E) | J5: Tipo de programación | K5: 1 | L5: 2 | M5: 3 | N5: 4 | O5: 5 | P5: 6 | Q5: 7 | R5: 8 | S5: 9 | T5: 10 | U5: 11 | V5: 12 | W5: 13 | X5: 14 | Y5: 15 | Z5: 16 | AA5: 17 | AB5: 18 | AC5: 19 | AD5: 20 | AE5: 21 | AF5: 22 | AG5: 23 | AH5: 24 | AI5: 25 | AJ5: 26 | AK5: 27 | AL5: 28 | AM5: 29 | AN5: 30 | AO5: 31 | AP5: 32 | AQ5: 33 | AR5: 34 | AS5: 35 | AT5: 36 | AU5: 37 | AV5: 38 | AW5: 39 | AX5: 40 | AY5: 41 | AZ5: 42 | BA5: 43 | BB5: 44 | BC5: 45 | BD5: 46 | BE5: 47 | BF5: 48 | BG5: 49 | BH5: 50 | BI5: 51 | BJ5: 52 | BK5: 53 | BL5: 54 | BM5: 55 | BN5: 56
J6: Mes calendario | K6: =EDATE('Parámetros'!$B$3,K5-1) | L6: =EDATE('Parámetros'!$B$3,L5-1) | M6: =EDATE('Parámetros'!$B$3,M5-1) | N6: =EDATE('Parámetros'!$B$3,N5-1) | O6: =EDATE('Parámetros'!$B$3,O5-1) | P6: =EDATE('Parámetros'!$B$3,P5-1) | Q6: =EDATE('Parámetros'!$B$3,Q5-1) | R6: =EDATE('Parámetros'!$B$3,R5-1) | ... BN6: =EDATE('Parámetros'!$B$3,BN5-1)
J7: Congelamiento | K7: =IF(OR(MONTH(K6)=9,MONTH(K6)=12),"C","") | L7: =IF(OR(MONTH(L6)=9,MONTH(L6)=12),"C","") | M7: =IF(OR(MONTH(M6)=9,MONTH(M6)=12),"C","") | N7: =IF(OR(MONTH(N6)=9,MONTH(N6)=12),"C","") | O7: =IF(OR(MONTH(O6)=9,MONTH(O6)=12),"C","") | P7: =IF(OR(MONTH(P6)=9,MONTH(P6)=12),"C","") | Q7: =IF(OR(MONTH(Q6)=9,MONTH(Q6)=12),"C","") | R7: =IF(OR(MONTH(R6)=9,MONTH(R6)=12),"C","") | ... BN7: =IF(OR(MONTH(BN6)=9,MONTH(BN6)=12),"C","")
J8: Hitos E-25 | K8: {=IFERROR(INDEX(Hitos!$A$2:$A$13,MATCH(K5,Hitos!$D$2:$D$13,0)),"")} | L8: {=IFERROR(INDEX(Hitos!$A$2:$A$13,MATCH(L5,Hitos!$D$2:$D$13,0)),"")} | M8: {=IFERROR(INDEX(Hitos!$A$2:$A$13,MATCH(M5,Hitos!$D$2:$D$13,0)),"")} | N8: {=IFERROR(INDEX(Hitos!$A$2:$A$13,MATCH(N5,Hitos!$D$2:$D$13,0)),"")} | O8: {=IFERROR(INDEX(Hitos!$A$2:$A$13,MATCH(O5,Hitos!$D$2:$D$13,0)),"")} | P8: {=IFERROR(INDEX(Hitos!$A$2:$A$13,MATCH(P5,Hitos!$D$2:$D$13,0)),"")} | Q8: {=IFERROR(INDEX(Hitos!$A$2:$A$13,MATCH(Q5,Hitos!$D$2:$D$13,0)),"")} | R8: {=IFERROR(INDEX(Hitos!$A$2:$A$13,MATCH(R5,Hitos!$D$2:$D$13,0)),"")} | ... BN8: {=IFERROR(INDEX(Hitos!$A$2:$A$13,MATCH(BN5,Hitos!$D$2:$D$13,0)),"")}
A9: 1 Inicio | B9: 1.1.1 | C9: Acta de constitución del proyecto, firmada con la Contraparte Técnica | D9: G | E9: Jefe de Proyecto | F9: 1 | G9: 1 | H9: =G9-F9+1 | I9: 80 | J9: Con entregable (actividades en hoja «Actividades hasta H2») | K9: =IF(AND(K$5>=$F9,K$5<=$G9),1,"") | L9: =IF(AND(L$5>=$F9,L$5<=$G9),1,"") | M9: =IF(AND(M$5>=$F9,M$5<=$G9),1,"") | N9: =IF(AND(N$5>=$F9,N$5<=$G9),1,"") | O9: =IF(AND(O$5>=$F9,O$5<=$G9),1,"") | P9: =IF(AND(P$5>=$F9,P$5<=$G9),1,"") | Q9: =IF(AND(Q$5>=$F9,Q$5<=$G9),1,"") | R9: =IF(AND(R$5>=$F9,R$5<=$G9),1,"") | ... BN9: =IF(AND(BN$5>=$F9,BN$5<=$G9),1,"")
A10: 1 Inicio | B10: 1.1.2 | C10: Documento de validación con el CLIENTE de los problemas y metas del proyecto | D10: G | E10: Jefe de Proyecto | F10: 1 | G10: 1 | H10: =G10-F10+1 | I10: 80 | J10: Con entregable (actividades en hoja «Actividades hasta H2») | K10: =IF(AND(K$5>=$F10,K$5<=$G10),1,"") | L10: =IF(AND(L$5>=$F10,L$5<=$G10),1,"") | M10: =IF(AND(M$5>=$F10,M$5<=$G10),1,"") | N10: =IF(AND(N$5>=$F10,N$5<=$G10),1,"") | O10: =IF(AND(O$5>=$F10,O$5<=$G10),1,"") | P10: =IF(AND(P$5>=$F10,P$5<=$G10),1,"") | Q10: =IF(AND(Q$5>=$F10,Q$5<=$G10),1,"") | R10: =IF(AND(R$5>=$F10,R$5<=$G10),1,"") | ... BN10: =IF(AND(BN$5>=$F10,BN$5<=$G10),1,"")
A11: 1 Inicio | B11: 1.1.3 | C11: Acta de confirmación con el CLIENTE de la fecha de inicio, la evidencia para el proveedor de lácteos, las ventanas de paso a producción y el acuse tributario | D11: G | E11: Jefe de Proyecto | F11: 1 | G11: 1 | H11: =G11-F11+1 | I11: 80 | J11: Con entregable (actividades en hoja «Actividades hasta H2») | K11: =IF(AND(K$5>=$F11,K$5<=$G11),1,"") | L11: =IF(AND(L$5>=$F11,L$5<=$G11),1,"") | M11: =IF(AND(M$5>=$F11,M$5<=$G11),1,"") | N11: =IF(AND(N$5>=$F11,N$5<=$G11),1,"") | O11: =IF(AND(O$5>=$F11,O$5<=$G11),1,"") | P11: =IF(AND(P$5>=$F11,P$5<=$G11),1,"") | Q11: =IF(AND(Q$5>=$F11,Q$5<=$G11),1,"") | R11: =IF(AND(R$5>=$F11,R$5<=$G11),1,"") | ... BN11: =IF(AND(BN$5>=$F11,BN$5<=$G11),1,"")
A12: 1 Inicio | B12: 1.2.1 | C12: Documento de especificación de requerimientos y línea base de alcance de la Etapa 1 (H1) | D12: G | E12: Arquitectura | F12: 1 | G12: 1 | H12: =G12-F12+1 | I12: 80 | J12: Con entregable (actividades en hoja «Actividades hasta H2») | K12: =IF(AND(K$5>=$F12,K$5<=$G12),1,"") | L12: =IF(AND(L$5>=$F12,L$5<=$G12),1,"") | M12: =IF(AND(M$5>=$F12,M$5<=$G12),1,"") | N12: =IF(AND(N$5>=$F12,N$5<=$G12),1,"") | O12: =IF(AND(O$5>=$F12,O$5<=$G12),1,"") | P12: =IF(AND(P$5>=$F12,P$5<=$G12),1,"") | Q12: =IF(AND(Q$5>=$F12,Q$5<=$G12),1,"") | R12: =IF(AND(R$5>=$F12,R$5<=$G12),1,"") | ... BN12: =IF(AND(BN$5>=$F12,BN$5<=$G12),1,"")
A13: 1 Inicio | B13: 1.2.2 | C13: Documento de reglas de ruteo capturadas al planificador de rutas | D13: G | E13: Implantación y gestión del cambio | F13: 1 | G13: 3 | H13: =G13-F13+1 | I13: 80 | J13: Esfuerzo continuo (por quincena u ocurrencia) | K13: =IF(AND(K$5>=$F13,K$5<=$G13),1,"") | L13: =IF(AND(L$5>=$F13,L$5<=$G13),1,"") | M13: =IF(AND(M$5>=$F13,M$5<=$G13),1,"") | N13: =IF(AND(N$5>=$F13,N$5<=$G13),1,"") | O13: =IF(AND(O$5>=$F13,O$5<=$G13),1,"") | P13: =IF(AND(P$5>=$F13,P$5<=$G13),1,"") | Q13: =IF(AND(Q$5>=$F13,Q$5<=$G13),1,"") | R13: =IF(AND(R$5>=$F13,R$5<=$G13),1,"") | ... BN13: =IF(AND(BN$5>=$F13,BN$5<=$G13),1,"")
A14: 1 Inicio | B14: 1.2.3 | C14: Documento de especificación de las interfaces sin documentación del ERP, del WMS de 2013 y de la telemetría del tercero | D14: G | E14: Arquitectura | F14: 1 | G14: 4 | H14: =G14-F14+1 | I14: 80 | J14: Con entregable (actividades en hoja «Actividades hasta H2») | K14: =IF(AND(K$5>=$F14,K$5<=$G14),1,"") | L14: =IF(AND(L$5>=$F14,L$5<=$G14),1,"") | M14: =IF(AND(M$5>=$F14,M$5<=$G14),1,"") | N14: =IF(AND(N$5>=$F14,N$5<=$G14),1,"") | O14: =IF(AND(O$5>=$F14,O$5<=$G14),1,"") | P14: =IF(AND(P$5>=$F14,P$5<=$G14),1,"") | Q14: =IF(AND(Q$5>=$F14,Q$5<=$G14),1,"") | R14: =IF(AND(R$5>=$F14,R$5<=$G14),1,"") | ... BN14: =IF(AND(BN$5>=$F14,BN$5<=$G14),1,"")
A15: 1 Inicio | B15: 1.2.4 | C15: Matriz de trazabilidad: requerimiento, módulo, paquete y prueba (H1) | D15: G | E15: Calidad y pruebas | F15: 2 | G15: 2 | H15: =G15-F15+1 | I15: 80 | J15: Con entregable (actividades en hoja «Actividades hasta H2») | K15: =IF(AND(K$5>=$F15,K$5<=$G15),1,"") | L15: =IF(AND(L$5>=$F15,L$5<=$G15),1,"") | M15: =IF(AND(M$5>=$F15,M$5<=$G15),1,"") | N15: =IF(AND(N$5>=$F15,N$5<=$G15),1,"") | O15: =IF(AND(O$5>=$F15,O$5<=$G15),1,"") | P15: =IF(AND(P$5>=$F15,P$5<=$G15),1,"") | Q15: =IF(AND(Q$5>=$F15,Q$5<=$G15),1,"") | R15: =IF(AND(R$5>=$F15,R$5<=$G15),1,"") | ... BN15: =IF(AND(BN$5>=$F15,BN$5<=$G15),1,"")
A16: 1 Inicio | B16: 1.2.5 | C16: Documento de línea base de alcance de la Etapa 2: canal moderno y costo de servir (H8) | D16: G | E16: Arquitectura | F16: 13 | G16: 13 | H16: =G16-F16+1 | I16: 80 | J16: Con entregable (detalle por planificación gradual) | K16: =IF(AND(K$5>=$F16,K$5<=$G16),1,"") | L16: =IF(AND(L$5>=$F16,L$5<=$G16),1,"") | M16: =IF(AND(M$5>=$F16,M$5<=$G16),1,"") | N16: =IF(AND(N$5>=$F16,N$5<=$G16),1,"") | O16: =IF(AND(O$5>=$F16,O$5<=$G16),1,"") | P16: =IF(AND(P$5>=$F16,P$5<=$G16),1,"") | Q16: =IF(AND(Q$5>=$F16,Q$5<=$G16),1,"") | R16: =IF(AND(R$5>=$F16,R$5<=$G16),1,"") | ... BN16: =IF(AND(BN$5>=$F16,BN$5<=$G16),1,"")
A17: 1 Inicio | B17: 1.3.1 | C17: Plan para la dirección del proyecto, con el calendario de congelamientos de septiembre, diciembre y el cierre mensual | D17: G | E17: Jefe de Proyecto | F17: 1 | G17: 1 | H17: =G17-F17+1 | I17: 80 | J17: Con entregable (actividades en hoja «Actividades hasta H2») | K17: =IF(AND(K$5>=$F17,K$5<=$G17),1,"") | L17: =IF(AND(L$5>=$F17,L$5<=$G17),1,"") | M17: =IF(AND(M$5>=$F17,M$5<=$G17),1,"") | N17: =IF(AND(N$5>=$F17,N$5<=$G17),1,"") | O17: =IF(AND(O$5>=$F17,O$5<=$G17),1,"") | P17: =IF(AND(P$5>=$F17,P$5<=$G17),1,"") | Q17: =IF(AND(Q$5>=$F17,Q$5<=$G17),1,"") | R17: =IF(AND(R$5>=$F17,R$5<=$G17),1,"") | ... BN17: =IF(AND(BN$5>=$F17,BN$5<=$G17),1,"")
A18: 1 Inicio | B18: 1.3.2 | C18: EDT y diccionario de la EDT (línea base del alcance) | D18: G | E18: Jefe de Proyecto | F18: 2 | G18: 2 | H18: =G18-F18+1 | I18: 80 | J18: Con entregable (actividades en hoja «Actividades hasta H2») | K18: =IF(AND(K$5>=$F18,K$5<=$G18),1,"") | L18: =IF(AND(L$5>=$F18,L$5<=$G18),1,"") | M18: =IF(AND(M$5>=$F18,M$5<=$G18),1,"") | N18: =IF(AND(N$5>=$F18,N$5<=$G18),1,"") | O18: =IF(AND(O$5>=$F18,O$5<=$G18),1,"") | P18: =IF(AND(P$5>=$F18,P$5<=$G18),1,"") | Q18: =IF(AND(Q$5>=$F18,Q$5<=$G18),1,"") | R18: =IF(AND(R$5>=$F18,R$5<=$G18),1,"") | ... BN18: =IF(AND(BN$5>=$F18,BN$5<=$G18),1,"")
A19: 1 Inicio | B19: 1.3.3 | C19: Carta Gantt de 56 meses con los hitos H1 a H12 y la ruta crítica | D19: G | E19: Jefe de Proyecto | F19: 2 | G19: 2 | H19: =G19-F19+1 | I19: 80 | J19: Con entregable (actividades en hoja «Actividades hasta H2») | K19: =IF(AND(K$5>=$F19,K$5<=$G19),1,"") | L19: =IF(AND(L$5>=$F19,L$5<=$G19),1,"") | M19: =IF(AND(M$5>=$F19,M$5<=$G19),1,"") | N19: =IF(AND(N$5>=$F19,N$5<=$G19),1,"") | O19: =IF(AND(O$5>=$F19,O$5<=$G19),1,"") | P19: =IF(AND(P$5>=$F19,P$5<=$G19),1,"") | Q19: =IF(AND(Q$5>=$F19,Q$5<=$G19),1,"") | R19: =IF(AND(R$5>=$F19,R$5<=$G19),1,"") | ... BN19: =IF(AND(BN$5>=$F19,BN$5<=$G19),1,"")
A20: 1 Inicio | B20: 1.3.4 | C20: Documento de nivelación de recursos y frentes del solapamiento de los meses 13 a 15 y 19 a 20 | D20: G | E20: Jefe de Proyecto | F20: 2 | G20: 2 | H20: =G20-F20+1 | I20: 80 | J20: Con entregable (actividades en hoja «Actividades hasta H2») | K20: =IF(AND(K$5>=$F20,K$5<=$G20),1,"") | L20: =IF(AND(L$5>=$F20,L$5<=$G20),1,"") | M20: =IF(AND(M$5>=$F20,M$5<=$G20),1,"") | N20: =IF(AND(N$5>=$F20,N$5<=$G20),1,"") | O20: =IF(AND(O$5>=$F20,O$5<=$G20),1,"") | P20: =IF(AND(P$5>=$F20,P$5<=$G20),1,"") | Q20: =IF(AND(Q$5>=$F20,Q$5<=$G20),1,"") | R20: =IF(AND(R$5>=$F20,R$5<=$G20),1,"") | ... BN20: =IF(AND(BN$5>=$F20,BN$5<=$G20),1,"")
... A43: 1 Inicio | B43: 1.9.5 | C43: Garantía de fiel cumplimiento, seguros y certificados laborales vigentes durante el contrato | D43: R | E43: Jefe de Proyecto | F43: 1 | G43: 56 | H43: =G43-F43+1 | I43: 224 | J43: Esfuerzo continuo (por quincena u ocurrencia) | K43: =IF(AND(K$5>=$F43,K$5<=$G43),1,"") | L43: =IF(AND(L$5>=$F43,L$5<=$G43),1,"") | M43: =IF(AND(M$5>=$F43,M$5<=$G43),1,"") | N43: =IF(AND(N$5>=$F43,N$5<=$G43),1,"") | O43: =IF(AND(O$5>=$F43,O$5<=$G43),1,"") | P43: =IF(AND(P$5>=$F43,P$5<=$G43),1,"") | Q43: =IF(AND(Q$5>=$F43,Q$5<=$G43),1,"") | R43: =IF(AND(R$5>=$F43,R$5<=$G43),1,"") | ... BN43: =IF(AND(BN$5>=$F43,BN$5<=$G43),1,"")
A44: 2 Elaboración | B44: 2.1.1 | C44: Documento de arquitectura lógica: capas, módulos M1 a M12 e interfaces | D44: E | E44: Arquitectura | F44: 2 | G44: 2 | H44: =G44-F44+1 | I44: 240 | J44: Con entregable (actividades en hoja «Actividades hasta H2») | K44: =IF(AND(K$5>=$F44,K$5<=$G44),2,"") | L44: =IF(AND(L$5>=$F44,L$5<=$G44),2,"") | M44: =IF(AND(M$5>=$F44,M$5<=$G44),2,"") | N44: =IF(AND(N$5>=$F44,N$5<=$G44),2,"") | O44: =IF(AND(O$5>=$F44,O$5<=$G44),2,"") | P44: =IF(AND(P$5>=$F44,P$5<=$G44),2,"") | Q44: =IF(AND(Q$5>=$F44,Q$5<=$G44),2,"") | R44: =IF(AND(R$5>=$F44,R$5<=$G44),2,"") | ... BN44: =IF(AND(BN$5>=$F44,BN$5<=$G44),2,"")
A45: 2 Elaboración | B45: 2.1.2 | C45: Documento de arquitectura física híbrida: nube, centros de distribución y plataformas de cross-docking | D45: E | E45: Arquitectura | F45: 2 | G45: 2 | H45: =G45-F45+1 | I45: 240 | J45: Con entregable (actividades en hoja «Actividades hasta H2») | K45: =IF(AND(K$5>=$F45,K$5<=$G45),2,"") | L45: =IF(AND(L$5>=$F45,L$5<=$G45),2,"") | M45: =IF(AND(M$5>=$F45,M$5<=$G45),2,"") | N45: =IF(AND(N$5>=$F45,N$5<=$G45),2,"") | O45: =IF(AND(O$5>=$F45,O$5<=$G45),2,"") | P45: =IF(AND(P$5>=$F45,P$5<=$G45),2,"") | Q45: =IF(AND(Q$5>=$F45,Q$5<=$G45),2,"") | R45: =IF(AND(R$5>=$F45,R$5<=$G45),2,"") | ... BN45: =IF(AND(BN$5>=$F45,BN$5<=$G45),2,"")
A46: 2 Elaboración | B46: 2.1.3 | C46: Modelo de datos y diccionario de datos, con la trazabilidad por lote | D46: E | E46: Datos | F46: 2 | G46: 2 | H46: =G46-F46+1 | I46: 240 | J46: Con entregable (actividades en hoja «Actividades hasta H2») | K46: =IF(AND(K$5>=$F46,K$5<=$G46),2,"") | L46: =IF(AND(L$5>=$F46,L$5<=$G46),2,"") | M46: =IF(AND(M$5>=$F46,M$5<=$G46),2,"") | N46: =IF(AND(N$5>=$F46,N$5<=$G46),2,"") | O46: =IF(AND(O$5>=$F46,O$5<=$G46),2,"") | P46: =IF(AND(P$5>=$F46,P$5<=$G46),2,"") | Q46: =IF(AND(Q$5>=$F46,Q$5<=$G46),2,"") | R46: =IF(AND(R$5>=$F46,R$5<=$G46),2,"") | ... BN46: =IF(AND(BN$5>=$F46,BN$5<=$G46),2,"")
A47: 2 Elaboración | B47: 2.1.4 | C47: Documento de diseño detallado de M11 y del intercambio con las cadenas | D47: E | E47: Arquitectura | F47: 13 | G47: 13 | H47: =G47-F47+1 | I47: 240 | J47: Con entregable (detalle por planificación gradual) | K47: =IF(AND(K$5>=$F47,K$5<=$G47),2,"") | L47: =IF(AND(L$5>=$F47,L$5<=$G47),2,"") | M47: =IF(AND(M$5>=$F47,M$5<=$G47),2,"") | N47: =IF(AND(N$5>=$F47,N$5<=$G47),2,"") | O47: =IF(AND(O$5>=$F47,O$5<=$G47),2,"") | P47: =IF(AND(P$5>=$F47,P$5<=$G47),2,"") | Q47: =IF(AND(Q$5>=$F47,Q$5<=$G47),2,"") | R47: =IF(AND(R$5>=$F47,R$5<=$G47),2,"") | ... BN47: =IF(AND(BN$5>=$F47,BN$5<=$G47),2,"")
A48: 2 Elaboración | B48: 2.2.1 | C48: Plan de seguridad de la información | D48: E | E48: Seguridad | F48: 2 | G48: 2 | H48: =G48-F48+1 | I48: 240 | J48: Con entregable (actividades en hoja «Actividades hasta H2») | K48: =IF(AND(K$5>=$F48,K$5<=$G48),2,"") | L48: =IF(AND(L$5>=$F48,L$5<=$G48),2,"") | M48: =IF(AND(M$5>=$F48,M$5<=$G48),2,"") | N48: =IF(AND(N$5>=$F48,N$5<=$G48),2,"") | O48: =IF(AND(O$5>=$F48,O$5<=$G48),2,"") | P48: =IF(AND(P$5>=$F48,P$5<=$G48),2,"") | Q48: =IF(AND(Q$5>=$F48,Q$5<=$G48),2,"") | R48: =IF(AND(R$5>=$F48,R$5<=$G48),2,"") | ... BN48: =IF(AND(BN$5>=$F48,BN$5<=$G48),2,"")
A49: 2 Elaboración | B49: 2.2.2 | C49: Modelado de amenazas por componente y por integración externa, actualizado ante cada cambio | D49: E | E49: Seguridad | F49: 3 | G49: 10 | H49: =G49-F49+1 | I49: 240 | J49: Esfuerzo continuo (por quincena u ocurrencia) | K49: =IF(AND(K$5>=$F49,K$5<=$G49),2,"") | L49: =IF(AND(L$5>=$F49,L$5<=$G49),2,"") | M49: =IF(AND(M$5>=$F49,M$5<=$G49),2,"") | N49: =IF(AND(N$5>=$F49,N$5<=$G49),2,"") | O49: =IF(AND(O$5>=$F49,O$5<=$G49),2,"") | P49: =IF(AND(P$5>=$F49,P$5<=$G49),2,"") | Q49: =IF(AND(Q$5>=$F49,Q$5<=$G49),2,"") | R49: =IF(AND(R$5>=$F49,R$5<=$G49),2,"") | ... BN49: =IF(AND(BN$5>=$F49,BN$5<=$G49),2,"")
A50: 2 Elaboración | B50: 2.2.3 | C50: Plan de respuesta a incidentes de seguridad, con aviso al CLIENTE en dos horas | D50: E | E50: Seguridad | F50: 3 | G50: 3 | H50: =G50-F50+1 | I50: 240 | J50: Con entregable (actividades en hoja «Actividades hasta H2») | K50: =IF(AND(K$5>=$F50,K$5<=$G50),2,"") | L50: =IF(AND(L$5>=$F50,L$5<=$G50),2,"") | M50: =IF(AND(M$5>=$F50,M$5<=$G50),2,"") | N50: =IF(AND(N$5>=$F50,N$5<=$G50),2,"") | O50: =IF(AND(O$5>=$F50,O$5<=$G50),2,"") | P50: =IF(AND(P$5>=$F50,P$5<=$G50),2,"") | Q50: =IF(AND(Q$5>=$F50,Q$5<=$G50),2,"") | R50: =IF(AND(R$5>=$F50,R$5<=$G50),2,"") | ... BN50: =IF(AND(BN$5>=$F50,BN$5<=$G50),2,"")
A51: 2 Elaboración | B51: 2.2.4 | C51: Matriz de clasificación de la información y matriz de controles | D51: E | E51: Seguridad | F51: 2 | G51: 2 | H51: =G51-F51+1 | I51: 240 | J51: Con entregable (actividades en hoja «Actividades hasta H2») | K51: =IF(AND(K$5>=$F51,K$5<=$G51),2,"") | L51: =IF(AND(L$5>=$F51,L$5<=$G51),2,"") | M51: =IF(AND(M$5>=$F51,M$5<=$G51),2,"") | N51: =IF(AND(N$5>=$F51,N$5<=$G51),2,"") | O51: =IF(AND(O$5>=$F51,O$5<=$G51),2,"") | P51: =IF(AND(P$5>=$F51,P$5<=$G51),2,"") | Q51: =IF(AND(Q$5>=$F51,Q$5<=$G51),2,"") | R51: =IF(AND(R$5>=$F51,R$5<=$G51),2,"") | ... BN51: =IF(AND(BN$5>=$F51,BN$5<=$G51),2,"")
A52: 2 Elaboración | B52: 2.3.1 | C52: Plano de la sala técnica de Talca, con su cálculo eléctrico y térmico | D52: E | E52: Operación / SRE | F52: 1 | G52: 2 | H52: =G52-F52+1 | I52: 240 | J52: Con entregable (actividades en hoja «Actividades hasta H2») | K52: =IF(AND(K$5>=$F52,K$5<=$G52),2,"") | L52: =IF(AND(L$5>=$F52,L$5<=$G52),2,"") | M52: =IF(AND(M$5>=$F52,M$5<=$G52),2,"") | N52: =IF(AND(N$5>=$F52,N$5<=$G52),2,"") | O52: =IF(AND(O$5>=$F52,O$5<=$G52),2,"") | P52: =IF(AND(P$5>=$F52,P$5<=$G52),2,"") | Q52: =IF(AND(Q$5>=$F52,Q$5<=$G52),2,"") | R52: =IF(AND(R$5>=$F52,R$5<=$G52),2,"") | ... BN52: =IF(AND(BN$5>=$F52,BN$5<=$G52),2,"")
A53: 2 Elaboración | B53: 2.3.2 | C53: Plano de distribución de los racks R01 de servidores y R02 de comunicaciones | D53: E | E53: Operación / SRE | F53: 1 | G53: 2 | H53: =G53-F53+1 | I53: 240 | J53: Con entregable (actividades en hoja «Actividades hasta H2») | K53: =IF(AND(K$5>=$F53,K$5<=$G53),2,"") | L53: =IF(AND(L$5>=$F53,L$5<=$G53),2,"") | M53: =IF(AND(M$5>=$F53,M$5<=$G53),2,"") | N53: =IF(AND(N$5>=$F53,N$5<=$G53),2,"") | O53: =IF(AND(O$5>=$F53,O$5<=$G53),2,"") | P53: =IF(AND(P$5>=$F53,P$5<=$G53),2,"") | Q53: =IF(AND(Q$5>=$F53,Q$5<=$G53),2,"") | R53: =IF(AND(R$5>=$F53,R$5<=$G53),2,"") | ... BN53: =IF(AND(BN$5>=$F53,BN$5<=$G53),2,"")
A54: 2 Elaboración | B54: 2.3.3 | C54: Plano de los gabinetes de borde de Concepción y de las plataformas de cross-docking | D54: E | E54: Operación / SRE | F54: 2 | G54: 2 | H54: =G54-F54+1 | I54: 240 | J54: Con entregable (actividades en hoja «Actividades hasta H2») | K54: =IF(AND(K$5>=$F54,K$5<=$G54),2,"") | L54: =IF(AND(L$5>=$F54,L$5<=$G54),2,"") | M54: =IF(AND(M$5>=$F54,M$5<=$G54),2,"") | N54: =IF(AND(N$5>=$F54,N$5<=$G54),2,"") | O54: =IF(AND(O$5>=$F54,O$5<=$G54),2,"") | P54: =IF(AND(P$5>=$F54,P$5<=$G54),2,"") | Q54: =IF(AND(Q$5>=$F54,Q$5<=$G54),2,"") | R54: =IF(AND(R$5>=$F54,R$5<=$G54),2,"") | ... BN54: =IF(AND(BN$5>=$F54,BN$5<=$G54),2,"")
A55: 2 Elaboración | B55: 2.4.1 | C55: Acta de aprobación de la arquitectura, el plan de seguridad y el modelo de datos (H2) | D55: E | E55: Arquitectura | F55: 3 | G55: 3 | H55: =G55-F55+1 | I55: 240 | J55: Con entregable (actividades en hoja «Actividades hasta H2») | K55: =IF(AND(K$5>=$F55,K$5<=$G55),2,"") | L55: =IF(AND(L$5>=$F55,L$5<=$G55),2,"") | M55: =IF(AND(M$5>=$F55,M$5<=$G55),2,"") | N55: =IF(AND(N$5>=$F55,N$5<=$G55),2,"") | O55: =IF(AND(O$5>=$F55,O$5<=$G55),2,"") | P55: =IF(AND(P$5>=$F55,P$5<=$G55),2,"") | Q55: =IF(AND(Q$5>=$F55,Q$5<=$G55),2,"") | R55: =IF(AND(R$5>=$F55,R$5<=$G55),2,"") | ... BN55: =IF(AND(BN$5>=$F55,BN$5<=$G55),2,"")
... A61: 2 Elaboración | B61: 2.6.3 | C61: Indicadores de usabilidad comprometidos por transacción crítica | D61: E | E61: Implantación y gestión del cambio | F61: 4 | G61: 4 | H61: =G61-F61+1 | I61: 240 | J61: Con entregable (actividades en hoja «Actividades hasta H2») | K61: =IF(AND(K$5>=$F61,K$5<=$G61),2,"") | L61: =IF(AND(L$5>=$F61,L$5<=$G61),2,"") | M61: =IF(AND(M$5>=$F61,M$5<=$G61),2,"") | N61: =IF(AND(N$5>=$F61,N$5<=$G61),2,"") | O61: =IF(AND(O$5>=$F61,O$5<=$G61),2,"") | P61: =IF(AND(P$5>=$F61,P$5<=$G61),2,"") | Q61: =IF(AND(Q$5>=$F61,Q$5<=$G61),2,"") | R61: =IF(AND(R$5>=$F61,R$5<=$G61),2,"") | ... BN61: =IF(AND(BN$5>=$F61,BN$5<=$G61),2,"")
A62: 3 Construcción | B62: 3.1.1 | C62: Ambientes de Desarrollo y QA en la nube (H3) | D62: E | E62: Operación / SRE | F62: 5 | G62: 5 | H62: =G62-F62+1 | I62: 240 | J62: Con entregable (detalle por planificación gradual) | K62: =IF(AND(K$5>=$F62,K$5<=$G62),3,"") | L62: =IF(AND(L$5>=$F62,L$5<=$G62),3,"") | M62: =IF(AND(M$5>=$F62,M$5<=$G62),3,"") | N62: =IF(AND(N$5>=$F62,N$5<=$G62),3,"") | O62: =IF(AND(O$5>=$F62,O$5<=$G62),3,"") | P62: =IF(AND(P$5>=$F62,P$5<=$G62),3,"") | Q62: =IF(AND(Q$5>=$F62,Q$5<=$G62),3,"") | R62: =IF(AND(R$5>=$F62,R$5<=$G62),3,"") | ... BN62: =IF(AND(BN$5>=$F62,BN$5<=$G62),3,"")
A63: 3 Construcción | B63: 3.1.2 | C63: Ambientes de Preproducción y Producción en la nube (H3) | D63: E | E63: Operación / SRE | F63: 5 | G63: 5 | H63: =G63-F63+1 | I63: 240 | J63: Con entregable (detalle por planificación gradual) | K63: =IF(AND(K$5>=$F63,K$5<=$G63),3,"") | L63: =IF(AND(L$5>=$F63,L$5<=$G63),3,"") | M63: =IF(AND(M$5>=$F63,M$5<=$G63),3,"") | N63: =IF(AND(N$5>=$F63,N$5<=$G63),3,"") | O63: =IF(AND(O$5>=$F63,O$5<=$G63),3,"") | P63: =IF(AND(P$5>=$F63,P$5<=$G63),3,"") | Q63: =IF(AND(Q$5>=$F63,Q$5<=$G63),3,"") | R63: =IF(AND(R$5>=$F63,R$5<=$G63),3,"") | ... BN63: =IF(AND(BN$5>=$F63,BN$5<=$G63),3,"")
A64: 3 Construcción | B64: 3.1.3 | C64: Ambiente de recuperación ante desastres en la región secundaria (H3) | D64: E | E64: Operación / SRE | F64: 5 | G64: 5 | H64: =G64-F64+1 | I64: 240 | J64: Con entregable (detalle por planificación gradual) | K64: =IF(AND(K$5>=$F64,K$5<=$G64),3,"") | L64: =IF(AND(L$5>=$F64,L$5<=$G64),3,"") | M64: =IF(AND(M$5>=$F64,M$5<=$G64),3,"") | N64: =IF(AND(N$5>=$F64,N$5<=$G64),3,"") | O64: =IF(AND(O$5>=$F64,O$5<=$G64),3,"") | P64: =IF(AND(P$5>=$F64,P$5<=$G64),3,"") | Q64: =IF(AND(Q$5>=$F64,Q$5<=$G64),3,"") | R64: =IF(AND(R$5>=$F64,R$5<=$G64),3,"") | ... BN64: =IF(AND(BN$5>=$F64,BN$5<=$G64),3,"")
A65: 3 Construcción | B65: 3.1.4 | C65: Cadena de integración y entrega continua, e infraestructura como código | D65: E | E65: Operación / SRE | F65: 4 | G65: 4 | H65: =G65-F65+1 | I65: 240 | J65: Con entregable (actividades en hoja «Actividades hasta H2») | K65: =IF(AND(K$5>=$F65,K$5<=$G65),3,"") | L65: =IF(AND(L$5>=$F65,L$5<=$G65),3,"") | M65: =IF(AND(M$5>=$F65,M$5<=$G65),3,"") | N65: =IF(AND(N$5>=$F65,N$5<=$G65),3,"") | O65: =IF(AND(O$5>=$F65,O$5<=$G65),3,"") | P65: =IF(AND(P$5>=$F65,P$5<=$G65),3,"") | Q65: =IF(AND(Q$5>=$F65,Q$5<=$G65),3,"") | R65: =IF(AND(R$5>=$F65,R$5<=$G65),3,"") | ... BN65: =IF(AND(BN$5>=$F65,BN$5<=$G65),3,"")
A66: 3 Construcción | B66: 3.1.5 | C66: Observabilidad de los doce módulos y de los sitios, con tableros para el CLIENTE (H3) | D66: E | E66: Operación / SRE | F66: 5 | G66: 5 | H66: =G66-F66+1 | I66: 240 | J66: Con entregable (detalle por planificación gradual) | K66: =IF(AND(K$5>=$F66,K$5<=$G66),3,"") | L66: =IF(AND(L$5>=$F66,L$5<=$G66),3,"") | M66: =IF(AND(M$5>=$F66,M$5<=$G66),3,"") | N66: =IF(AND(N$5>=$F66,N$5<=$G66),3,"") | O66: =IF(AND(O$5>=$F66,O$5<=$G66),3,"") | P66: =IF(AND(P$5>=$F66,P$5<=$G66),3,"") | Q66: =IF(AND(Q$5>=$F66,Q$5<=$G66),3,"") | R66: =IF(AND(R$5>=$F66,R$5<=$G66),3,"") | ... BN66: =IF(AND(BN$5>=$F66,BN$5<=$G66),3,"")
A67: 3 Construcción | B67: 3.2.1 | C67: Servicio de nube para la aplicación y los portales | D67: E | E67: Operación / SRE | F67: 4 | G67: 4 | H67: =G67-F67+1 | I67: 240 | J67: Con entregable (actividades en hoja «Actividades hasta H2») | K67: =IF(AND(K$5>=$F67,K$5<=$G67),3,"") | L67: =IF(AND(L$5>=$F67,L$5<=$G67),3,"") | M67: =IF(AND(M$5>=$F67,M$5<=$G67),3,"") | N67: =IF(AND(N$5>=$F67,N$5<=$G67),3,"") | O67: =IF(AND(O$5>=$F67,O$5<=$G67),3,"") | P67: =IF(AND(P$5>=$F67,P$5<=$G67),3,"") | Q67: =IF(AND(Q$5>=$F67,Q$5<=$G67),3,"") | R67: =IF(AND(R$5>=$F67,R$5<=$G67),3,"") | ... BN67: =IF(AND(BN$5>=$F67,BN$5<=$G67),3,"")
...

Sheet Actividades hasta H2
A1: Actividad | B1: Paquete | C1: Nombre de la actividad | D1: Responsable (familia de rol) | E1: Personas asignadas | F1: HH | G1: Inicio | H1: Fin | I1: Días hábiles | J1: Predecesoras | K1: Día hábil n.º de inicio (dato T-15) | L1: Día hábil n.º de fin (dato T-15)
A2: 1.1.1.A01 | B2: 1.1.1 | C2: Elaboración, revisión y aprobación del entregable | D2: Jefe de Proyecto | E2: 2 | F2: 80 | G2: =WORKDAY('Parámetros'!$B$3-1,K2+1) | H2: =WORKDAY('Parámetros'!$B$3-1,L2+1) | I2: =NETWORKDAYS(G2,H2) | J2: — | K2: 0 | L2: 6
A3: 1.1.2.A01 | B3: 1.1.2 | C3: Elaboración, revisión y aprobación del entregable | D3: Jefe de Proyecto | E3: 2 | F3: 80 | G3: =WORKDAY('Parámetros'!$B$3-1,K3+1) | H3: =WORKDAY('Parámetros'!$B$3-1,L3+1) | I3: =NETWORKDAYS(G3,H3) | J3: — | K3: 0 | L3: 6
A4: 1.1.3.A01 | B4: 1.1.3 | C4: Elaboración, revisión y aprobación del entregable | D4: Jefe de Proyecto | E4: 2 | F4: 80 | G4: =WORKDAY('Parámetros'!$B$3-1,K4+1) | H4: =WORKDAY('Parámetros'!$B$3-1,L4+1) | I4: =NETWORKDAYS(G4,H4) | J4: — | K4: 0 | L4: 6
A5: 1.2.1.A01 | B5: 1.2.1 | C5: Elaboración, revisión y aprobación del entregable | D5: Arquitectura | E5: 2 | F5: 80 | G5: =WORKDAY('Parámetros'!$B$3-1,K5+1) | H5: =WORKDAY('Parámetros'!$B$3-1,L5+1) | I5: =NETWORKDAYS(G5,H5) | J5: — | K5: 0 | L5: 6
A6: 1.2.3.A01 | B6: 1.2.3 | C6: Elaboración, revisión y aprobación del entregable | D6: Arquitectura | E6: 2 | F6: 80 | G6: =WORKDAY('Parámetros'!$B$3-1,K6+1) | H6: =WORKDAY('Parámetros'!$B$3-1,L6+1) | I6: =NETWORKDAYS(G6,H6) | J6: — | K6: 0 | L6: 6
A7: 1.2.4.A01 | B7: 1.2.4 | C7: Elaboración, revisión y aprobación del entregable | D7: Calidad y pruebas | E7: 2 | F7: 80 | G7: =WORKDAY('Parámetros'!$B$3-1,K7+1) | H7: =WORKDAY('Parámetros'!$B$3-1,L7+1) | I7: =NETWORKDAYS(G7,H7) | J7: — | K7: 20 | L7: 26
A8: 1.3.1.A01 | B8: 1.3.1 | C8: Elaboración, revisión y aprobación del entregable | D8: Jefe de Proyecto | E8: 2 | F8: 80 | G8: =WORKDAY('Parámetros'!$B$3-1,K8+1) | H8: =WORKDAY('Parámetros'!$B$3-1,L8+1) | I8: =NETWORKDAYS(G8,H8) | J8: — | K8: 7 | L8: 13
A9: 1.3.2.A01 | B9: 1.3.2 | C9: Elaboración, revisión y aprobación del entregable | D9: Jefe de Proyecto | E9: 2 | F9: 80 | G9: =WORKDAY('Parámetros'!$B$3-1,K9+1) | H9: =WORKDAY('Parámetros'!$B$3-1,L9+1) | I9: =NETWORKDAYS(G9,H9) | J9: — | K9: 20 | L9: 26
A10: 1.3.3.A01 | B10: 1.3.3 | C10: Elaboración, revisión y aprobación del entregable | D10: Jefe de Proyecto | E10: 2 | F10: 80 | G10: =WORKDAY('Parámetros'!$B$3-1,K10+1) | H10: =WORKDAY('Parámetros'!$B$3-1,L10+1) | I10: =NETWORKDAYS(G10,H10) | J10: — | K10: 20 | L10: 26
A11: 1.3.4.A01 | B11: 1.3.4 | C11: Elaboración, revisión y aprobación del entregable | D11: Jefe de Proyecto | E11: 2 | F11: 80 | G11: =WORKDAY('Parámetros'!$B$3-1,K11+1) | H11: =WORKDAY('Parámetros'!$B$3-1,L11+1) | I11: =NETWORKDAYS(G11,H11) | J11: — | K11: 20 | L11: 26
A12: 1.4.1.A01 | B12: 1.4.1 | C12: Elaboración, revisión y aprobación del entregable | D12: Jefe de Proyecto | E12: 2 | F12: 80 | G12: =WORKDAY('Parámetros'!$B$3-1,K12+1) | H12: =WORKDAY('Parámetros'!$B$3-1,L12+1) | I12: =NETWORKDAYS(G12,H12) | J12: — | K12: 0 | L12: 6
A13: 1.4.2.A01 | B13: 1.4.2 | C13: Elaboración, revisión y aprobación del entregable | D13: Jefe de Proyecto | E13: 2 | F13: 80 | G13: =WORKDAY('Parámetros'!$B$3-1,K13+1) | H13: =WORKDAY('Parámetros'!$B$3-1,L13+1) | I13: =NETWORKDAYS(G13,H13) | J13: — | K13: 0 | L13: 6
... A109: 7.2.3.A02 | B109: 7.2.3 | C109: Prueba o evaluación, corrección y acta | D109: Implantación | E109: 2 | F109: 80 | G109: =WORKDAY('Parámetros'!$B$3-1,K109+1) | H109: =WORKDAY('Parámetros'!$B$3-1,L109+1) | I109: =NETWORKDAYS(G109,H109) | J109: 7.2.3.A01 | K109: 75 | L109: 81
A111: Fuente: Formulario T-15, Tabla 6.1b. Se muestran las 108 actividades de los paquetes que terminan hasta el H2; los demás paquetes se detallan por planificación gradual antes de cada fase (T-15, sección 6.1 y Figura T15.3).

Sheet Esfuerzo continuo
A1: Paquete | B1: Nombre del paquete | C1: Clase | D1: Inicio (mes) | E1: Fin (mes) | F1: HH (E) | G1: Regla de programación | H1: Relevos u ocurrencias | I1: HH máximas por relevo u ocurrencia
A2: 1.2.2 | B2: Documento de reglas de ruteo capturadas al planificador de rutas | C2: G | D2: 1 | E2: 3 | F2: 80 | G2: Una actividad por quincena, por presencia continua o periódica | H2: 6 | I2: 13.3
A3: 1.3.5 | B3: Reunión semanal de seguimiento con su informe semanal | C3: R | D3: 1 | E3: 20 | F3: 480 | G3: Una actividad de nivel de esfuerzo por quincena | H3: 40 | I3: 12
A4: 1.4.3 | B4: Registro de solicitudes de cambio con análisis de impacto | C4: R | D4: 1 | E4: 56 | F4: 896 | G4: Una actividad de nivel de esfuerzo por quincena | H4: 112 | I4: 8
A5: 1.5.2 | B5: Puertas de calidad automáticas en la cadena de integración (cobertura mínima del 80 %) | C5: G | D5: 6 | E5: 20 | F5: 80 | G5: Una actividad cada 3 quincenas, por presencia continua o periódica | H5: 10 | I5: 8
A6: 1.6.2 | B6: Registro de riesgos revisado en cada Comité de Proyecto | C6: R | D6: 1 | E6: 20 | F6: 160 | G6: Una actividad por ocurrencia (quincenal, en cada Comité de Proyecto), ejecutada dentro de una quincena; 1 actividad(es) por ocurrencia | H6: 40 | I6: 4
A7: 1.8.1 | B7: Oficina de gestión del proyecto con metodología basada en el PMBOK | C7: R | D7: 1 | E7: 20 | F7: 320 | G7: Una actividad de nivel de esfuerzo por quincena | H7: 40 | I7: 8
A8: 1.8.2 | B8: Actas del Comité Ejecutivo mensual, con la aprobación de los cambios de alcance | C8: R | D8: 1 | E8: 56 | F8: 448 | G8: Una actividad por ocurrencia (mensual), ejecutada dentro de una quincena; 1 actividad(es) por ocurrencia | H8: 56 | I8: 8
A9: 1.8.3 | B9: Actas del Comité de Proyecto quincenal | C9: R | D9: 1 | E9: 20 | F9: 240 | G9: Una actividad por ocurrencia (quincenal), ejecutada dentro de una quincena; 1 actividad(es) por ocurrencia | H9: 40 | I9: 6
A10: 1.8.4 | B10: Actas del Comité de Arquitectura mensual | C10: R | D10: 1 | E10: 56 | F10: 448 | G10: Una actividad por ocurrencia (mensual), ejecutada dentro de una quincena; 1 actividad(es) por ocurrencia | H10: 56 | I10: 8
A11: 1.8.5 | B11: Actas del Comité de Operación mensual, desde el mes 13 | C11: R | D11: 13 | E11: 56 | F11: 352 | G11: Una actividad por ocurrencia (mensual), ejecutada dentro de una quincena; 1 actividad(es) por ocurrencia | H11: 44 | I11: 8
A12: 1.8.6 | B12: Informe mensual de avance con valor ganado | C12: R | D12: 1 | E12: 20 | F12: 480 | G12: Una actividad por ocurrencia (mensual), ejecutada dentro de una quincena; 1 actividad(es) por ocurrencia | H12: 20 | I12: 24
A13: 1.8.7 | B13: Tablero de estado del proyecto disponible para el CLIENTE | C13: R | D13: 2 | E13: 56 | F13: 440 | G13: Una actividad cada 2 quincenas, ejecutada en la última quincena del grupo | H13: 55 | I13: 8
... A60: 9.2.1 | B60: Ejecución del Plan de Reversibilidad y acompañamiento de 90 días | C60: G | D60: 54 | E60: 56 | F60: 80 | G60: Una actividad por quincena, por presencia continua o periódica | H60: 6 | I60: 13.3
B62: Fuente: Formulario T-15, Tabla 6.2. Estos paquetes no producen un entregable único sino un servicio o una reunión que se repite; por eso no se dividen en actividades distintas.

Sheet Glosario
A1: Término | B1: Qué es | C1: Ejemplo en este proyecto | D1: Fuente
