Workbook

Sheet RESUMEN
A1: Resumen
A4: Costo de proyecto total Cliente | F4: Tarifa de proyecto total Empresa | K4: Margen / Utilidad
B5: UF | C5: CLP | D5: USD | G5: UF | H5: CLP | I5: USD | L5: UF | M5: CLP | N5: USD
A6: Total en Implementación | B6: =B18 -> 51593.643 | C6: =B6*PARÁMETROS!$B$4 -> 1857371130 | D6: =C6/PARÁMETROS!$B$2 -> 2063745.7 | F6: Total en Implementación | G6: =G18 -> 88013.019 | H6: =G6*PARÁMETROS!$B$4 -> 3168468702 | I6: =H6/PARÁMETROS!$B$2 -> 3520520.8 | K6: Total en Implementación | L6: =+G6-B6 -> 36419.377 | M6: =L6*PARÁMETROS!$B$4 -> 1.3110976e+09 | N6: =M6/PARÁMETROS!$B$2 -> 1456775.1
A7: Total en Soporte | B7: =B19 -> 84074 | C7: =B7*PARÁMETROS!$B$4 -> 3.026664e+09 | D7: =C7/PARÁMETROS!$B$2 -> 3362960 | F7: Total en Soporte | G7: =G19 -> 109838.8 | H7: =G7*PARÁMETROS!$B$4 -> 3.9541968e+09 | I7: =H7/PARÁMETROS!$B$2 -> 4393552 | K7: Total en Soporte | L7: =+G7-B7 -> 25764.8 | M7: =L7*PARÁMETROS!$B$4 -> 9.275328e+08 | N7: =M7/PARÁMETROS!$B$2 -> 1030592
A8: Total en Proyecto | B8: =SUM(B6:B7) -> 135667.64 | C8: =SUM(C6:C7) -> 4.8840351e+09 | D8: =SUM(D6:D7) -> 5426705.7 | F8: Total en Proyecto | G8: =SUM(G6:G7) -> 197851.82 | H8: =SUM(H6:H7) -> 7122665502 | I8: =SUM(I6:I7) -> 7914072.8 | K8: Total en Proyecto | L8: =SUM(L6:L7) -> 62184.177 | M8: =SUM(M6:M7) -> 2.2386304e+09 | N8: =SUM(N6:N7) -> 2487367.1
K9: Rentabilidad Nominal | L9: =+L8/B8 -> 0.45835673 | M9: =+M8/C8 -> 0.45835673 | N9: =+N8/D8 -> 0.45835673
A10: Costo por Ítem Cliente | F10: Tarifa por Ítem Empresa
B11: UF | C11: CLP | D11: USD | G11: UF | H11: CLP | I11: USD
A12: Implementación Recursos Humanos | B12: ='COSTOS DE OPERACION'!N50 -> 27019.2 | C12: =B12*PARÁMETROS!$B$4 -> 972691200 | D12: =C12/PARÁMETROS!$B$2 -> 1080768 | F12: Implementación Recursos Humanos | G12: ='TARIFAS DE OPERACION'!N50 -> 51470.4 | H12: =G12*PARÁMETROS!$B$4 -> 1852934400 | I12: =H12/PARÁMETROS!$B$2 -> 2058816
A13: Implementacion Adquisiciones | B13: =-SUM('FLUJO DE CAJA NETO'!C31:BB31) -> 14833.392 | C13: =B13*PARÁMETROS!$B$4 -> 534002130 | D13: =C13/PARÁMETROS!$B$2 -> 593335.7 | F13: Implementacion Adquisiciones | G13: =B13*(1+'TARIFAS DE OPERACION'!B62) -> 20766.749 | H13: =G13*PARÁMETROS!$B$4 -> 7.4760298e+08 | I13: =H13/PARÁMETROS!$B$2 -> 830669.98
A14: Implementación Capacitaciones | B14: ='COSTOS DE OPERACION'!N60 -> 1044 | C14: =B14*PARÁMETROS!$B$4 -> 37584000 | D14: =C14/PARÁMETROS!$B$2 -> 41760 | F14: Implementación Capacitaciones | G14: ='TARIFAS DE OPERACION'!N60 -> 3600 | H14: =G14*PARÁMETROS!$B$4 -> 129600000 | I14: =H14/PARÁMETROS!$B$2 -> 144000
A15: Implementacion Servicios | B15: =-SUM('FLUJO DE CAJA NETO'!B33:N43) -> 8697.05 | C15: =B15*PARÁMETROS!$B$4 -> 313093800 | D15: =C15/PARÁMETROS!$B$2 -> 347882 | F15: Implementacion Servicios | G15: =-SUM('FLUJO DE CAJA NETO'!B33:N43)*(1+'TARIFAS DE OPERACION'!B62) -> 12175.87 | H15: =G15*PARÁMETROS!$B$4 -> 4.3833132e+08 | I15: =H15/PARÁMETROS!$B$2 -> 487034.8
A16: Soporte Recursos Humanos | B16: ='COSTOS DE OPERACION'!BJ50 -> 30627.2 | C16: =B16*PARÁMETROS!$B$4 -> 1.1025792e+09 | D16: =C16/PARÁMETROS!$B$2 -> 1225088 | F16: Soporte Recursos Humanos | G16: ='TARIFAS DE OPERACION'!BJ50 -> 56392 | H16: =G16*PARÁMETROS!$B$4 -> 2030112000 | I16: =H16/PARÁMETROS!$B$2 -> 2255680
A17: Soporte Servicios | B17: =-SUM('FLUJO DE CAJA NETO'!O33:BJ43) -> 53446.8 | C17: =B17*PARÁMETROS!$B$4 -> 1.9240848e+09 | D17: =C17/PARÁMETROS!$B$2 -> 2137872 | F17: Soporte Servicios | G17: =-SUM('FLUJO DE CAJA NETO'!O33:BJ43) -> 53446.8 | H17: =G17*PARÁMETROS!$B$4 -> 1.9240848e+09 | I17: =H17/PARÁMETROS!$B$2 -> 2137872
A18: Total Implementación | B18: =SUM(B12:B15) -> 51593.643 | C18: =SUM(C12:C14) -> 1544277330 | D18: =SUM(D12:D14) -> 1715863.7 | F18: Total Implementación | G18: =SUM(G12:G15) -> 88013.019 | H18: =SUM(H12:H15) -> 3168468702 | I18: =SUM(I12:I15) -> 3520520.8
A19: Total Soporte | B19: =SUM(B16:B17) -> 84074 | C19: =SUM(C16) -> 1.1025792e+09 | D19: =SUM(D16) -> 1225088 | F19: Total Soporte | G19: =SUM(G16:G17) -> 109838.8 | H19: =SUM(H16:H17) -> 3.9541968e+09 | I19: =SUM(I16:I17) -> 4393552
A20: Total Proyecto | B20: =SUM(B18:B19) -> 135667.64 | C20: =SUM(C18:C19) -> 2.6468565e+09 | D20: =SUM(D18:D19) -> 2940951.7 | F20: Total Proyecto | G20: =SUM(G18:G19) -> 197851.82 | H20: =SUM(H18:H19) -> 7122665502 | I20: =SUM(I18:I19) -> 7914072.8
F21: VAN | G21: ='FLUJO DE CAJA COMPLETO'!B23 -> 136691.93
F22: TIR | G22: ='FLUJO DE CAJA COMPLETO'!B26 -> 0.064893093
A23: Viabilidad y HH
B24: Valor
A25: Cantidad Punto Caso de Uso Ajustados | B25: =PCUESFUERZO!G37 -> 341.75235 | C25: Puntos
A26: Factor de Conversión a HH | B26: 20
A27: Cantidad HH Programacion | B27: =PCUESFUERZO!H44 -> 6835.047 | C27: Horas
A28: Cantidad HH Proyecto | B28: =PCUESFUERZO!H47 -> 18796.379 | C28: Horas
A29: Costo Total (Según Tablas) del Proyecto | B29: =G8 -> 197851.82 | C29: UF
A30: Venta Total (Según Tablas) del Proyecto | B30: =B8 -> 135667.64 | C30: UF

Sheet PARÁMETROS
A1: CONVERSIONES | B1: CLP
A2: Dólar | B2: 900 | C2: =+B2/B4 -> 0.025
A3: Euro | B3: 800 | C3: =+B3/B4 -> 0.022222222
A4: UF | B4: 36000 | C4: =+B4/B2 -> 40
A5: HH Mes | B5: 160 | C5: horas
A7: DATOS
A8: Tasa Interes de Prestamo (Mensual) | B8: 0.009
A9: Linea de Credito | B9: 50000000 | C9: CLP
A10: Tasa Interes de LC (Mensual) | B10: 0.03
A11: Impuestos | B11: 0.27
A12: Tasa Inversionista (Anual) | B12: 0.18
A13: Tasa Inversionista (Mensual) | B13: =((1+B12)^(1/12))-1 -> 0.01388843
A14: Porcentaje de financiamiento propio | B14: 0.2
A15: Porcentaje de financiamiento banco | B15: 0.8

Sheet CURVA S
A30: FLUJO DE CAJA
A32: Mes | B32: 0 | C32: 1 | D32: 2 | E32: 3 | F32: 4 | G32: 5 | H32: 6 | I32: 7 | J32: 8 | K32: 9 | L32: 10 | M32: 11 | N32: 12 | O32: 13 | P32: 14 | Q32: 15 | R32: 16 | S32: 17 | T32: 18 | U32: 19 | V32: 20 | W32: 21 | X32: 22 | Y32: 23 | Z32: 24 | AA32: 25 | AB32: 26 | AC32: 27 | AD32: 28 | AE32: 29 | AF32: 30 | AG32: 31 | AH32: 32 | AI32: 33 | AJ32: 34 | AK32: 35 | AL32: =AK32+1 -> 36 | AM32: =AL32+1 -> 37 | AN32: =AM32+1 -> 38 | AO32: =AN32+1 -> 39 | AP32: =AO32+1 -> 40 | AQ32: =AP32+1 -> 41 | AR32: =AQ32+1 -> 42 | AS32: =AR32+1 -> 43 | ... BJ32: =BI32+1 -> 60
A33: Fecha | C33: 45292 | D33: 45323 | E33: 45352 | F33: 45383 | G33: 45413 | H33: 45444 | I33: 45474 | J33: 45505 | K33: 45536 | L33: 45566 | M33: 45597 | N33: 45627 | O33: 45658 | P33: 45689 | Q33: 45717 | R33: 45748 | S33: 45778 | T33: 45809 | U33: 45839 | V33: 45870 | W33: 45901 | X33: 45931 | Y33: 45962 | Z33: 45992 | AA33: 46023 | AB33: 46054 | AC33: 46082 | AD33: 46113 | AE33: 46143 | AF33: 46174 | AG33: 46204 | AH33: 46235 | AI33: 46266 | AJ33: 46296 | AK33: =AJ33+31 -> 46327 | AL33: =AK33+31 -> 46358 | AM33: =AL33+31 -> 46389 | AN33: =AM33+31 -> 46420 | AO33: =AN33+31 -> 46451 | AP33: =AO33+31 -> 46482 | AQ33: =AP33+31 -> 46513 | AR33: =AQ33+31 -> 46544 | ... BJ33: =BI33+31 -> 47102
A34: A.2 - INGRESO ACUMULADO | B34: ='FLUJO DE CAJA COMPLETO'!B5 -> 108534.11 | C34: =B34+'FLUJO DE CAJA COMPLETO'!C5 -> 108534.11 | D34: =C34+'FLUJO DE CAJA COMPLETO'!D5 -> 126136.72 | E34: =D34+'FLUJO DE CAJA COMPLETO'!E5 -> 126136.72 | F34: =E34+'FLUJO DE CAJA COMPLETO'!F5 -> 126136.72 | G34: =F34+'FLUJO DE CAJA COMPLETO'!G5 -> 126136.72 | H34: =G34+'FLUJO DE CAJA COMPLETO'!H5 -> 126136.72 | I34: =H34+'FLUJO DE CAJA COMPLETO'!I5 -> 152540.62 | J34: =I34+'FLUJO DE CAJA COMPLETO'!J5 -> 152540.62 | ... BJ34: =BI34+'FLUJO DE CAJA COMPLETO'!BJ5 -> 308209.93
A35: B.2.- EGRESO TOTAL | B35: ='FLUJO DE CAJA NETO'!B26 -> 27133.529 | C35: ='FLUJO DE CAJA NETO'!C26 -> 34629.997 | D35: ='FLUJO DE CAJA NETO'!D26 -> 42126.465 | E35: ='FLUJO DE CAJA NETO'!E26 -> 49574.934 | F35: ='FLUJO DE CAJA NETO'!F26 -> 56026.602 | G35: ='FLUJO DE CAJA NETO'!G26 -> 64851.171 | H35: ='FLUJO DE CAJA NETO'!H26 -> 73675.739 | I35: ='FLUJO DE CAJA NETO'!I26 -> 87070.147 | ... BJ35: ='FLUJO DE CAJA NETO'!BJ26 -> 222338.79
A37: RESULTADO DEL MES | B37: ='FLUJO DE CAJA COMPLETO'!B16 -> 81400.586 | C37: ='FLUJO DE CAJA COMPLETO'!C16 -> -5472.4219 | D37: ='FLUJO DE CAJA COMPLETO'!D16 -> 7377.4789 | E37: ='FLUJO DE CAJA COMPLETO'!E16 -> -5437.3819 | F37: ='FLUJO DE CAJA COMPLETO'!F16 -> -4709.7179 | G37: ='FLUJO DE CAJA COMPLETO'!G16 -> -5726.0057 | H37: ='FLUJO DE CAJA COMPLETO'!H16 -> -5726.0057 | I37: ='FLUJO DE CAJA COMPLETO'!I16 -> 10276.355 | ... BJ37: ='FLUJO DE CAJA COMPLETO'!BJ16 -> 69106.035
A38: RESULTADO ACUMULADO | B38: ='FLUJO DE CAJA COMPLETO'!B21 -> 81400.586 | C38: ='FLUJO DE CAJA COMPLETO'!C21 -> 76003.126 | D38: ='FLUJO DE CAJA COMPLETO'!D21 -> 83179.873 | E38: ='FLUJO DE CAJA COMPLETO'!E21 -> 77962.891 | F38: ='FLUJO DE CAJA COMPLETO'!F21 -> 73505.977 | G38: ='FLUJO DE CAJA COMPLETO'!G21 -> 68161.553 | H38: ='FLUJO DE CAJA COMPLETO'!H21 -> 62890.337 | I38: ='FLUJO DE CAJA COMPLETO'!I21 -> 72220.902 | ... BJ38: ='FLUJO DE CAJA COMPLETO'!BJ21 -> 136691.93
A40: PUNTO EQUILIBRIO | B40: {=INDEX(C38:BJ38,0,MATCH(TRUE,INDEX(C35:BJ35>0,1,0),0))} -> 76003.126 | C40: {=INDEX(C33:AK33,0,MATCH(TRUE,INDEX(C35:AK35>0,1,0),0))} -> 45292
A41: MES MAS BAJO | B41: {=INDEX(C38:BJ38,0,MATCH(TRUE,INDEX(C38:BJ38=MIN(C38:BJ38),1,0),0))} -> 56294.668 | C41: {=INDEX(C33:AK33,0,MATCH(TRUE,INDEX(C38:AK38=MIN(C38:AK38),1,0),0))} -> 45536
A42: TIR | B42: =IRR(C37:BJ37) -> 0.064893093

Sheet FINANCIAMIENTO
A1: CONVERSIONES | B1: CLP
A2: Dólar | B2: ='Costos HH - Sueldos'!B3 -> 900 | C2: =+B2/B4 -> 0.025
A3: Euro | B3: ='Costos HH - Sueldos'!B4 -> 800 | C3: =+B3/B4 -> 0.022222222 | F3: UF | G3: USD | H3: CLP
A4: UF | B4: ='Costos HH - Sueldos'!B5 -> 36000 | C4: =+B4/B2 -> 40 | E4: Monto Credito | F4: =RESUMEN!B8*PARÁMETROS!B15 -> 108534.11 | G4: =H4/B2 -> 4341364.6 | H4: =F4*B4 -> 3.9072281e+09
A5: HH Mes | B5: 160 | C5: horas
A7: DATOS | E7: HITOS DE PAGO | F7: Fecha | G7: Pago
A8: Porcentaje de financiamiento propio | B8: =PARÁMETROS!B14 -> 0.2 | E8: Hito 1: Análisis | F8: 45323 | G8: ='FLUJO DE CAJA NETO'!D16 -> 17602.604
A9: Porcentaje de financiamiento banco | B9: =PARÁMETROS!B15 -> 0.8 | E9: Hito 3: Entrega de página web y datacenter | F9: 45474 | G9: ='FLUJO DE CAJA NETO'!I17 -> 26403.906
A10: Tasa Interes de Prestamo (Mensual) | B10: =PARÁMETROS!B8 -> 0.009 | E10: Hito 4: Certificación de solución | F10: 45579 | G10: ='FLUJO DE CAJA NETO'!L18 -> 26403.906
A11: Tasa Interes de LC (Mensual) | B11: =PARÁMETROS!B10 -> 0.03 | E11: Hito 5: Lanzamiento de plataforma | F11: 45635 | G11: ='FLUJO DE CAJA NETO'!N19 -> 17602.604
A12: Impuestos | B12: =PARÁMETROS!B11 -> 0.27 | E12: Pago Mensual | F12: DESDE ene 2025 | G12: ='FLUJO DE CAJA NETO'!O20 -> 2288.3083
A13: Cuotas | B13: 24 | E13: Credito Banco | G13: ='FLUJO DE CAJA NETO'!B21 -> 108534.11
A14: VAN Financiamiento | B14: {=F4+NPV($B$11,L18:L29)} -> 60384.821
A16: Tabla Amortizacion del Credito | G16: Flujo de Financiamiento
A17: Mes | B17: Saldo | C17: Cuota | D17: Interés Mensual | E17: Amortización | G17: Mes | H17: Interés Mensual | I17: Ahorro Tributario | J17: Con impuestos | K17: Amortización | L17: Flujo Neto Financiamiento
A18: 1 | B18: =F4 -> 108534.11 | C18: =-PMT($B$10,$B$13,$B$18) -> 5048.4684 | D18: =$B$10*B18 -> 976.80703 | E18: =C18-D18 -> 4071.6614 | G18: 1 | H18: =-D18 -> -976.80703 | I18: =-$B$12*H18 -> 263.7379 | J18: =H18+I18 -> -713.06913 | K18: =-E18 -> -4071.6614 | L18: =K18+J18 -> -4784.7305
A19: 2 | B19: =B18-E18 -> 104462.45 | C19: =-PMT($B$10,$B$13,$B$18) -> 5048.4684 | D19: =$B$10*B19 -> 940.16207 | E19: =C19-D19 -> 4108.3063 | G19: 2 | H19: =-D19 -> -940.16207 | I19: =-$B$12*H19 -> 253.84376 | J19: =H19+I19 -> -686.31831 | K19: =-E19 -> -4108.3063 | L19: =K19+J19 -> -4794.6247
A20: 3 | B20: =B19-E19 -> 100354.15 | C20: =-PMT($B$10,$B$13,$B$18) -> 5048.4684 | D20: =$B$10*B20 -> 903.18732 | E20: =C20-D20 -> 4145.2811 | G20: 3 | H20: =-D20 -> -903.18732 | I20: =-$B$12*H20 -> 243.86058 | J20: =H20+I20 -> -659.32674 | K20: =-E20 -> -4145.2811 | L20: =K20+J20 -> -4804.6078
A21: 4 | B21: =B20-E20 -> 96208.865 | C21: =-PMT($B$10,$B$13,$B$18) -> 5048.4684 | D21: =$B$10*B21 -> 865.87979 | E21: =C21-D21 -> 4182.5886 | G21: 4 | H21: =-D21 -> -865.87979 | I21: =-$B$12*H21 -> 233.78754 | J21: =H21+I21 -> -632.09224 | K21: =-E21 -> -4182.5886 | L21: =K21+J21 -> -4814.6809
A22: 5 | B22: =B21-E21 -> 92026.277 | C22: =-PMT($B$10,$B$13,$B$18) -> 5048.4684 | D22: =$B$10*B22 -> 828.23649 | E22: =C22-D22 -> 4220.2319 | G22: 5 | H22: =-D22 -> -828.23649 | I22: =-$B$12*H22 -> 223.62385 | J22: =H22+I22 -> -604.61264 | K22: =-E22 -> -4220.2319 | L22: =K22+J22 -> -4824.8446
A23: 6 | B23: =B22-E22 -> 87806.045 | C23: =-PMT($B$10,$B$13,$B$18) -> 5048.4684 | D23: =$B$10*B23 -> 790.2544 | E23: =C23-D23 -> 4258.214 | G23: 6 | H23: =-D23 -> -790.2544 | I23: =-$B$12*H23 -> 213.36869 | J23: =H23+I23 -> -576.88571 | K23: =-E23 -> -4258.214 | L23: =K23+J23 -> -4835.0997
A24: 7 | B24: =B23-E23 -> 83547.831 | C24: =-PMT($B$10,$B$13,$B$18) -> 5048.4684 | D24: =$B$10*B24 -> 751.93048 | E24: =C24-D24 -> 4296.5379 | G24: 7 | H24: =-D24 -> -751.93048 | I24: =-$B$12*H24 -> 203.02123 | J24: =H24+I24 -> -548.90925 | K24: =-E24 -> -4296.5379 | L24: =K24+J24 -> -4845.4472
A25: 8 | B25: =B24-E24 -> 79251.293 | C25: =-PMT($B$10,$B$13,$B$18) -> 5048.4684 | D25: =$B$10*B25 -> 713.26163 | E25: =C25-D25 -> 4335.2068 | G25: 8 | H25: =-D25 -> -713.26163 | I25: =-$B$12*H25 -> 192.58064 | J25: =H25+I25 -> -520.68099 | K25: =-E25 -> -4335.2068 | L25: =K25+J25 -> -4855.8878
A26: 9 | B26: =B25-E25 -> 74916.086 | C26: =-PMT($B$10,$B$13,$B$18) -> 5048.4684 | D26: =$B$10*B26 -> 674.24477 | E26: =C26-D26 -> 4374.2237 | G26: 9 | H26: =-D26 -> -674.24477 | I26: =-$B$12*H26 -> 182.04609 | J26: =H26+I26 -> -492.19868 | K26: =-E26 -> -4374.2237 | L26: =K26+J26 -> -4866.4223
A27: 10 | B27: =B26-E26 -> 70541.862 | C27: =-PMT($B$10,$B$13,$B$18) -> 5048.4684 | D27: =$B$10*B27 -> 634.87676 | E27: =C27-D27 -> 4413.5917 | G27: 10 | H27: =-D27 -> -634.87676 | I27: =-$B$12*H27 -> 171.41673 | J27: =H27+I27 -> -463.46003 | K27: =-E27 -> -4413.5917 | L27: =K27+J27 -> -4877.0517
A28: 11 | B28: =B27-E27 -> 66128.271 | C28: =-PMT($B$10,$B$13,$B$18) -> 5048.4684 | D28: =$B$10*B28 -> 595.15443 | E28: =C28-D28 -> 4453.314 | G28: 11 | H28: =-D28 -> -595.15443 | I28: =-$B$12*H28 -> 160.6917 | J28: =H28+I28 -> -434.46274 | K28: =-E28 -> -4453.314 | L28: =K28+J28 -> -4887.7767
A29: =A28+1 -> 12 | B29: =B28-E28 -> 61674.957 | C29: =-PMT($B$10,$B$13,$B$18) -> 5048.4684 | D29: =$B$10*B29 -> 555.07461 | E29: =C29-D29 -> 4493.3938 | G29: 12 | H29: =-D29 -> -555.07461 | I29: =-$B$12*H29 -> 149.87014 | J29: =H29+I29 -> -405.20446 | K29: =-E29 -> -4493.3938 | L29: =K29+J29 -> -4898.5983
A30: =A29+1 -> 13 | B30: =B29-E29 -> 57181.563 | C30: =-PMT($B$10,$B$13,$B$18) -> 5048.4684 | D30: =$B$10*B30 -> 514.63406 | E30: =C30-D30 -> 4533.8344 | G30: =G29+1 -> 13 | H30: =-D30 -> -514.63406 | I30: =-$B$12*H30 -> 138.9512 | J30: =H30+I30 -> -375.68287 | K30: =-E30 -> -4533.8344 | L30: =K30+J30 -> -4909.5172
A31: =A30+1 -> 14 | B31: =B30-E30 -> 52647.728 | C31: =-PMT($B$10,$B$13,$B$18) -> 5048.4684 | D31: =$B$10*B31 -> 473.82956 | E31: =C31-D31 -> 4574.6389 | G31: =G30+1 -> 14 | H31: =-D31 -> -473.82956 | I31: =-$B$12*H31 -> 127.93398 | J31: =H31+I31 -> -345.89558 | K31: =-E31 -> -4574.6389 | L31: =K31+J31 -> -4920.5344
A32: =A31+1 -> 15 | B32: =B31-E31 -> 48073.089 | C32: =-PMT($B$10,$B$13,$B$18) -> 5048.4684 | D32: =$B$10*B32 -> 432.65781 | E32: =C32-D32 -> 4615.8106 | G32: =G31+1 -> 15 | H32: =-D32 -> -432.65781 | I32: =-$B$12*H32 -> 116.81761 | J32: =H32+I32 -> -315.8402 | K32: =-E32 -> -4615.8106 | L32: =K32+J32 -> -4931.6508
A33: =A32+1 -> 16 | B33: =B32-E32 -> 43457.279 | C33: =-PMT($B$10,$B$13,$B$18) -> 5048.4684 | D33: =$B$10*B33 -> 391.11551 | E33: =C33-D33 -> 4657.3529 | G33: =G32+1 -> 16 | H33: =-D33 -> -391.11551 | I33: =-$B$12*H33 -> 105.60119 | J33: =H33+I33 -> -285.51432 | K33: =-E33 -> -4657.3529 | L33: =K33+J33 -> -4942.8672
A34: =A33+1 -> 17 | B34: =B33-E33 -> 38799.926 | C34: =-PMT($B$10,$B$13,$B$18) -> 5048.4684 | D34: =$B$10*B34 -> 349.19933 | E34: =C34-D34 -> 4699.2691 | G34: =G33+1 -> 17 | H34: =-D34 -> -349.19933 | I34: =-$B$12*H34 -> 94.28382 | J34: =H34+I34 -> -254.91551 | K34: =-E34 -> -4699.2691 | L34: =K34+J34 -> -4954.1846
A35: =A34+1 -> 18 | B35: =B34-E34 -> 34100.657 | C35: =-PMT($B$10,$B$13,$B$18) -> 5048.4684 | D35: =$B$10*B35 -> 306.90591 | E35: =C35-D35 -> 4741.5625 | G35: =G34+1 -> 18 | H35: =-D35 -> -306.90591 | I35: =-$B$12*H35 -> 82.864596 | J35: =H35+I35 -> -224.04132 | K35: =-E35 -> -4741.5625 | L35: =K35+J35 -> -4965.6038
A36: =A35+1 -> 19 | B36: =B35-E35 -> 29359.094 | C36: =-PMT($B$10,$B$13,$B$18) -> 5048.4684 | D36: =$B$10*B36 -> 264.23185 | E36: =C36-D36 -> 4784.2366 | G36: =G35+1 -> 19 | H36: =-D36 -> -264.23185 | I36: =-$B$12*H36 -> 71.342599 | J36: =H36+I36 -> -192.88925 | K36: =-E36 -> -4784.2366 | L36: =K36+J36 -> -4977.1258
A37: =A36+1 -> 20 | B37: =B36-E36 -> 24574.858 | C37: =-PMT($B$10,$B$13,$B$18) -> 5048.4684 | D37: =$B$10*B37 -> 221.17372 | E37: =C37-D37 -> 4827.2947 | G37: =G36+1 -> 20 | H37: =-D37 -> -221.17372 | I37: =-$B$12*H37 -> 59.716904 | J37: =H37+I37 -> -161.45682 | K37: =-E37 -> -4827.2947 | L37: =K37+J37 -> -4988.7515
A38: =A37+1 -> 21 | B38: =B37-E37 -> 19747.563 | C38: =-PMT($B$10,$B$13,$B$18) -> 5048.4684 | D38: =$B$10*B38 -> 177.72807 | E38: =C38-D38 -> 4870.7404 | G38: =G37+1 -> 21 | H38: =-D38 -> -177.72807 | I38: =-$B$12*H38 -> 47.986578 | J38: =H38+I38 -> -129.74149 | K38: =-E38 -> -4870.7404 | L38: =K38+J38 -> -5000.4818
A39: =A38+1 -> 22 | B39: =B38-E38 -> 14876.823 | C39: =-PMT($B$10,$B$13,$B$18) -> 5048.4684 | D39: =$B$10*B39 -> 133.8914 | E39: =C39-D39 -> 4914.577 | G39: =G38+1 -> 22 | H39: =-D39 -> -133.8914 | I39: =-$B$12*H39 -> 36.150679 | J39: =H39+I39 -> -97.740725 | K39: =-E39 -> -4914.577 | L39: =K39+J39 -> -5012.3177
A40: =A39+1 -> 23 | B40: =B39-E39 -> 9962.2457 | C40: =-PMT($B$10,$B$13,$B$18) -> 5048.4684 | D40: =$B$10*B40 -> 89.660211 | E40: =C40-D40 -> 4958.8082 | G40: =G39+1 -> 23 | H40: =-D40 -> -89.660211 | I40: =-$B$12*H40 -> 24.208257 | J40: =H40+I40 -> -65.451954 | K40: =-E40 -> -4958.8082 | L40: =K40+J40 -> -5024.2602
A41: =A40+1 -> 24 | B41: =B40-E40 -> 5003.4375 | C41: =-PMT($B$10,$B$13,$B$18) -> 5048.4684 | D41: =$B$10*B41 -> 45.030937 | E41: =C41-D41 -> 5003.4375 | G41: =G40+1 -> 24 | H41: =-D41 -> -45.030937 | I41: =-$B$12*H41 -> 12.158353 | J41: =H41+I41 -> -32.872584 | K41: =-E41 -> -5003.4375 | L41: =K41+J41 -> -5036.3101

Sheet PCUESFUERZO
A1: N | B1: Caso de uso | C1: Peso | F1: FACTORES TECNICOS
A2: 1-Gestion de licitaciones | E2: Factor | F2: Descripcion | G2: Valor(0-5) | H2: Peso | I2: Total | J2: Justificación
A3: Proveedor | E3: T1 | F3: Sistema distribuido | G3: 5 | H3: 2 | I3: =G3*H3 -> 10 | J3: Se solicita que sea sistema distribuido para que en caso de caer el sistema en Stgo los demas almacenes puedan seguir funcionando correctamente
B4: ver detalles de licitacion y bases | C4: 10 | E4: T2 | F4: Objetivos de performance o tiempo de respuesta | G4: 5 | H4: 1 | I4: =G4*H4 -> 5 | J4: Se requiere de un alto performance para el proyecto y ademas el tiempo de espera no debe superar el maximo solicitado
B5: realizar preguntas | C5: 5 | E5: T3 | F5: Eficiencia del usuario final | G5: 2 | H5: 1 | I5: =G5*H5 -> 2 | J5: L
B6: participar en licitación | C6: 10 | E6: T4 | F6: Procesamiento interno complejo | G6: 5 | H6: 1 | I6: =G6*H6 -> 5 | J6: Al estar interconectado a varios microservicios se espera que su procesamiento interno sea complejo
B7: Subir documentos | C7: 5 | E7: T5 | F7: El código debe ser reutilizable | G7: 5 | H7: 1 | I7: =G7*H7 -> 5 | J7: se solicita que sea un codigo escalable en caso de futuras actualizaciones.
B8: realizar seguimiento de etapas | C8: 10 | E8: T6 | F8: Facilidad de instalación | G8: 2 | H8: 0.5 | I8: =G8*H8 -> 1 | J8: No es relevante
B9: ver resultados | C9: 5 | E9: T7 | F9: Facilidad de uso | G9: 4 | H9: 0.5 | I9: =G9*H9 -> 2 | J9: Al ser usado por personas que no tendran capacitacion, debe tener una facilidad de uso y ser intuitivo.
B10: realizar reclamos | C10: 10 | E10: T8 | F10: Portabilidad | G10: 4 | H10: 2 | I10: =G10*H10 -> 8 | J10: Los modulos se utilizaran tanto en computador como tecnologia Handheld
B11: recepción de acta | C11: 15 | E11: T9 | F11: Facilidad de cambio | G11: 1 | H11: 1 | I11: =G11*H11 -> 1 | J11: No se espera cambios en requerimientos
B12: enviar boleta garantia | C12: 10 | E12: T10 | F12: Concurrencia | G12: 5 | H12: 1 | I12: =G12*H12 -> 5 | J12: Todos los modulos deben ser capaces de funcionar en paralelo
B13: ver historial de licitaciones | C13: 10 | E13: T11 | F13: Incluye objetivos especiales de seguridad | G13: 5 | H13: 1 | I13: =G13*H13 -> 5 | J13: Solicita objetivos especiales como verificacion de identidad, verificacion de empresa, seguridad de metodos de pago.
B14: eliminar postulación licitación | C14: 10 | E14: T12 | F14: Provee acceso directo a terceras partes | G14: 1 | H14: 1 | I14: =G14*H14 -> 1 | J14: No es relevante
B15: licitaciones participando | C15: 10 | E15: T13 | F15: Se requieren facilidades especiales de entrenamiento a usuarios | G15: 1 | H15: 1 | I15: =G15*H15 -> 1 | J15: El sistema no debe ser complejo de entender por ende no se requiere de capacitacion para usuarios finales
B16: sugerencias de licitaciones | C16: 5 | F16: TOTAL | I16: =SUM(I2:I15) -> 51
A17: Demandante
B18: crear licitación pública o privada | C18: 15
B19: adjuntar documentos y bases | C19: 15 | F19: FCT | G19: =0.6+0.01*I16 -> 1.11
B20: eventos de proceso de licitación | C20: 10
B21: publicar licitación | C21: 10
B22: guardar borrador licitación | C22: 15 | F22: FACTORES AMBIENTALES
B23: seleccionar proveedor | C23: 10 | E23: Factor | F23: Descripcion | G23: Valor(0-5) | H23: Peso | I23: Total | J23: Justificación
B24: ver historial de licitaciones | C24: 10 | E24: E1 | F24: Familiaridad con el modelo del proyecto | G24: 2 | H24: 1.5 | I24: =G24*H24 -> 3 | J24: Equipo con baja familiariadad en estos proyectos. | L24: F1 | M24: =COUNTIF(I24:I29,"<3") -> 2
B25: publicar borrador de licitación | C25: 10 | E25: E2 | F25: Experiencia en la aplicación | G25: 2 | H25: 0.5 | I25: =G25*H25 -> 1 | J25: El equipo no esta capacitado para trabajar con las tecnologias seleccionadas | L25: F2 | M25: =COUNTIF(I30:I31,">3") -> 0
B26: eliminar licitación | C26: 5 | E26: E3 | F26: Experiencia en orientación a objetos | G26: 5 | H26: 1 | I26: =G26*H26 -> 5 | J26: Se cuenta con experiencia | L26: TOTAL | M26: =SUM(M24:M25) -> 2
B27: modificar licitación | C27: 5 | E27: E4 | F27: Capacidad del analista líder | G27: 5 | H27: 0.5 | I27: =G27*H27 -> 2.5 | J27: Alta capacidad
B28: ver informes y reportes | C28: 10 | E28: E5 | F28: Motivación | G28: 5 | H28: 1 | I28: =G28*H28 -> 5 | J28: Equipo cuenta con la unión y motivacion para desarrollar el proyecto
B29: ver licitaciones vigentes | C29: 10 | E29: E6 | F29: Estabilidad de los requerimientos | G29: 4 | H29: 2 | I29: =G29*H29 -> 8 | J29: Requerimientos robusos, es decir, no es probable que cambien
B30: cerrar convocatoria de licitación | C30: 10 | E30: E7 | F30: Personal part-time | G30: 0 | H30: -1 | I30: =G30*H30 -> 0 | J30: No se cuenta con personal part-time
B31: terminar publicación de licitación | C31: 15 | E31: E8 | F31: Dificultad del lenguaje de programación | G31: 1 | H31: -1 | I31: =G31*H31 -> -1 | J31: El lenguaje es conocido por el equipo
B32: publicar acta de adjudicación | C32: 15 | F32: TOTAL | I32: =SUM(I24:I31) -> 23.5
B33: gestionar boletas de garantias | C33: 10
B34: Finalizar licitación | C34: 15 | F34: FA | G34: =1.4-(0.03*I32) -> 0.695
A35: 2-Gestión de cotizaciones | F35: FC | G35: =CHOOSE(M26,20,20,28,28,"NO HACER") -> 20
A36: Proveedor
B37: buscar cotizaciones | C37: 10 | F37: PCUA | G37: =G34*G19*C188 -> 341.75235
B38: ver cotizacion y sus bases | C38: 10 | F38: E | G38: =G37*G35 -> 6835.047
B39: realizar preguntas | C39: 15 | F39: E TOTAL | G39: =G38/0.4 -> 17087.617
B40: participar en cotización | C40: 15
...

Sheet Costos HH - Sueldos
A2: Conversiones
A3: Dólar | B3: =PARÁMETROS!B2 -> 900 | N3: 35
A4: Euro | B4: =PARÁMETROS!B3 -> 800
A5: UF | B5: =PARÁMETROS!B4 -> 36000
A6: HH Mes | B6: 160
A8: Costo implementación
B9: Dias según Gantt | C9: Horas (8 hrs x dia) | D9: Costo $ UF/HH | E9: Tarifa$ UF/HH | F9: Total Costo | G9: Total Tarifa | H9: Cant de personas | I9: Horas x Persona | J9: Sueldo costo CLP | K9: Sueldo tarifa CLP | L9: Sueldo Costo UF | M9: Sueldo Tarifa UF
A10: Director de Proyecto | B10: 328 | C10: 8 | D10: 2.3 | E10: 4 | F10: =C10*D10 -> 18.4 | G10: =C10*E10 -> 32 | H10: 1 | I10: =C10/H10 -> 8 | J10: =B10*C10*D10*$B$5 -> 217267200 | K10: =B10*C10*E10*$B$5 -> 377856000 | L10: =J10/$B$5 -> 6035.2 | M10: =K10/$B$5 -> 10496
A11: Analista de negocios Senior | B11: 40 | C11: 8 | D11: 0.6 | E11: 1.2 | F11: =C11*D11 -> 4.8 | G11: =C11*E11 -> 9.6 | H11: 2 | I11: =C11/H11 -> 4 | J11: =B11*C11*D11*$B$5 -> 6912000 | K11: =B11*C11*E11*$B$5 -> 13824000 | L11: =J11/$B$5 -> 192 | M11: =K11/$B$5 -> 384
A12: Analista de negocios junior | B12: 40 | C12: 8 | D12: 0.3 | E12: 1 | F12: =C12*D12 -> 2.4 | G12: =C12*E12 -> 8 | H12: 2 | I12: =C12/H12 -> 4 | J12: =B12*C12*D12*$B$5 -> 3456000 | K12: =B12*C12*E12*$B$5 -> 11520000 | L12: =J12/$B$5 -> 96 | M12: =K12/$B$5 -> 320
A13: Gestor de riesgos senior | B13: =191+70 -> 261 | C13: 8 | D13: 1 | E13: 1.5 | F13: =C13*D13 -> 8 | G13: =C13*E13 -> 12 | H13: 1 | I13: =C13/H13 -> 8 | J13: =B13*C13*D13*$B$5 -> 75168000 | K13: =B13*C13*E13*$B$5 -> 112752000 | L13: =J13/$B$5 -> 2088 | M13: =K13/$B$5 -> 3132
A14: Analista de sistemas senior | B14: 60 | C14: 8 | D14: 0.5 | E14: 1 | F14: =C14*D14 -> 4 | G14: =C14*E14 -> 8 | H14: 4 | I14: =C14/H14 -> 2 | J14: =B14*C14*D14*$B$5 -> 8640000 | K14: =B14*C14*E14*$B$5 -> 17280000 | L14: =J14/$B$5 -> 240 | M14: =K14/$B$5 -> 480
A15: Analista de sistemas junior | B15: 60 | C15: 8 | D15: 0.3 | E15: 0.8 | F15: =C15*D15 -> 2.4 | G15: =C15*E15 -> 6.4 | H15: 2 | I15: =C15/H15 -> 4 | J15: =B15*C15*D15*$B$5 -> 5184000 | K15: =B15*C15*E15*$B$5 -> 13824000 | L15: =J15/$B$5 -> 144 | M15: =K15/$B$5 -> 384
A16: Diseñador de UX senior | B16: 180 | C16: 8 | D16: 1 | E16: 1 | F16: =C16*D16 -> 8 | G16: =C16*E16 -> 8 | H16: 2 | I16: =C16/H16 -> 4 | J16: =B16*C16*D16*$B$5 -> 51840000 | K16: =B16*C16*E16*$B$5 -> 51840000 | L16: =J16/$B$5 -> 1440 | M16: =K16/$B$5 -> 1440
A17: Diseñador de UX junior | B17: 180 | C17: 8 | D17: 0.5 | E17: 0.8 | F17: =C17*D17 -> 4 | G17: =C17*E17 -> 6.4 | H17: 2 | I17: =C17/H17 -> 4 | J17: =B17*C17*D17*$B$5 -> 25920000 | K17: =B17*C17*E17*$B$5 -> 41472000 | L17: =J17/$B$5 -> 720 | M17: =K17/$B$5 -> 1152
A18: Arquitecto software Senior | B18: 60 | C18: 8 | D18: 1.3 | E18: 2.5 | F18: =C18*D18 -> 10.4 | G18: =C18*E18 -> 20 | H18: 1 | I18: =C18/H18 -> 8 | J18: =B18*C18*D18*$B$5 -> 22464000 | K18: =B18*C18*E18*$B$5 -> 43200000 | L18: =J18/$B$5 -> 624 | M18: =K18/$B$5 -> 1200
A19: Arquitecto de software Junior | B19: 60 | C19: 8 | D19: 0.5 | E19: 1.5 | F19: =C19*D19 -> 4 | G19: =C19*E19 -> 12 | H19: 1 | I19: =C19/H19 -> 8 | J19: =B19*C19*D19*$B$5 -> 8640000 | K19: =B19*C19*E19*$B$5 -> 25920000 | L19: =J19/$B$5 -> 240 | M19: =K19/$B$5 -> 720
A20: Desarrollador Front-end senior | B20: 40 | C20: 8 | D20: 0.7 | E20: 1 | F20: =C20*D20 -> 5.6 | G20: =C20*E20 -> 8 | H20: 2 | I20: =C20/H20 -> 4 | J20: =B20*C20*D20*$B$5 -> 8064000 | K20: =B20*C20*E20*$B$5 -> 11520000 | L20: =J20/$B$5 -> 224 | M20: =K20/$B$5 -> 320
A21: Desarrollador Front-end Junior | B21: 1000 | C21: 8 | D21: 0.5 | E21: 0.8 | F21: =C21*D21 -> 4 | G21: =C21*E21 -> 6.4 | H21: 2 | I21: =C21/H21 -> 4 | J21: =B21*C21*D21*$B$5 -> 144000000 | K21: =B21*C21*E21*$B$5 -> 230400000 | L21: =J21/$B$5 -> 4000 | M21: =K21/$B$5 -> 6400
A22: Desarrollador Back-end Senior | B22: 40 | C22: 8 | D22: 0.8 | E22: 1 | F22: =C22*D22 -> 6.4 | G22: =C22*E22 -> 8 | H22: 2 | I22: =C22/H22 -> 4 | J22: =B22*C22*D22*$B$5 -> 9216000 | K22: =B22*C22*E22*$B$5 -> 11520000 | L22: =J22/$B$5 -> 256 | M22: =K22/$B$5 -> 320
A23: Desarrollador Back-end junior | B23: 1000 | C23: 8 | D23: 0.5 | E23: 0.8 | F23: =C23*D23 -> 4 | G23: =C23*E23 -> 6.4 | H23: 2 | I23: =C23/H23 -> 4 | J23: =B23*C23*D23*$B$5 -> 144000000 | K23: =B23*C23*E23*$B$5 -> 230400000 | L23: =J23/$B$5 -> 4000 | M23: =K23/$B$5 -> 6400
A24: Desarrollador de software senior | B24: 60 | C24: 8 | D24: 0.5 | E24: 1 | F24: =C24*D24 -> 4 | G24: =C24*E24 -> 8 | H24: 1 | I24: =C24/H24 -> 8 | J24: =B24*C24*D24*$B$5 -> 8640000 | K24: =B24*C24*E24*$B$5 -> 17280000 | L24: =J24/$B$5 -> 240 | M24: =K24/$B$5 -> 480
A25: Desarrollador de software junior | B25: 1020 | C25: 8 | D25: 0.4 | E25: 0.8 | F25: =C25*D25 -> 3.2 | G25: =C25*E25 -> 6.4 | H25: 1 | I25: =C25/H25 -> 8 | J25: =B25*C25*D25*$B$5 -> 117504000 | K25: =B25*C25*E25*$B$5 -> 235008000 | L25: =J25/$B$5 -> 3264 | M25: =K25/$B$5 -> 6528
... A41: Administrador de Sistema Senior | B41: 150 | C41: 8 | D41: 0.8 | E41: 1 | F41: =C41*D41 -> 6.4 | G41: =C41*E41 -> 8 | H41: 1 | I41: =C41/H41 -> 8 | J41: =B41*C41*D41*$B$5 -> 34560000 | K41: =B41*C41*E41*$B$5 -> 43200000 | L41: =J41/$B$5 -> 960 | M41: =K41/$B$5 -> 1200
A42: Total | B42: =SUM(B9:B41) -> 8639 | H42: =SUM(H9:H41) -> 46 | J42: =SUM(J9:J41) -> 1696723200 | K42: =SUM(K9:K41) -> 3054960000 | L42: =SUM(L9:L41) -> 47131.2 | M42: =SUM(M9:M41) -> 84860
B43: =(B42*8) -> 69112
C51: Costo | E51: Tarifa
B52: Cantidad Personas | C52: UF Mensuales (160 Hrs) | D52: CLP Mensuales/persona | E52: UF Mensuales (160 Hrs) /Persona | F52: CLP Mensual/persona
A53: Director de Proyecto | B53: =H10 -> 1 | C53: =($B$6*D10) -> 368 | D53: =C53*$B$5 -> 13248000 | E53: =(B$6*E10) -> 640 | F53: =E53*B$5 -> 23040000
A54: Analista de negocios Senior | B54: =H11 -> 2 | C54: =($B$6*D11) -> 96 | D54: =C54*$B$5 -> 3456000 | E54: =(B$6*E11) -> 192 | F54: =E54*B$5 -> 6912000
A55: Analista de negocios junior | B55: =H12 -> 2 | C55: =($B$6*D12) -> 48 | D55: =C55*$B$5 -> 1728000 | E55: =(B$6*E12) -> 160 | F55: =E55*B$5 -> 5760000
A56: Gestor de riesgos senior | B56: =H13 -> 1 | C56: =($B$6*D13) -> 160 | D56: =C56*$B$5 -> 5760000 | E56: =(B$6*E13) -> 240 | F56: =E56*B$5 -> 8640000
A57: Analista de sistemas senior | B57: =H14 -> 4 | C57: =($B$6*D14) -> 80 | D57: =C57*$B$5 -> 2880000 | E57: =(B$6*E14) -> 160 | F57: =E57*B$5 -> 5760000
A58: Analista de sistemas junior | B58: =H15 -> 2 | C58: =($B$6*D15) -> 48 | D58: =C58*$B$5 -> 1728000 | E58: =(B$6*E15) -> 128 | F58: =E58*B$5 -> 4608000
A59: Diseñador de UX senior | B59: =H16 -> 2 | C59: =($B$6*D16) -> 160 | D59: =C59*$B$5 -> 5760000 | E59: =(B$6*E16) -> 160 | F59: =E59*B$5 -> 5760000
A60: Diseñador de UX junior | B60: =H17 -> 2 | C60: =($B$6*D17) -> 80 | D60: =C60*$B$5 -> 2880000 | E60: =(B$6*E17) -> 128 | F60: =E60*B$5 -> 4608000
A61: Arquitecto software Senior | B61: =H18 -> 1 | C61: =($B$6*D18) -> 208 | D61: =C61*$B$5 -> 7488000 | E61: =(B$6*E18) -> 400 | F61: =E61*B$5 -> 14400000
A62: Arquitecto de software Junior | B62: =H19 -> 1 | C62: =($B$6*D19) -> 80 | D62: =C62*$B$5 -> 2880000 | E62: =(B$6*E19) -> 240 | F62: =E62*B$5 -> 8640000
A63: Desarrollador Front-end senior | B63: =H20 -> 2 | C63: =($B$6*D20) -> 112 | D63: =C63*$B$5 -> 4032000 | E63: =(B$6*E20) -> 160 | F63: =E63*B$5 -> 5760000
A64: Desarrollador Front-end Junior | B64: =H21 -> 2 | C64: =($B$6*D21) -> 80 | D64: =C64*$B$5 -> 2880000 | E64: =(B$6*E21) -> 128 | F64: =E64*B$5 -> 4608000
...

Sheet Costos HH por MES
A3: Conversiones | F3: Costo | H3: Tarifa
A4: Dólar | B4: =PARÁMETROS!B2 -> 900 | E4: Cantidad Personas | F4: UF Mensuales (160 Hrs) /Persona | G4: CLP Mensuales/persona | H4: UF Mensuales (160 Hrs) /Persona | I4: CLP Mensual/persona
A5: Euro | B5: =PARÁMETROS!B3 -> 800 | D5: =+'Costos HH - Sueldos'!A53 -> Director de Proyecto | E5: =+'Costos HH - Sueldos'!H10 -> 1 | F5: =+'Costos HH - Sueldos'!C53 -> 368 | G5: =+'Costos HH - Sueldos'!D53 -> 13248000 | H5: =+'Costos HH - Sueldos'!E53 -> 640 | I5: =+'Costos HH - Sueldos'!F53 -> 23040000
A6: UF | B6: =PARÁMETROS!B4 -> 36000 | D6: =+'Costos HH - Sueldos'!A54 -> Analista de negocios Senior | E6: =+'Costos HH - Sueldos'!H11 -> 2 | F6: =+'Costos HH - Sueldos'!C54 -> 96 | G6: =+'Costos HH - Sueldos'!D54 -> 3456000 | H6: =+'Costos HH - Sueldos'!E54 -> 192 | I6: =+'Costos HH - Sueldos'!F54 -> 6912000
A7: HH Mes | B7: 160 | D7: =+'Costos HH - Sueldos'!A55 -> Analista de negocios junior | E7: =+'Costos HH - Sueldos'!H12 -> 2 | F7: =+'Costos HH - Sueldos'!C55 -> 48 | G7: =+'Costos HH - Sueldos'!D55 -> 1728000 | H7: =+'Costos HH - Sueldos'!E55 -> 160 | I7: =+'Costos HH - Sueldos'!F55 -> 5760000
D8: =+'Costos HH - Sueldos'!A56 -> Gestor de riesgos senior | E8: =+'Costos HH - Sueldos'!H13 -> 1 | F8: =+'Costos HH - Sueldos'!C56 -> 160 | G8: =+'Costos HH - Sueldos'!D56 -> 5760000 | H8: =+'Costos HH - Sueldos'!E56 -> 240 | I8: =+'Costos HH - Sueldos'!F56 -> 8640000
B9: Dias según Gantt | D9: =+'Costos HH - Sueldos'!A57 -> Analista de sistemas senior | E9: =+'Costos HH - Sueldos'!H14 -> 4 | F9: =+'Costos HH - Sueldos'!C57 -> 80 | G9: =+'Costos HH - Sueldos'!D57 -> 2880000 | H9: =+'Costos HH - Sueldos'!E57 -> 160 | I9: =+'Costos HH - Sueldos'!F57 -> 5760000
A10: =+'Costos HH - Sueldos'!A10 -> Director de Proyecto | B10: =+'Costos HH - Sueldos'!B10 -> 328 | D10: =+'Costos HH - Sueldos'!A58 -> Analista de sistemas junior | E10: =+'Costos HH - Sueldos'!H15 -> 2 | F10: =+'Costos HH - Sueldos'!C58 -> 48 | G10: =+'Costos HH - Sueldos'!D58 -> 1728000 | H10: =+'Costos HH - Sueldos'!E58 -> 128 | I10: =+'Costos HH - Sueldos'!F58 -> 4608000
A11: =+'Costos HH - Sueldos'!A11 -> Analista de negocios Senior | B11: =+'Costos HH - Sueldos'!B11 -> 40 | D11: =+'Costos HH - Sueldos'!A59 -> Diseñador de UX senior | E11: =+'Costos HH - Sueldos'!H16 -> 2 | F11: =+'Costos HH - Sueldos'!C59 -> 160 | G11: =+'Costos HH - Sueldos'!D59 -> 5760000 | H11: =+'Costos HH - Sueldos'!E59 -> 160 | I11: =+'Costos HH - Sueldos'!F59 -> 5760000
A12: =+'Costos HH - Sueldos'!A12 -> Analista de negocios junior | B12: =+'Costos HH - Sueldos'!B12 -> 40 | D12: =+'Costos HH - Sueldos'!A60 -> Diseñador de UX junior | E12: =+'Costos HH - Sueldos'!H17 -> 2 | F12: =+'Costos HH - Sueldos'!C60 -> 80 | G12: =+'Costos HH - Sueldos'!D60 -> 2880000 | H12: =+'Costos HH - Sueldos'!E60 -> 128 | I12: =+'Costos HH - Sueldos'!F60 -> 4608000
A13: =+'Costos HH - Sueldos'!A13 -> Gestor de riesgos senior | B13: =+'Costos HH - Sueldos'!B13 -> 261 | D13: =+'Costos HH - Sueldos'!A61 -> Arquitecto software Senior | E13: =+'Costos HH - Sueldos'!H18 -> 1 | F13: =+'Costos HH - Sueldos'!C61 -> 208 | G13: =+'Costos HH - Sueldos'!D61 -> 7488000 | H13: =+'Costos HH - Sueldos'!E61 -> 400 | I13: =+'Costos HH - Sueldos'!F61 -> 14400000
A14: =+'Costos HH - Sueldos'!A14 -> Analista de sistemas senior | B14: =+'Costos HH - Sueldos'!B14 -> 60 | D14: =+'Costos HH - Sueldos'!A62 -> Arquitecto de software Junior | E14: =+'Costos HH - Sueldos'!H19 -> 1 | F14: =+'Costos HH - Sueldos'!C62 -> 80 | G14: =+'Costos HH - Sueldos'!D62 -> 2880000 | H14: =+'Costos HH - Sueldos'!E62 -> 240 | I14: =+'Costos HH - Sueldos'!F62 -> 8640000
A15: =+'Costos HH - Sueldos'!A16 -> Diseñador de UX senior | B15: =+'Costos HH - Sueldos'!B16 -> 180 | D15: =+'Costos HH - Sueldos'!A63 -> Desarrollador Front-end senior | E15: =+'Costos HH - Sueldos'!H20 -> 2 | F15: =+'Costos HH - Sueldos'!C63 -> 112 | G15: =+'Costos HH - Sueldos'!D63 -> 4032000 | H15: =+'Costos HH - Sueldos'!E63 -> 160 | I15: =+'Costos HH - Sueldos'!F63 -> 5760000
A16: =+'Costos HH - Sueldos'!A17 -> Diseñador de UX junior | B16: =+'Costos HH - Sueldos'!B17 -> 180 | D16: =+'Costos HH - Sueldos'!A64 -> Desarrollador Front-end Junior | E16: =+'Costos HH - Sueldos'!H21 -> 2 | F16: =+'Costos HH - Sueldos'!C64 -> 80 | G16: =+'Costos HH - Sueldos'!D64 -> 2880000 | H16: =+'Costos HH - Sueldos'!E64 -> 128 | I16: =+'Costos HH - Sueldos'!F64 -> 4608000
A17: =+'Costos HH - Sueldos'!A18 -> Arquitecto software Senior | B17: =+'Costos HH - Sueldos'!B18 -> 60 | D17: =+'Costos HH - Sueldos'!A65 -> Desarrollador Back-end Senior | E17: =+'Costos HH - Sueldos'!H22 -> 2 | F17: =+'Costos HH - Sueldos'!C65 -> 128 | G17: =+'Costos HH - Sueldos'!D65 -> 4608000 | H17: =+'Costos HH - Sueldos'!E65 -> 160 | I17: =+'Costos HH - Sueldos'!F65 -> 5760000
A18: =+'Costos HH - Sueldos'!A19 -> Arquitecto de software Junior | B18: =+'Costos HH - Sueldos'!B19 -> 60 | D18: =+'Costos HH - Sueldos'!A66 -> Desarrollador Back-end junior | E18: =+'Costos HH - Sueldos'!H23 -> 2 | F18: =+'Costos HH - Sueldos'!C66 -> 80 | G18: =+'Costos HH - Sueldos'!D66 -> 2880000 | H18: =+'Costos HH - Sueldos'!E66 -> 128 | I18: =+'Costos HH - Sueldos'!F66 -> 4608000
D19: =+'Costos HH - Sueldos'!A67 -> Desarrollador de software senior | E19: =+'Costos HH - Sueldos'!H24 -> 1 | F19: =+'Costos HH - Sueldos'!C67 -> 80 | G19: =+'Costos HH - Sueldos'!D67 -> 2880000 | H19: =+'Costos HH - Sueldos'!E67 -> 160 | I19: =+'Costos HH - Sueldos'!F67 -> 5760000
A20: =+'Costos HH - Sueldos'!A20 -> Desarrollador Front-end senior | B20: =+'Costos HH - Sueldos'!B20 -> 40 | D20: =+'Costos HH - Sueldos'!A68 -> Desarrollador de software junior | E20: =+'Costos HH - Sueldos'!H25 -> 1 | F20: =+'Costos HH - Sueldos'!C68 -> 64 | G20: =+'Costos HH - Sueldos'!D68 -> 2304000 | H20: =+'Costos HH - Sueldos'!E68 -> 128 | I20: =+'Costos HH - Sueldos'!F68 -> 4608000
A21: =+'Costos HH - Sueldos'!A21 -> Desarrollador Front-end Junior | B21: =+'Costos HH - Sueldos'!B21 -> 1000 | D21: =+'Costos HH - Sueldos'!A69 -> Diseñador de base de datos senior | E21: =+'Costos HH - Sueldos'!H26 -> 1 | F21: =+'Costos HH - Sueldos'!C69 -> 144 | G21: =+'Costos HH - Sueldos'!D69 -> 5184000 | H21: =+'Costos HH - Sueldos'!E69 -> 160 | I21: =+'Costos HH - Sueldos'!F69 -> 5760000
A22: =+'Costos HH - Sueldos'!A22 -> Desarrollador Back-end Senior | B22: =+'Costos HH - Sueldos'!B22 -> 40 | D22: =+'Costos HH - Sueldos'!A70 -> Diseñador de base de datos junior | E22: =+'Costos HH - Sueldos'!H27 -> 1 | F22: =+'Costos HH - Sueldos'!C70 -> 48 | G22: =+'Costos HH - Sueldos'!D70 -> 1728000 | H22: =+'Costos HH - Sueldos'!E70 -> 128 | I22: =+'Costos HH - Sueldos'!F70 -> 4608000
A23: =+'Costos HH - Sueldos'!A23 -> Desarrollador Back-end junior | B23: =+'Costos HH - Sueldos'!B23 -> 1000 | D23: =+'Costos HH - Sueldos'!A71 -> Ingeniero DevOps senior | E23: =+'Costos HH - Sueldos'!H28 -> 1 | F23: =+'Costos HH - Sueldos'!C71 -> 160 | G23: =+'Costos HH - Sueldos'!D71 -> 5760000 | H23: =+'Costos HH - Sueldos'!E71 -> 240 | I23: =+'Costos HH - Sueldos'!F71 -> 8640000
A24: =+'Costos HH - Sueldos'!A24 -> Desarrollador de software senior | B24: =+'Costos HH - Sueldos'!B24 -> 60 | D24: =+'Costos HH - Sueldos'!A72 -> Ingeniero de sistemas senior | E24: =+'Costos HH - Sueldos'!H29 -> 1 | F24: =+'Costos HH - Sueldos'!C72 -> 128 | G24: =+'Costos HH - Sueldos'!D72 -> 4608000 | H24: =+'Costos HH - Sueldos'!E72 -> 240 | I24: =+'Costos HH - Sueldos'!F72 -> 8640000
A25: =+'Costos HH - Sueldos'!A25 -> Desarrollador de software junior | B25: =+'Costos HH - Sueldos'!B25 -> 1020 | D25: =+'Costos HH - Sueldos'!A73 -> Ingeniero de sistemas junior | E25: =+'Costos HH - Sueldos'!H30 -> 1 | F25: =+'Costos HH - Sueldos'!C73 -> 112 | G25: =+'Costos HH - Sueldos'!D73 -> 4032000 | H25: =+'Costos HH - Sueldos'!E73 -> 160 | I25: =+'Costos HH - Sueldos'!F73 -> 5760000
A26: =+'Costos HH - Sueldos'!A26 -> Diseñador de base de datos senior | B26: =+'Costos HH - Sueldos'!B26 -> 60 | D26: =+'Costos HH - Sueldos'!A74 -> QA senior | E26: =+'Costos HH - Sueldos'!H31 -> 1 | F26: =+'Costos HH - Sueldos'!C74 -> 96 | G26: =+'Costos HH - Sueldos'!D74 -> 3456000 | H26: =+'Costos HH - Sueldos'!E74 -> 160 | I26: =+'Costos HH - Sueldos'!F74 -> 5760000
A27: =+'Costos HH - Sueldos'!A27 -> Diseñador de base de datos junior | B27: =+'Costos HH - Sueldos'!B27 -> 60 | D27: =+'Costos HH - Sueldos'!A75 -> QA junior | E27: =+'Costos HH - Sueldos'!H32 -> 1 | F27: =+'Costos HH - Sueldos'!C75 -> 64 | G27: =+'Costos HH - Sueldos'!D75 -> 2304000 | H27: =+'Costos HH - Sueldos'!E75 -> 128 | I27: =+'Costos HH - Sueldos'!F75 -> 4608000
A28: =+'Costos HH - Sueldos'!A28 -> Ingeniero DevOps senior | B28: =+'Costos HH - Sueldos'!B28 -> 60 | D28: =+'Costos HH - Sueldos'!A76 -> Ingeniero soporte senior | E28: =+'Costos HH - Sueldos'!H33 -> 1 | F28: =+'Costos HH - Sueldos'!C76 -> 112 | G28: =+'Costos HH - Sueldos'!D76 -> 4032000 | H28: =+'Costos HH - Sueldos'!E76 -> 240 | I28: =+'Costos HH - Sueldos'!F76 -> 8640000
A29: =+'Costos HH - Sueldos'!A29 -> Ingeniero de sistemas senior | B29: =+'Costos HH - Sueldos'!B29 -> 100 | D29: =+'Costos HH - Sueldos'!A77 -> Ingeniero soporte junior | E29: =+'Costos HH - Sueldos'!H34 -> 1 | F29: =+'Costos HH - Sueldos'!C77 -> 64 | G29: =+'Costos HH - Sueldos'!D77 -> 2304000 | H29: =+'Costos HH - Sueldos'!E77 -> 160 | I29: =+'Costos HH - Sueldos'!F77 -> 5760000
A30: =+'Costos HH - Sueldos'!A31 -> QA senior | B30: =+'Costos HH - Sueldos'!B31 -> 120 | D30: =+'Costos HH - Sueldos'!A78 -> Especialista atencion al cliente | E30: =+'Costos HH - Sueldos'!H35 -> 1 | F30: =+'Costos HH - Sueldos'!C78 -> 80 | G30: =+'Costos HH - Sueldos'!D78 -> 2880000 | H30: =+'Costos HH - Sueldos'!E78 -> 128 | I30: =+'Costos HH - Sueldos'!F78 -> 4608000
A31: =+'Costos HH - Sueldos'!A32 -> QA junior | B31: =+'Costos HH - Sueldos'!B32 -> 120 | D31: =+'Costos HH - Sueldos'!A79 -> Arquitecto de Redes Senior | E31: =+'Costos HH - Sueldos'!H36 -> 2 | F31: =+'Costos HH - Sueldos'!C79 -> 128 | G31: =+'Costos HH - Sueldos'!D79 -> 4608000 | H31: =+'Costos HH - Sueldos'!E79 -> 192 | I31: =+'Costos HH - Sueldos'!F79 -> 6912000
A32: =+'Costos HH - Sueldos'!A33 -> Ingeniero soporte senior | B32: =+'Costos HH - Sueldos'!B33 -> 960 | D32: =+'Costos HH - Sueldos'!A80 -> Técnico de Hardware Senior | E32: =+'Costos HH - Sueldos'!H37 -> 2 | F32: =+'Costos HH - Sueldos'!C80 -> 144 | G32: =+'Costos HH - Sueldos'!D80 -> 5184000 | H32: =+'Costos HH - Sueldos'!E80 -> 160 | I32: =+'Costos HH - Sueldos'!F80 -> 5760000
A33: =+'Costos HH - Sueldos'!A34 -> Ingeniero soporte junior | B33: =+'Costos HH - Sueldos'!B34 -> 960 | D33: =+'Costos HH - Sueldos'!A81 -> Técnico de Hardware Junior | E33: =+'Costos HH - Sueldos'!H38 -> 1 | F33: =+'Costos HH - Sueldos'!C81 -> 48 | G33: =+'Costos HH - Sueldos'!D81 -> 1728000 | H33: =+'Costos HH - Sueldos'!E81 -> 288 | I33: =+'Costos HH - Sueldos'!F81 -> 10368000
A34: =+'Costos HH - Sueldos'!A35 -> Especialista atencion al cliente | B34: =+'Costos HH - Sueldos'!B35 -> 130 | D34: =+'Costos HH - Sueldos'!A82 -> Ingeniero de Redes Senior | E34: =+'Costos HH - Sueldos'!H39 -> 1 | F34: =+'Costos HH - Sueldos'!C82 -> 192 | G34: =+'Costos HH - Sueldos'!D82 -> 6912000 | H34: =+'Costos HH - Sueldos'!E82 -> 320 | I34: =+'Costos HH - Sueldos'!F82 -> 11520000
A35: =+'Costos HH - Sueldos'!A36 -> Arquitecto en Redes Senior | B35: =+'Costos HH - Sueldos'!B36 -> 200 | D35: =+'Costos HH - Sueldos'!A83 -> Ingeniero de Seguridad de TI Senior | E35: =+'Costos HH - Sueldos'!H40 -> 1 | F35: =+'Costos HH - Sueldos'!C83 -> 192 | G35: =+'Costos HH - Sueldos'!D83 -> 6912000 | H35: =+'Costos HH - Sueldos'!E83 -> 320 | I35: =+'Costos HH - Sueldos'!F83 -> 11520000
A36: =+'Costos HH - Sueldos'!A37 -> Tecnico de Hardware Senior | B36: =+'Costos HH - Sueldos'!B37 -> 300 | D36: =+'Costos HH - Sueldos'!A84 -> Administrador de Sistema Senior | E36: =+'Costos HH - Sueldos'!H41 -> 1 | F36: =+'Costos HH - Sueldos'!C84 -> 128 | G36: =+'Costos HH - Sueldos'!D84 -> 4608000 | H36: =+'Costos HH - Sueldos'!E84 -> 160 | I36: =+'Costos HH - Sueldos'!F84 -> 5760000
A37: =+'Costos HH - Sueldos'!A38 -> Tecnico de Hardware Junior | B37: =+'Costos HH - Sueldos'!B38 -> 250 | D37: =+'Costos HH - Sueldos'!A85 -> Totales | E37: =SUM(E5:E36) -> 46 | F37: =+'Costos HH - Sueldos'!C85 -> 3712 | G37: =+'Costos HH - Sueldos'!D85 -> 133632000 | H37: =+'Costos HH - Sueldos'!E85 -> 6496 | I37: =+'Costos HH - Sueldos'!F85 -> 233856000
A38: =+'Costos HH - Sueldos'!A39 -> Ingeniero de Redes Senior | B38: =+'Costos HH - Sueldos'!B39 -> 320
A39: =+'Costos HH - Sueldos'!A40 -> Ingeniero de Seguridad de TI Senior | B39: =+'Costos HH - Sueldos'!B40 -> 320
A40: =+'Costos HH - Sueldos'!A41 -> Administrador de Sistema Senior | B40: =+'Costos HH - Sueldos'!B41 -> 150
A41: =+'Costos HH - Sueldos'!A42 -> Total | B41: =+'Costos HH - Sueldos'!B42 -> 8639

Sheet COSTOS DE OPERACION
F1: Costos de implementacion | Z1: Costos de soporte
B2: Sueldo(UF) | C2: Mes 1 | D2: Mes 2 | E2: Mes 3 | F2: Mes 4 | G2: Mes 5 | H2: Mes 6 | I2: Mes 7 | J2: Mes 8 | K2: Mes 9 | L2: Mes 10 | M2: Mes 11 | N2: Mes 12 | O2: Mes 13 | P2: Mes 14 | Q2: Mes 15 | R2: Mes 16 | S2: Mes 17 | T2: Mes 18 | U2: Mes 19 | V2: Mes 20 | W2: Mes 21 | X2: Mes 22 | Y2: Mes 23 | Z2: Mes 24 | AA2: Mes 25 | AB2: Mes 26 | AC2: Mes 27 | AD2: Mes 28 | AE2: Mes 29 | AF2: Mes 30 | AG2: Mes 31 | AH2: Mes 32 | AI2: Mes 33 | AJ2: Mes 34 | AK2: Mes 35 | AL2: Mes 36 | AM2: Mes 37 | AN2: Mes 38 | AO2: Mes 39 | AP2: Mes 40 | AQ2: Mes 41 | AR2: Mes 42 | AS2: Mes 43 | AT2: Mes 44 | AU2: Mes 45 | AV2: Mes 46 | AW2: Mes 47 | AX2: Mes 48 | AY2: Mes 49 | AZ2: Mes 50 | BA2: Mes 51 | BB2: Mes 52 | BC2: Mes 53 | BD2: Mes 54 | BE2: Mes 55 | BF2: Mes 56 | BG2: Mes 57 | BH2: Mes 58 | BI2: Mes 59 | BJ2: Mes 60
A3: Director de Proyecto | B3: =+'Costos HH por MES'!$F$5 -> 368 | C3: =$B$3 -> 368 | D3: =$B$3 -> 368 | E3: =$B$3 -> 368 | F3: =$B$3 -> 368 | G3: =$B$3 -> 368 | H3: =$B$3 -> 368 | I3: =$B$3 -> 368 | J3: =$B$3 -> 368 | ... N3: =$B$3 -> 368 | O3: =$B$3/20 -> 18.4 | P3: =$B$3/20 -> 18.4 | Q3: =$B$3/20 -> 18.4 | R3: =$B$3/20 -> 18.4 | S3: =$B$3/20 -> 18.4 | T3: =$B$3/20 -> 18.4 | U3: =$B$3/20 -> 18.4 | V3: =$B$3/20 -> 18.4 | ... BJ3: =$B$3/20 -> 18.4
A4: Analista de Negocios Senior A | B4: =+'Costos HH por MES'!F6 -> 96 | C4: =B$4 -> 96 | D4: =$B$4 -> 96
A5: Analista de Negocios Senior B | B5: =B4 -> 96 | C5: =($B$5) -> 96 | D5: =($C$5) -> 96 | F5: =(E5) -> 0 | G5: =(F5) -> 0 | H5: =(G5) -> 0 | I5: =(H5) -> 0 | J5: =(I5) -> 0 | K5: =(J5) -> 0 | L5: =(K5) -> 0 | M5: =(L5) -> 0 | N5: =(M5) -> 0
A6: Analista de Negocios Junior A | B6: =+'Costos HH por MES'!F7 -> 48 | C6: =($B$6) -> 48 | D6: =($C$6) -> 48
A7: Analista de Negocios Junior B | B7: =B6 -> 48 | C7: =($B$7) -> 48 | D7: =(C7) -> 48
A8: Gestor de Riesgos Senior | B8: =+'Costos HH por MES'!F8 -> 160 | C8: =($B$8) -> 160 | D8: =($B$8) -> 160 | E8: =($B$8) -> 160 | F8: =($B$8) -> 160 | G8: =($B$8) -> 160 | H8: =($B$8) -> 160 | I8: =($B$8) -> 160 | J8: =($B$8) -> 160 | ... N8: =($B$8) -> 160 | O8: =$B$8 -> 160 | P8: =$B$8 -> 160 | Q8: =$B$8 -> 160 | R8: =$B$8/2 -> 80
A9: Analista de Sistemas Senior A | B9: =+'Costos HH por MES'!F9 -> 80 | C9: =$B$9 -> 80 | D9: =$B$9 -> 80 | E9: =$B$9 -> 80
A10: Analista de Sistemas Senior B | B10: =$B$9 -> 80 | C10: =$B$10 -> 80 | D10: =$B$10 -> 80 | E10: =$B$10 -> 80
A11: Analista de Sistemas Senior C | B11: =B10 -> 80 | C11: =($B$11) -> 80 | D11: =($B$11) -> 80 | E11: =($B$11) -> 80
A12: Analista de Sistemas Senior D | B12: =B11 -> 80 | C12: =($B$12) -> 80 | D12: =($B$12) -> 80 | E12: =($B$12) -> 80
A13: Analista de Sistemas Junior A | B13: =+'Costos HH por MES'!F10 -> 48 | C13: =($B$13) -> 48 | D13: =($B$13) -> 48 | E13: =($B$13) -> 48
A14: Analista de Sistemas Junior B | B14: =B13 -> 48 | C14: =($B$14) -> 48 | D14: =($B$14) -> 48 | E14: =($B$14) -> 48
A15: Diseñador de UX senior A | B15: =+'Costos HH por MES'!F11 -> 160 | C15: =($B$15) -> 160 | D15: =($B$15) -> 160 | E15: =($B$15) -> 160 | G15: =($B$15) -> 160 | H15: =($B$15) -> 160 | J15: =($B$15) -> 160 | K15: =($B$15) -> 160 | L15: =($B$15) -> 160 | M15: =($B$15) -> 160
A16: Diseñador de UX senior B | B16: =B15 -> 160 | C16: =($B$16) -> 160 | D16: =($B$16) -> 160 | E16: =($B$16) -> 160 | G16: =($B$16) -> 160 | H16: =($B$16) -> 160 | J16: =($B$16) -> 160 | K16: =($B$16) -> 160 | L16: =($B$16) -> 160 | M16: =($B$16) -> 160
A17: Diseñador de UX junior A | B17: =+'Costos HH por MES'!F12 -> 80 | C17: =$B$17 -> 80 | D17: =$B$17 -> 80 | E17: =$B$17 -> 80 | G17: =$B$17 -> 80 | H17: =$B$17 -> 80 | J17: =$B$17 -> 80 | K17: =$B$17 -> 80 | L17: =$B$17 -> 80 | M17: =$B$17 -> 80
A18: Diseñador de UX junior B | B18: =B17 -> 80 | C18: =$B$18 -> 80 | D18: =$B$18 -> 80 | E18: =$B$18 -> 80 | G18: =$B$18 -> 80 | H18: =$B$18 -> 80 | J18: =$B$18 -> 80 | K18: =$B$18 -> 80 | L18: =$B$18 -> 80 | M18: =$B$18 -> 80
A19: Arquitecto de Software Senior | B19: =+'Costos HH por MES'!F13 -> 208 | C19: =$B$19 -> 208 | D19: =$B$19 -> 208 | E19: =$B$19 -> 208
A20: Arquitecto de Software Junior | B20: =+'Costos HH por MES'!F14 -> 80 | C20: =$B$20 -> 80 | D20: =$B$20 -> 80 | E20: =$B$20 -> 80
A21: Desarrollador Front-end senior A | B21: =+'Costos HH por MES'!F15 -> 112 | F21: =(B21/20)*6 -> 33.6 | G21: =B21 -> 112 | H21: =B21 -> 112 | I21: 112
A22: Desarrollador Front-end senior B | B22: =B21 -> 112 | F22: =(B22/20)*6 -> 33.6 | G22: =B22 -> 112 | H22: =B22 -> 112 | I22: 112
A23: Desarrollador Front-end Junior A | B23: =+'Costos HH por MES'!F16 -> 80 | F23: =(B23/20)*6 -> 24 | G23: =B23 -> 80 | H23: =B23 -> 80 | I23: =B23 -> 80 | N23: 64 | O23: =$B$23 -> 80 | P23: =$B$23 -> 80 | Q23: =$B$23 -> 80 | R23: =$B$23 -> 80 | S23: =$B$23 -> 80 | T23: =$B$23 -> 80 | U23: =$B$23 -> 80 | V23: =$B$23 -> 80 | ... BJ23: =$B$23 -> 80
A24: Desarrollador Front-end Junior B | B24: =B23 -> 80 | F24: =(B24/20)*6 -> 24 | G24: =B24 -> 80 | H24: =B24 -> 80 | I24: =B24 -> 80
A25: Desarrollador Back-end Senior A | B25: =+'Costos HH por MES'!F17 -> 128 | F25: =(B25/20)*6 -> 38.4 | G25: =B25 -> 128 | H25: =B25 -> 128 | I25: =B25 -> 128
A26: Desarrollador Back-end Senior B | B26: =B25 -> 128 | F26: =(B26/20)*6 -> 38.4 | G26: =B26 -> 128 | H26: =B26 -> 128 | I26: =B26 -> 128
A27: Desarrollador Back-end junior A | B27: =+'Costos HH por MES'!F18 -> 80 | F27: =(B27/20)*6 -> 24 | G27: =B27 -> 80 | H27: =B27 -> 80 | I27: =B27 -> 80 | N27: 64 | O27: =$B$27 -> 80 | P27: =$B$27 -> 80 | Q27: =$B$27 -> 80 | R27: =$B$27 -> 80 | S27: =$B$27 -> 80 | T27: =$B$27 -> 80 | U27: =$B$27 -> 80 | V27: =$B$27 -> 80 | ... BJ27: =$B$27 -> 80
A28: Desarrollador Back-end junior B | B28: =B27 -> 80 | F28: =(B28/20)*6 -> 24 | G28: =B28 -> 80 | H28: =B28 -> 80 | I28: =B28 -> 80
A29: Desarrollador de software Senior | B29: =+'Costos HH por MES'!F18 -> 80 | F29: =(B29/20)*6 -> 24 | G29: =B29 -> 80 | H29: =B29 -> 80 | I29: =B29 -> 80
A30: Desarrollador de software junior | B30: =+'Costos HH por MES'!F20 -> 64 | F30: =(B30/20)*6 -> 19.2 | G30: =B30 -> 64 | H30: =B30 -> 64 | I30: =$B$30 -> 64 | M30: =E30 -> 0 | N30: 128 | O30: =$B$30 -> 64 | P30: =$B$30 -> 64 | Q30: =$B$30 -> 64 | R30: =$B$30 -> 64 | S30: =$B$30 -> 64 | T30: =$B$30 -> 64 | U30: =$B$30 -> 64 | V30: =$B$30 -> 64 | ... BJ30: =$B$30 -> 64
A31: Diseñador de base de datos senior | B31: =+'Costos HH por MES'!F21 -> 144 | C31: =$B$31 -> 144 | D31: =$B$31 -> 144 | E31: =$B$31 -> 144
A32: Diseñador de base de datos Junior | B32: =+'Costos HH por MES'!F22 -> 48 | C32: =$B$32 -> 48 | D32: =$B$32 -> 48 | E32: =$B$32 -> 48
A33: Ingeniero DevOps senior | B33: =+'Costos HH por MES'!F23 -> 160 | F33: =($B$33/20)*6 -> 48 | G33: =$B$33 -> 160 | H33: =$B$33 -> 160 | I33: =$B$33 -> 160 | N33: =$B$33 -> 160
A34: Ingeniero de sistemas senior | B34: =+'Costos HH por MES'!F24 -> 128 | E34: =$B$34 -> 128 | F34: =$B$34 -> 128 | G34: =$B$34 -> 128 | H34: =$B$34 -> 128 | I34: =$B$34 -> 128 | N34: =$B$34 -> 128
A35: Ingeniero de sistemas junior | B35: =+'Costos HH por MES'!F25 -> 112 | E35: =$B$35 -> 112 | F35: =$B$35 -> 112 | G35: =$B$35 -> 112 | H35: =$B$35 -> 112 | I35: =$B$35 -> 112 | N35: =$B$35 -> 112
A36: QA senior | B36: =+'Costos HH por MES'!F26 -> 96 | F36: =(B36/20)*6 -> 28.8 | G36: =B36 -> 96 | H36: =B36 -> 96 | I36: =B36 -> 96 | N36: =G36 -> 96
A37: QA junior | B37: =+'Costos HH por MES'!F27 -> 64 | F37: =(B37/20)*6 -> 19.2 | G37: =B37 -> 64 | H37: =B37 -> 64 | I37: =B37 -> 64 | N37: =G37 -> 64
A38: Ingeniero soporte senior | B38: =+'Costos HH por MES'!F28 -> 112 | O38: =B38 -> 112 | P38: =$B$38 -> 112 | Q38: =$B$38 -> 112 | R38: =$B$38 -> 112 | S38: =$B$38 -> 112 | T38: =$B$38 -> 112 | U38: =$B$38 -> 112 | V38: =$B$38 -> 112 | W38: =$B$38 -> 112 | ... BJ38: =$B$38 -> 112
A39: Ingeniero soporte junior | B39: =+'Costos HH por MES'!F29 -> 64 | O39: =B39 -> 64 | P39: =$B$39 -> 64 | Q39: =$B$39 -> 64 | R39: =$B$39 -> 64 | S39: =$B$39 -> 64 | T39: =$B$39 -> 64 | U39: =$B$39 -> 64 | V39: =$B$39 -> 64 | W39: =$B$39 -> 64 | ... BJ39: =$B$39 -> 64
A40: Especialista atencion al cliente | B40: =+'Costos HH por MES'!F30 -> 80 | O40: =$B$40 -> 80 | P40: =$B$40 -> 80 | Q40: =$B$40 -> 80 | R40: =$B$40 -> 80 | S40: =$B$40 -> 80 | T40: =$B$40 -> 80 | U40: =$B$40 -> 80 | V40: =$B$40 -> 80 | ... BJ40: =$B$40 -> 80
...

Sheet TARIFAS DE OPERACION
F1: Tarifa de implementacion | Z1: Tarifa de soporte
B2: Tarifas(UF) | C2: Mes 1 | D2: Mes 2 | E2: Mes 3 | F2: Mes 4 | G2: Mes 5 | H2: Mes 6 | I2: Mes 7 | J2: Mes 8 | K2: Mes 9 | L2: Mes 10 | M2: Mes 11 | N2: Mes 12 | O2: Mes 13 | P2: Mes 14 | Q2: Mes 15 | R2: Mes 16 | S2: Mes 17 | T2: Mes 18 | U2: Mes 19 | V2: Mes 20 | W2: Mes 21 | X2: Mes 22 | Y2: Mes 23 | Z2: Mes 24 | AA2: Mes 25 | AB2: Mes 26 | AC2: Mes 27 | AD2: Mes 28 | AE2: Mes 29 | AF2: Mes 30 | AG2: Mes 31 | AH2: Mes 32 | AI2: Mes 33 | AJ2: Mes 34 | AK2: Mes 35 | AL2: Mes 36 | AM2: Mes 37 | AN2: Mes 38 | AO2: Mes 39 | AP2: Mes 40 | AQ2: Mes 41 | AR2: Mes 42 | AS2: Mes 43 | AT2: Mes 44 | AU2: Mes 45 | AV2: Mes 46 | AW2: Mes 47 | AX2: Mes 48 | AY2: Mes 49 | AZ2: Mes 50 | BA2: Mes 51 | BB2: Mes 52 | BC2: Mes 53 | BD2: Mes 54 | BE2: Mes 55 | BF2: Mes 56 | BG2: Mes 57 | BH2: Mes 58 | BI2: Mes 59 | BJ2: Mes 60
A3: =+'COSTOS DE OPERACION'!A3 -> Director de Proyecto | B3: =+'Costos HH por MES'!$H$5 -> 640 | C3: =$B$3 -> 640 | D3: =$B$3 -> 640 | E3: =$B$3 -> 640 | F3: =$B$3 -> 640 | G3: =$B$3 -> 640 | H3: =$B$3 -> 640 | I3: =$B$3 -> 640 | J3: =$B$3 -> 640 | ... N3: =$B$3 -> 640 | O3: =$B$3/20 -> 32 | P3: =$B$3/20 -> 32 | Q3: =$B$3/20 -> 32 | R3: =$B$3/20 -> 32 | S3: =$B$3/20 -> 32 | T3: =$B$3/20 -> 32 | U3: =$B$3/20 -> 32 | V3: =$B$3/20 -> 32 | ... BJ3: =$B$3/20 -> 32
A4: =+'COSTOS DE OPERACION'!A4 -> Analista de Negocios Senior A | B4: =+'Costos HH por MES'!$H$6 -> 192 | C4: =B$4 -> 192 | D4: =$B$4 -> 192
A5: =+'COSTOS DE OPERACION'!A5 -> Analista de Negocios Senior B | B5: =B4 -> 192 | C5: =($B$5) -> 192 | D5: =($C$5) -> 192 | F5: =(E5) -> 0 | G5: =(F5) -> 0 | H5: =(G5) -> 0 | I5: =(H5) -> 0 | J5: =(I5) -> 0 | K5: =(J5) -> 0 | L5: =(K5) -> 0 | M5: =(L5) -> 0 | N5: =(M5) -> 0
A6: =+'COSTOS DE OPERACION'!A6 -> Analista de Negocios Junior A | B6: =+'Costos HH por MES'!$H$7 -> 160 | C6: =($B$6) -> 160 | D6: =($C$6) -> 160
A7: =+'COSTOS DE OPERACION'!A7 -> Analista de Negocios Junior B | B7: =B6 -> 160 | C7: =($B$7) -> 160 | D7: =(C7) -> 160
A8: =+'COSTOS DE OPERACION'!A8 -> Gestor de Riesgos Senior | B8: =+'Costos HH por MES'!$H$8 -> 240 | C8: =($B$8) -> 240 | D8: =($B$8) -> 240 | E8: =($B$8) -> 240 | F8: =($B$8) -> 240 | G8: =($B$8) -> 240 | H8: =($B$8) -> 240 | I8: =($B$8) -> 240 | J8: =($B$8) -> 240 | ... N8: =($B$8) -> 240 | O8: =$B$8 -> 240 | P8: =$B$8 -> 240 | Q8: =$B$8 -> 240 | R8: =$B$8/2 -> 120
A9: =+'COSTOS DE OPERACION'!A9 -> Analista de Sistemas Senior A | B9: =+'Costos HH por MES'!H9 -> 160 | C9: =$B$9 -> 160 | D9: =$B$9 -> 160 | E9: =$B$9 -> 160
A10: =+'COSTOS DE OPERACION'!A10 -> Analista de Sistemas Senior B | B10: =$B$9 -> 160 | C10: =$B$10 -> 160 | D10: =$B$10 -> 160 | E10: =$B$10 -> 160
A11: =+'COSTOS DE OPERACION'!A11 -> Analista de Sistemas Senior C | B11: =$B$9 -> 160 | C11: =($B$11) -> 160 | D11: =($B$11) -> 160 | E11: =($B$11) -> 160
A12: =+'COSTOS DE OPERACION'!A12 -> Analista de Sistemas Senior D | B12: =$B$9 -> 160 | C12: =($B$12) -> 160 | D12: =($B$12) -> 160 | E12: =($B$12) -> 160
A13: =+'COSTOS DE OPERACION'!A13 -> Analista de Sistemas Junior A | B13: =+'Costos HH por MES'!H10 -> 128 | C13: =($B$13) -> 128 | D13: =($B$13) -> 128 | E13: =($B$13) -> 128
A14: =+'COSTOS DE OPERACION'!A14 -> Analista de Sistemas Junior B | B14: =B13 -> 128 | C14: =($B$14) -> 128 | D14: =($B$14) -> 128 | E14: =($B$14) -> 128
A15: =+'COSTOS DE OPERACION'!A15 -> Diseñador de UX senior A | B15: =+'Costos HH por MES'!H11 -> 160 | C15: =($B$15) -> 160 | D15: =($B$15) -> 160 | E15: =($B$15) -> 160 | G15: =($B$15) -> 160 | H15: =($B$15) -> 160 | J15: =($B$15) -> 160 | K15: =($B$15) -> 160 | L15: =($B$15) -> 160 | M15: =($B$15) -> 160
A16: =+'COSTOS DE OPERACION'!A16 -> Diseñador de UX senior B | B16: =+'Costos HH por MES'!H11 -> 160 | C16: =($B$16) -> 160 | D16: =($B$16) -> 160 | E16: =($B$16) -> 160 | G16: =($B$16) -> 160 | H16: =($B$16) -> 160 | J16: =($B$16) -> 160 | K16: =($B$16) -> 160 | L16: =($B$16) -> 160 | M16: =($B$16) -> 160
A17: =+'COSTOS DE OPERACION'!A17 -> Diseñador de UX junior A | B17: =+'Costos HH por MES'!H12 -> 128 | C17: =$B$17 -> 128 | D17: =$B$17 -> 128 | E17: =$B$17 -> 128 | G17: =$B$17 -> 128 | H17: =$B$17 -> 128 | J17: =$B$17 -> 128 | K17: =$B$17 -> 128 | L17: =$B$17 -> 128 | M17: =$B$17 -> 128
A18: =+'COSTOS DE OPERACION'!A18 -> Diseñador de UX junior B | B18: =+'Costos HH por MES'!H12 -> 128 | C18: =$B$18 -> 128 | D18: =$B$18 -> 128 | E18: =$B$18 -> 128 | G18: =$B$18 -> 128 | H18: =$B$18 -> 128 | J18: =$B$18 -> 128 | K18: =$B$18 -> 128 | L18: =$B$18 -> 128 | M18: =$B$18 -> 128
A19: =+'COSTOS DE OPERACION'!A19 -> Arquitecto de Software Senior | B19: =+'Costos HH por MES'!H13 -> 400 | C19: =$B$19 -> 400 | D19: =$B$19 -> 400 | E19: =$B$19 -> 400
A20: =+'COSTOS DE OPERACION'!A20 -> Arquitecto de Software Junior | B20: =+'Costos HH por MES'!$H$14 -> 240 | C20: =$B$20 -> 240 | D20: =$B$20 -> 240 | E20: =$B$20 -> 240
A21: =+'COSTOS DE OPERACION'!A21 -> Desarrollador Front-end senior A | B21: =$B$16 -> 160 | F21: =(B21/20)*6 -> 48 | G21: =B21 -> 160 | H21: =B21 -> 160 | I21: 112
A22: =+'COSTOS DE OPERACION'!A22 -> Desarrollador Front-end senior B | B22: =$B$16 -> 160 | F22: =(B22/20)*6 -> 48 | G22: =B22 -> 160 | H22: =B22 -> 160 | I22: 112
A23: =+'COSTOS DE OPERACION'!A23 -> Desarrollador Front-end Junior A | B23: =+'Costos HH por MES'!$H$16 -> 128 | F23: =(B23/20)*6 -> 38.4 | G23: =B23 -> 128 | H23: =B23 -> 128 | I23: =B23 -> 128 | N23: 64 | O23: =$B$23 -> 128 | P23: =$B$23 -> 128 | Q23: =$B$23 -> 128 | R23: =$B$23 -> 128 | S23: =$B$23 -> 128 | T23: =$B$23 -> 128 | U23: =$B$23 -> 128 | V23: =$B$23 -> 128 | ... BJ23: =$B$23 -> 128
A24: =+'COSTOS DE OPERACION'!A24 -> Desarrollador Front-end Junior B | B24: =+'Costos HH por MES'!$H$16 -> 128 | F24: =(B24/20)*6 -> 38.4 | G24: =B24 -> 128 | H24: =B24 -> 128 | I24: =B24 -> 128
A25: =+'COSTOS DE OPERACION'!A25 -> Desarrollador Back-end Senior A | B25: =+'Costos HH por MES'!$H$17 -> 160 | F25: =(B25/20)*6 -> 48 | G25: =B25 -> 160 | H25: =B25 -> 160 | I25: =B25 -> 160
A26: =+'COSTOS DE OPERACION'!A26 -> Desarrollador Back-end Senior B | B26: =+'Costos HH por MES'!$H$17 -> 160 | F26: =(B26/20)*6 -> 48 | G26: =B26 -> 160 | H26: =B26 -> 160 | I26: =B26 -> 160
A27: =+'COSTOS DE OPERACION'!A27 -> Desarrollador Back-end junior A | B27: =+'Costos HH por MES'!$H$18 -> 128 | F27: =(B27/20)*6 -> 38.4 | G27: =B27 -> 128 | H27: =B27 -> 128 | I27: =B27 -> 128 | N27: 64 | O27: =$B$27 -> 128 | P27: =$B$27 -> 128 | Q27: =$B$27 -> 128 | R27: =$B$27 -> 128 | S27: =$B$27 -> 128 | T27: =$B$27 -> 128 | U27: =$B$27 -> 128 | V27: =$B$27 -> 128 | ... BJ27: =$B$27 -> 128
A28: =+'COSTOS DE OPERACION'!A28 -> Desarrollador Back-end junior B | B28: =B27 -> 128 | F28: =(B28/20)*6 -> 38.4 | G28: =B28 -> 128 | H28: =B28 -> 128 | I28: =B28 -> 128
A29: =+'COSTOS DE OPERACION'!A29 -> Desarrollador de software Senior | B29: ='Costos HH por MES'!H19 -> 160 | F29: =(B29/20)*6 -> 48 | G29: =B29 -> 160 | H29: =B29 -> 160 | I29: =B29 -> 160
A30: =+'COSTOS DE OPERACION'!A30 -> Desarrollador de software junior | B30: ='Costos HH por MES'!H20 -> 128 | F30: =(B30/20)*6 -> 38.4 | G30: =B30 -> 128 | H30: =B30 -> 128 | I30: =$B$30 -> 128 | M30: =E30 -> 0 | N30: 128 | O30: =$B$30 -> 128 | P30: =$B$30 -> 128 | Q30: =$B$30 -> 128 | R30: =$B$30 -> 128 | S30: =$B$30 -> 128 | T30: =$B$30 -> 128 | U30: =$B$30 -> 128 | V30: =$B$30 -> 128 | ... BJ30: =$B$30 -> 128
A31: =+'COSTOS DE OPERACION'!A31 -> Diseñador de base de datos senior | B31: ='Costos HH por MES'!H21 -> 160 | C31: =$B$31 -> 160 | D31: =$B$31 -> 160 | E31: =$B$31 -> 160
