Workbook

Sheet Resumen
A2: Estimación por puntos de casos de uso
A4: LafroX para Distribuidora Puelche. Alcance E1 + E2 e innovaciones. Valores propuestos al 30/10/2026.
A8: Medida | B8: Resultado | C8: Unidad / origen | E8: Actividad | F8: Participación | G8: Horas de desarrollo
A9: Actores incluidos | B9: =SUM('Actores UAW'!$E$9:$E$100) -> 32 | C9: Roles y sistemas externos | E9: =Esfuerzo!A20 -> Análisis | F9: =Esfuerzo!B20 -> 0.1 | G9: =Esfuerzo!C20 -> 4749.3906
A10: Casos de uso incluidos | B10: =COUNTIF('Catalogo CU'!$G$9:$G$500,1) -> 91 | C10: Objetivos del actor | E10: =Esfuerzo!A21 -> Diseño | F10: =Esfuerzo!B21 -> 0.2 | G10: =Esfuerzo!C21 -> 9498.7812
A11: Transacciones incluidas | B11: =SUMIFS('Catalogo CU'!$J$9:$J$500,'Catalogo CU'!$G$9:$G$500,1) -> 390 | C11: Interacciones, sin multiplicar repeticiones | E11: =Esfuerzo!A22 -> Programación | F11: =Esfuerzo!B22 -> 0.4 | G11: =Esfuerzo!C22 -> 18997.562
A12: Peso de actores UAW | B12: ='Actores UAW'!B5 -> 75 | C12: puntos | E12: =Esfuerzo!A23 -> Pruebas | F12: =Esfuerzo!B23 -> 0.15 | G12: =Esfuerzo!C23 -> 7124.0859
A13: Peso de casos UUCW | B13: ='Casos UUCW'!B5 -> 790 | C13: puntos | E13: =Esfuerzo!A24 -> Sobrecarga | F13: =Esfuerzo!B24 -> 0.15 | G13: =Esfuerzo!C24 -> 7124.0859
A14: Puntos sin ajustar UUCP | B14: ='Puntos sin ajustar'!B11 -> 865 | C14: puntos
A15: Factor técnico TCF | B15: ='Factores tecnicos'!B5 -> 1.255 | C15: coeficiente
A16: Factor de ambiente EF | B16: ='Factores ambiente'!B5 -> 0.875 | C16: coeficiente | E16: Etapa contractual | F16: UUCW | G16: Horas de desarrollo
A17: Puntos ajustados UCP | B17: ='Puntos ajustados'!B12 -> 949.87812 | C17: UCP | E17: Etapa 1 | F17: ='Puntos sin ajustar'!C10 -> 630 | G17: =Esfuerzo!D14 -> 37874.887
A18: Factor de conversión | B18: =Esfuerzo!B11 -> 20 | C18: HH por UCP | E18: Etapa 2 | F18: ='Puntos sin ajustar'!D10 -> 160 | G18: =Esfuerzo!E14 -> 9619.019
A19: Horas de programación | B19: =Esfuerzo!B12 -> 18997.562 | C19: HH
A20: Horas totales de desarrollo | B20: =Esfuerzo!B14 -> 47493.906 | C20: HH, lectura B del PDF
A23: Cómo editar
A24: 1. Cambie puntuaciones amarillas en Factores ambiente o Factores tecnicos.
A25: 2. Para cambiar complejidad de un caso, edite sus filas de Transacciones y la columna Contar.
A26: 3. Para excluir alcance, cambie Incluir a 0 en el Catálogo o en Actores UAW.
A27: 4. Las fórmulas actualizan factores, puntos, conversión, horas y distribución. Excel debe usar cálculo automático.
A29: Estado del esfuerzo | B29: =Esfuerzo!B15 -> Calculado con valores propuestos
A31: Las horas excluyen operación, infraestructura, migración, capacitación ejecutada y reservas.
A33: Celdas amarillas: entradas editables. Valores sin relleno amarillo: fórmulas, datos fuente o reglas publicadas.

Sheet Catalogo CU
A2: Catálogo de casos de uso
A4: Desglose propuesto desde requisitos. Las cantidades se calculan desde Transacciones; edite el detalle para cambiarlas.
A8: ID caso | B8: Módulo | C8: Etapa | D8: Caso de uso | E8: Descripción y resultado | F8: Actores (ID) | G8: Incluir | H8: Principal | I8: Alternativo | J8: Total tx | K8: Requisitos / innovación | L8: Fuente funcional | M8: Control
A9: CU-001 | B9: M1 Recepción | C9: E1 | D9: Registrar recepción de proveedor | E9: Registrar cantidades, lote y vencimiento contra la orden de compra; el cierre conserva discrepancias y solicita el ingreso al ERP. | F9: A14, A04 | G9: 1 | H9: =SUMIFS(Transacciones!$G$9:$G$3000,Transacciones!$B$9:$B$3000,A9,Transacciones!$D$9:$D$3000,"Principal") -> 5 | I9: =SUMIFS(Transacciones!$G$9:$G$3000,Transacciones!$B$9:$B$3000,A9,Transacciones!$D$9:$D$3000,"Alternativo adicional") -> 1 | J9: =SUM(H9:I9) -> 6 | K9: RF-01.01, RF-01.02, RF-01.03, RF-01.06, RF-01.09 | L9: SD3 Anexo 3.A | M9: =IF(AND(ISNUMBER(G9),G9=0),"Excluido",IF(AND(ISNUMBER(G9),G9=1,COUNTIF($A$9:$A$500,A9)=1,OR(C9="E1",C9="E2"),D9<>"",E9<>"",F9<>"",J9>=1,COUNTIFS(Transacciones!$B$9:$B$3000,A9,Transacciones!$H$9:$H$3000,"<>Válido")=0),"Válido","Revisar caso o detalle")) -> Válido
A10: CU-002 | B10: M1 Recepción | C10: E1 | D10: Registrar no conformidad en recepción | E10: Documentar una anomalía con evidencia y retener la cantidad afectada para evaluación de Calidad. | F10: A14, A09 | G10: 1 | H10: =SUMIFS(Transacciones!$G$9:$G$3000,Transacciones!$B$9:$B$3000,A10,Transacciones!$D$9:$D$3000,"Principal") -> 4 | I10: =SUMIFS(Transacciones!$G$9:$G$3000,Transacciones!$B$9:$B$3000,A10,Transacciones!$D$9:$D$3000,"Alternativo adicional") -> 0 | J10: =SUM(H10:I10) -> 4 | K10: RF-01.04, RF-01.05 | L10: SD3 Anexo 3.A | M10: =IF(AND(ISNUMBER(G10),G10=0),"Excluido",IF(AND(ISNUMBER(G10),G10=1,COUNTIF($A$9:$A$500,A10)=1,OR(C10="E1",C10="E2"),D10<>"",E10<>"",F10<>"",J10>=1,COUNTIFS(Transacciones!$B$9:$B$3000,A10,Transacciones!$H$9:$H$3000,"<>Válido")=0),"Válido","Revisar caso o detalle")) -> Válido
A11: CU-003 | B11: M1 Recepción | C11: E1 | D11: Identificar unidad logística con SSCC | E11: Generar e imprimir la identificación logística de un pallet con vínculo a su contenido, sin confundir SSCC con lote. | F11: A14, A04 | G11: 1 | H11: =SUMIFS(Transacciones!$G$9:$G$3000,Transacciones!$B$9:$B$3000,A11,Transacciones!$D$9:$D$3000,"Principal") -> 3 | I11: =SUMIFS(Transacciones!$G$9:$G$3000,Transacciones!$B$9:$B$3000,A11,Transacciones!$D$9:$D$3000,"Alternativo adicional") -> 0 | J11: =SUM(H11:I11) -> 3 | K11: RF-01.07 | L11: SD3 Anexo 3.A | M11: =IF(AND(ISNUMBER(G11),G11=0),"Excluido",IF(AND(ISNUMBER(G11),G11=1,COUNTIF($A$9:$A$500,A11)=1,OR(C11="E1",C11="E2"),D11<>"",E11<>"",F11<>"",J11>=1,COUNTIFS(Transacciones!$B$9:$B$3000,A11,Transacciones!$H$9:$H$3000,"<>Válido")=0),"Válido","Revisar caso o detalle")) -> Válido
A12: CU-004 | B12: M1 Recepción | C12: E1 | D12: Ubicar unidad logística en bodega | E12: Asociar una unidad logística a una posición térmicamente compatible y registrar el movimiento. | F12: A04, A14 | G12: 1 | H12: =SUMIFS(Transacciones!$G$9:$G$3000,Transacciones!$B$9:$B$3000,A12,Transacciones!$D$9:$D$3000,"Principal") -> 3 | I12: =SUMIFS(Transacciones!$G$9:$G$3000,Transacciones!$B$9:$B$3000,A12,Transacciones!$D$9:$D$3000,"Alternativo adicional") -> 0 | J12: =SUM(H12:I12) -> 3 | K12: RF-01.08, RF-01.11 | L12: SD3 Anexo 3.A | M12: =IF(AND(ISNUMBER(G12),G12=0),"Excluido",IF(AND(ISNUMBER(G12),G12=1,COUNTIF($A$9:$A$500,A12)=1,OR(C12="E1",C12="E2"),D12<>"",E12<>"",F12<>"",J12>=1,COUNTIFS(Transacciones!$B$9:$B$3000,A12,Transacciones!$H$9:$H$3000,"<>Válido")=0),"Válido","Revisar caso o detalle")) -> Válido
A13: CU-005 | B13: M1 Recepción | C13: E1 | D13: Mantener maestro de productos | E13: Mantener fichas y atributos logísticos, comerciales y sanitarios con historial de cambios. | F13: A10, A13, A16 | G13: 1 | H13: =SUMIFS(Transacciones!$G$9:$G$3000,Transacciones!$B$9:$B$3000,A13,Transacciones!$D$9:$D$3000,"Principal") -> 5 | I13: =SUMIFS(Transacciones!$G$9:$G$3000,Transacciones!$B$9:$B$3000,A13,Transacciones!$D$9:$D$3000,"Alternativo adicional") -> 0 | J13: =SUM(H13:I13) -> 5 | K13: RF-01.10 | L13: SD3 Anexo 3.A | M13: =IF(AND(ISNUMBER(G13),G13=0),"Excluido",IF(AND(ISNUMBER(G13),G13=1,COUNTIF($A$9:$A$500,A13)=1,OR(C13="E1",C13="E2"),D13<>"",E13<>"",F13<>"",J13>=1,COUNTIFS(Transacciones!$B$9:$B$3000,A13,Transacciones!$H$9:$H$3000,"<>Válido")=0),"Válido","Revisar caso o detalle")) -> Válido
A14: CU-006 | B14: M2 Inventario | C14: E1 | D14: Configurar instalaciones y ubicaciones | E14: Mantener sitios, zonas térmicas y posiciones, con disponibilidad local para operar sin WAN. | F14: A13, A14 | G14: 1 | H14: =SUMIFS(Transacciones!$G$9:$G$3000,Transacciones!$B$9:$B$3000,A14,Transacciones!$D$9:$D$3000,"Principal") -> 5 | I14: =SUMIFS(Transacciones!$G$9:$G$3000,Transacciones!$B$9:$B$3000,A14,Transacciones!$D$9:$D$3000,"Alternativo adicional") -> 0 | J14: =SUM(H14:I14) -> 5 | K14: RF-02.01 | L14: SD3 Anexo 3.A | M14: =IF(AND(ISNUMBER(G14),G14=0),"Excluido",IF(AND(ISNUMBER(G14),G14=1,COUNTIF($A$9:$A$500,A14)=1,OR(C14="E1",C14="E2"),D14<>"",E14<>"",F14<>"",J14>=1,COUNTIFS(Transacciones!$B$9:$B$3000,A14,Transacciones!$H$9:$H$3000,"<>Válido")=0),"Válido","Revisar caso o detalle")) -> Válido
A15: CU-007 | B15: M2 Inventario | C15: E1 | D15: Consultar stock y disponibilidad | E15: Consultar existencias físicas, comprometidas, disponibles y en tránsito por SKU y sitio, mostrando antigüedad sin conexión. | F15: A01, A14, A13 | G15: 1 | H15: =SUMIFS(Transacciones!$G$9:$G$3000,Transacciones!$B$9:$B$3000,A15,Transacciones!$D$9:$D$3000,"Principal") -> 3 | I15: =SUMIFS(Transacciones!$G$9:$G$3000,Transacciones!$B$9:$B$3000,A15,Transacciones!$D$9:$D$3000,"Alternativo adicional") -> 0 | J15: =SUM(H15:I15) -> 3 | K15: RF-02.02, RF-02.05, RF-03.01, RF-03.02 | L15: SD3 Anexo 3.A | M15: =IF(AND(ISNUMBER(G15),G15=0),"Excluido",IF(AND(ISNUMBER(G15),G15=1,COUNTIF($A$9:$A$500,A15)=1,OR(C15="E1",C15="E2"),D15<>"",E15<>"",F15<>"",J15>=1,COUNTIFS(Transacciones!$B$9:$B$3000,A15,Transacciones!$H$9:$H$3000,"<>Válido")=0),"Válido","Revisar caso o detalle")) -> Válido
A16: CU-008 | B16: M2 Inventario | C16: E1 | D16: Aprobar y ejecutar propuesta de slotting | E16: Proponer y aprobar reubicaciones por rotación, capacidad y compatibilidad térmica. | F16: A14, A04 | G16: 1 | H16: =SUMIFS(Transacciones!$G$9:$G$3000,Transacciones!$B$9:$B$3000,A16,Transacciones!$D$9:$D$3000,"Principal") -> 5 | I16: =SUMIFS(Transacciones!$G$9:$G$3000,Transacciones!$B$9:$B$3000,A16,Transacciones!$D$9:$D$3000,"Alternativo adicional") -> 0 | J16: =SUM(H16:I16) -> 5 | K16: RF-02.03 | L16: SD3 Anexo 3.A | M16: =IF(AND(ISNUMBER(G16),G16=0),"Excluido",IF(AND(ISNUMBER(G16),G16=1,COUNTIF($A$9:$A$500,A16)=1,OR(C16="E1",C16="E2"),D16<>"",E16<>"",F16<>"",J16>=1,COUNTIFS(Transacciones!$B$9:$B$3000,A16,Transacciones!$H$9:$H$3000,"<>Válido")=0),"Válido","Revisar caso o detalle")) -> Válido
A17: CU-009 | B17: M2 Inventario | C17: E1 | D17: Realizar conteo cíclico y ajuste | E17: Planificar conteos ciegos y resolver diferencias con umbral y segregación de autorización. | F17: A14, A04 | G17: 1 | H17: =SUMIFS(Transacciones!$G$9:$G$3000,Transacciones!$B$9:$B$3000,A17,Transacciones!$D$9:$D$3000,"Principal") -> 5 | I17: =SUMIFS(Transacciones!$G$9:$G$3000,Transacciones!$B$9:$B$3000,A17,Transacciones!$D$9:$D$3000,"Alternativo adicional") -> 1 | J17: =SUM(H17:I17) -> 6 | K17: RF-02.04 | L17: SD3 Anexo 3.A | M17: =IF(AND(ISNUMBER(G17),G17=0),"Excluido",IF(AND(ISNUMBER(G17),G17=1,COUNTIF($A$9:$A$500,A17)=1,OR(C17="E1",C17="E2"),D17<>"",E17<>"",F17<>"",J17>=1,COUNTIFS(Transacciones!$B$9:$B$3000,A17,Transacciones!$H$9:$H$3000,"<>Válido")=0),"Válido","Revisar caso o detalle")) -> Válido
A18: CU-010 | B18: M2 Inventario | C18: E1 | D18: Transferir inventario entre sitios | E18: Despachar y recibir existencias en tránsito, conservando la autoridad local y el movimiento hacia el ERP. | F18: A14, A04 | G18: 1 | H18: =SUMIFS(Transacciones!$G$9:$G$3000,Transacciones!$B$9:$B$3000,A18,Transacciones!$D$9:$D$3000,"Principal") -> 5 | I18: =SUMIFS(Transacciones!$G$9:$G$3000,Transacciones!$B$9:$B$3000,A18,Transacciones!$D$9:$D$3000,"Alternativo adicional") -> 1 | J18: =SUM(H18:I18) -> 6 | K18: RF-02.06 | L18: SD3 Anexo 3.A | M18: =IF(AND(ISNUMBER(G18),G18=0),"Excluido",IF(AND(ISNUMBER(G18),G18=1,COUNTIF($A$9:$A$500,A18)=1,OR(C18="E1",C18="E2"),D18<>"",E18<>"",F18<>"",J18>=1,COUNTIFS(Transacciones!$B$9:$B$3000,A18,Transacciones!$H$9:$H$3000,"<>Válido")=0),"Válido","Revisar caso o detalle")) -> Válido
A19: CU-011 | B19: M2 Inventario | C19: E1 | D19: Consultar ocupación de bodegas | E19: Consultar capacidad utilizada por instalación y zona con histórico exportable. | F19: A14, A13 | G19: 1 | H19: =SUMIFS(Transacciones!$G$9:$G$3000,Transacciones!$B$9:$B$3000,A19,Transacciones!$D$9:$D$3000,"Principal") -> 3 | I19: =SUMIFS(Transacciones!$G$9:$G$3000,Transacciones!$B$9:$B$3000,A19,Transacciones!$D$9:$D$3000,"Alternativo adicional") -> 0 | J19: =SUM(H19:I19) -> 3 | K19: RF-02.07 | L19: SD3 Anexo 3.A | M19: =IF(AND(ISNUMBER(G19),G19=0),"Excluido",IF(AND(ISNUMBER(G19),G19=1,COUNTIF($A$9:$A$500,A19)=1,OR(C19="E1",C19="E2"),D19<>"",E19<>"",F19<>"",J19>=1,COUNTIFS(Transacciones!$B$9:$B$3000,A19,Transacciones!$H$9:$H$3000,"<>Válido")=0),"Válido","Revisar caso o detalle")) -> Válido
A20: CU-012 | B20: M2 Inventario | C20: E1 | D20: Gestionar alertas de vencimiento en bodega | E20: Revisar lotes próximos a vencer y registrar una acción permitida sin sustituir FEFO. | F20: A14, A09 | G20: 1 | H20: =SUMIFS(Transacciones!$G$9:$G$3000,Transacciones!$B$9:$B$3000,A20,Transacciones!$D$9:$D$3000,"Principal") -> 3 | I20: =SUMIFS(Transacciones!$G$9:$G$3000,Transacciones!$B$9:$B$3000,A20,Transacciones!$D$9:$D$3000,"Alternativo adicional") -> 0 | J20: =SUM(H20:I20) -> 3 | K20: RF-02.09 | L20: SD3 Anexo 3.A | M20: =IF(AND(ISNUMBER(G20),G20=0),"Excluido",IF(AND(ISNUMBER(G20),G20=1,COUNTIF($A$9:$A$500,A20)=1,OR(C20="E1",C20="E2"),D20<>"",E20<>"",F20<>"",J20>=1,COUNTIFS(Transacciones!$B$9:$B$3000,A20,Transacciones!$H$9:$H$3000,"<>Válido")=0),"Válido","Revisar caso o detalle")) -> Válido
... A99: CU-091 | B99: Base compartida | C99: E1 | D99: Clasificar información y aplicar acceso | E99: Asignar nivel de sensibilidad a conjuntos de información y revisar controles de acceso correspondientes. | F99: A15 | G99: 1 | H99: =SUMIFS(Transacciones!$G$9:$G$3000,Transacciones!$B$9:$B$3000,A99,Transacciones!$D$9:$D$3000,"Principal") -> 4 | I99: =SUMIFS(Transacciones!$G$9:$G$3000,Transacciones!$B$9:$B$3000,A99,Transacciones!$D$9:$D$3000,"Alternativo adicional") -> 0 | J99: =SUM(H99:I99) -> 4 | K99: RF-14.01-BTT | L99: SD3 Anexo 3.A | M99: =IF(AND(ISNUMBER(G99),G99=0),"Excluido",IF(AND(ISNUMBER(G99),G99=1,COUNTIF($A$9:$A$500,A99)=1,OR(C99="E1",C99="E2"),D99<>"",E99<>"",F99<>"",J99>=1,COUNTIFS(Transacciones!$B$9:$B$3000,A99,Transacciones!$H$9:$H$3000,"<>Válido")=0),"Válido","Revisar caso o detalle")) -> Válido

Sheet Transacciones
A2: Transacciones por caso de uso
A4: Amarillo: entradas editables. Contar = 1 incluye la interacción; 0 la excluye. No sumar repeticiones del mismo tipo.
A8: ID transacción | B8: ID caso | C8: N.º | D8: Flujo | E8: Acción del actor | F8: Respuesta del sistema | G8: Contar | H8: Control
A9: CU-001-T01 | B9: CU-001 | C9: 1 | D9: Principal | E9: Selecciona la orden de compra y el andén | F9: Muestra líneas esperadas y recepción abierta | G9: 1 | H9: =IF(G9=0,"Válido",IF(AND(ISNUMBER(G9),G9=1,A9<>"",COUNTIF($A$9:$A$3000,A9)=1,COUNTIF('Catalogo CU'!$A$9:$A$500,B9)=1,ISNUMBER(C9),C9>=1,OR(D9="Principal",D9="Alternativo adicional"),E9<>"",F9<>""),"Válido","Revisar transacción")) -> Válido
A10: CU-001-T02 | B10: CU-001 | C10: 2 | D10: Principal | E10: Escanea el producto y su lote GS1 | F10: Identifica SKU, lote y vencimiento y muestra los datos capturados | G10: 1 | H10: =IF(G10=0,"Válido",IF(AND(ISNUMBER(G10),G10=1,A10<>"",COUNTIF($A$9:$A$3000,A10)=1,COUNTIF('Catalogo CU'!$A$9:$A$500,B10)=1,ISNUMBER(C10),C10>=1,OR(D10="Principal",D10="Alternativo adicional"),E10<>"",F10<>""),"Válido","Revisar transacción")) -> Válido
A11: CU-001-T03 | B11: CU-001 | C11: 3 | D11: Principal | E11: Registra cantidades y confirma los datos de la línea | F11: Valida campos obligatorios y muestra diferencias contra la orden | G11: 1 | H11: =IF(G11=0,"Válido",IF(AND(ISNUMBER(G11),G11=1,A11<>"",COUNTIF($A$9:$A$3000,A11)=1,COUNTIF('Catalogo CU'!$A$9:$A$500,B11)=1,ISNUMBER(C11),C11>=1,OR(D11="Principal",D11="Alternativo adicional"),E11<>"",F11<>""),"Válido","Revisar transacción")) -> Válido
A12: CU-001-T04 | B12: CU-001 | C12: 4 | D12: Principal | E12: Solicita el resumen de recepción | F12: Presenta cantidades, lotes y discrepancias del documento | G12: 1 | H12: =IF(G12=0,"Válido",IF(AND(ISNUMBER(G12),G12=1,A12<>"",COUNTIF($A$9:$A$3000,A12)=1,COUNTIF('Catalogo CU'!$A$9:$A$500,B12)=1,ISNUMBER(C12),C12>=1,OR(D12="Principal",D12="Alternativo adicional"),E12<>"",F12<>""),"Válido","Revisar transacción")) -> Válido
A13: CU-001-T05 | B13: CU-001 | C13: 5 | D13: Principal | E13: Confirma el cierre de la recepción | F13: Registra el ingreso y devuelve identificador y estado de integración | G13: 1 | H13: =IF(G13=0,"Válido",IF(AND(ISNUMBER(G13),G13=1,A13<>"",COUNTIF($A$9:$A$3000,A13)=1,COUNTIF('Catalogo CU'!$A$9:$A$500,B13)=1,ISNUMBER(C13),C13>=1,OR(D13="Principal",D13="Alternativo adicional"),E13<>"",F13<>""),"Válido","Revisar transacción")) -> Válido
A14: CU-001-T06 | B14: CU-001 | C14: 6 | D14: Alternativo adicional | E14: Ingresa manualmente un código no reconocido | F14: Valida el ingreso autorizado y devuelve la línea identificada | G14: 1 | H14: =IF(G14=0,"Válido",IF(AND(ISNUMBER(G14),G14=1,A14<>"",COUNTIF($A$9:$A$3000,A14)=1,COUNTIF('Catalogo CU'!$A$9:$A$500,B14)=1,ISNUMBER(C14),C14>=1,OR(D14="Principal",D14="Alternativo adicional"),E14<>"",F14<>""),"Válido","Revisar transacción")) -> Válido
A15: CU-002-T01 | B15: CU-002 | C15: 1 | D15: Principal | E15: Selecciona recepción y cantidad afectada | F15: Muestra SKU y lote vinculados | G15: 1 | H15: =IF(G15=0,"Válido",IF(AND(ISNUMBER(G15),G15=1,A15<>"",COUNTIF($A$9:$A$3000,A15)=1,COUNTIF('Catalogo CU'!$A$9:$A$500,B15)=1,ISNUMBER(C15),C15>=1,OR(D15="Principal",D15="Alternativo adicional"),E15<>"",F15<>""),"Válido","Revisar transacción")) -> Válido
A16: CU-002-T02 | B16: CU-002 | C16: 2 | D16: Principal | E16: Indica tipo de no conformidad y observaciones | F16: Valida la causa y muestra el detalle | G16: 1 | H16: =IF(G16=0,"Válido",IF(AND(ISNUMBER(G16),G16=1,A16<>"",COUNTIF($A$9:$A$3000,A16)=1,COUNTIF('Catalogo CU'!$A$9:$A$500,B16)=1,ISNUMBER(C16),C16>=1,OR(D16="Principal",D16="Alternativo adicional"),E16<>"",F16<>""),"Válido","Revisar transacción")) -> Válido
A17: CU-002-T03 | B17: CU-002 | C17: 3 | D17: Principal | E17: Adjunta la fotografía | F17: Confirma el archivo y su vinculación | G17: 1 | H17: =IF(G17=0,"Válido",IF(AND(ISNUMBER(G17),G17=1,A17<>"",COUNTIF($A$9:$A$3000,A17)=1,COUNTIF('Catalogo CU'!$A$9:$A$500,B17)=1,ISNUMBER(C17),C17>=1,OR(D17="Principal",D17="Alternativo adicional"),E17<>"",F17<>""),"Válido","Revisar transacción")) -> Válido
A18: CU-002-T04 | B18: CU-002 | C18: 4 | D18: Principal | E18: Confirma la no conformidad | F18: Registra cuarentena y devuelve estado y aviso a Calidad | G18: 1 | H18: =IF(G18=0,"Válido",IF(AND(ISNUMBER(G18),G18=1,A18<>"",COUNTIF($A$9:$A$3000,A18)=1,COUNTIF('Catalogo CU'!$A$9:$A$500,B18)=1,ISNUMBER(C18),C18>=1,OR(D18="Principal",D18="Alternativo adicional"),E18<>"",F18<>""),"Válido","Revisar transacción")) -> Válido
A19: CU-003-T01 | B19: CU-003 | C19: 1 | D19: Principal | E19: Selecciona el pallet recibido | F19: Muestra contenido, lotes y vencimientos | G19: 1 | H19: =IF(G19=0,"Válido",IF(AND(ISNUMBER(G19),G19=1,A19<>"",COUNTIF($A$9:$A$3000,A19)=1,COUNTIF('Catalogo CU'!$A$9:$A$500,B19)=1,ISNUMBER(C19),C19>=1,OR(D19="Principal",D19="Alternativo adicional"),E19<>"",F19<>""),"Válido","Revisar transacción")) -> Válido
A20: CU-003-T02 | B20: CU-003 | C20: 2 | D20: Principal | E20: Confirma su identificación | F20: Asigna SSCC único y presenta etiqueta GS1-128 | G20: 1 | H20: =IF(G20=0,"Válido",IF(AND(ISNUMBER(G20),G20=1,A20<>"",COUNTIF($A$9:$A$3000,A20)=1,COUNTIF('Catalogo CU'!$A$9:$A$500,B20)=1,ISNUMBER(C20),C20>=1,OR(D20="Principal",D20="Alternativo adicional"),E20<>"",F20<>""),"Válido","Revisar transacción")) -> Válido
... A398: CU-091-T04 | B398: CU-091 | C398: 4 | D398: Principal | E398: Confirma clasificación autorizada | F398: Publica nivel y conserva auditoría | G398: 1 | H398: =IF(G398=0,"Válido",IF(AND(ISNUMBER(G398),G398=1,A398<>"",COUNTIF($A$9:$A$3000,A398)=1,COUNTIF('Catalogo CU'!$A$9:$A$500,B398)=1,ISNUMBER(C398),C398>=1,OR(D398="Principal",D398="Alternativo adicional"),E398<>"",F398<>""),"Válido","Revisar transacción")) -> Válido

Sheet Actores UAW
A2: Peso de los actores sin ajustar
A4: Un actor por rol o contrato de interacción. Amarillo: interfaz e inclusión. Los cuatro roles humanos adicionales están justificados.
A5: UAW | B5: =IF(COUNTIF(J9:J100,"Revisar*")>0,"Revisar actores",SUM(G9:G100)) -> 75
A8: ID actor | B8: Actor | C8: Interfaz | D8: Clase | E8: Incluir | F8: Peso | G8: Aporte UAW | H8: Criterio de conteo | I8: Fuente | J8: Control
A9: A01 | B9: Preventista | C9: Gráfica | D9: =IF(C9="API","Simple",IF(C9="Protocolo","Medio",IF(C9="Gráfica","Complejo","Revisar interfaz"))) -> Complejo | E9: 1 | F9: =IF(D9="Simple",'Criterios y fuentes'!$B$25,IF(D9="Medio",'Criterios y fuentes'!$B$26,IF(D9="Complejo",'Criterios y fuentes'!$B$27,"Revisar"))) -> 3 | G9: =IF(E9=0,0,IF(J9="Válido",E9*F9,"Revisar actor")) -> 3 | H9: Rol, no 62 personas. | I9: SD3 §3.4.2 / Anexo 3.A, actores | J9: =IF(AND(ISNUMBER(E9),OR(E9=0,E9=1),COUNTIF($A$9:$A$100,A9)=1,OR(C9="API",C9="Protocolo",C9="Gráfica")),"Válido","Revisar actor") -> Válido
A10: A02 | B10: Conductor propio | C10: Gráfica | D10: =IF(C10="API","Simple",IF(C10="Protocolo","Medio",IF(C10="Gráfica","Complejo","Revisar interfaz"))) -> Complejo | E10: 1 | F10: =IF(D10="Simple",'Criterios y fuentes'!$B$25,IF(D10="Medio",'Criterios y fuentes'!$B$26,IF(D10="Complejo",'Criterios y fuentes'!$B$27,"Revisar"))) -> 3 | G10: =IF(E10=0,0,IF(J10="Válido",E10*F10,"Revisar actor")) -> 3 | H10: Mantiene rol propio del catálogo. | I10: SD3 §3.4.2 | J10: =IF(AND(ISNUMBER(E10),OR(E10=0,E10=1),COUNTIF($A$9:$A$100,A10)=1,OR(C10="API",C10="Protocolo",C10="Gráfica")),"Válido","Revisar actor") -> Válido
A11: A03 | B11: Conductor externo | C11: Gráfica | D11: =IF(C11="API","Simple",IF(C11="Protocolo","Medio",IF(C11="Gráfica","Complejo","Revisar interfaz"))) -> Complejo | E11: 1 | F11: =IF(D11="Simple",'Criterios y fuentes'!$B$25,IF(D11="Medio",'Criterios y fuentes'!$B$26,IF(D11="Complejo",'Criterios y fuentes'!$B$27,"Revisar"))) -> 3 | G11: =IF(E11=0,0,IF(J11="Válido",E11*F11,"Revisar actor")) -> 3 | H11: Rol concreto con relación externa y vigencia por turno. | I11: SD3 §3.4.2 / RF-06.08 | J11: =IF(AND(ISNUMBER(E11),OR(E11=0,E11=1),COUNTIF($A$9:$A$100,A11)=1,OR(C11="API",C11="Protocolo",C11="Gráfica")),"Válido","Revisar actor") -> Válido
A12: A04 | B12: Preparador | C12: Gráfica | D12: =IF(C12="API","Simple",IF(C12="Protocolo","Medio",IF(C12="Gráfica","Complejo","Revisar interfaz"))) -> Complejo | E12: 1 | F12: =IF(D12="Simple",'Criterios y fuentes'!$B$25,IF(D12="Medio",'Criterios y fuentes'!$B$26,IF(D12="Complejo",'Criterios y fuentes'!$B$27,"Revisar"))) -> 3 | G12: =IF(E12=0,0,IF(J12="Válido",E12*F12,"Revisar actor")) -> 3 | H12: Recepción y movimientos solo con autorización funcional. | I12: SD3 §3.4.2 | J12: =IF(AND(ISNUMBER(E12),OR(E12=0,E12=1),COUNTIF($A$9:$A$100,A12)=1,OR(C12="API",C12="Protocolo",C12="Gráfica")),"Válido","Revisar actor") -> Válido
A13: A05 | B13: Cliente del canal tradicional | C13: Gráfica | D13: =IF(C13="API","Simple",IF(C13="Protocolo","Medio",IF(C13="Gráfica","Complejo","Revisar interfaz"))) -> Complejo | E13: 1 | F13: =IF(D13="Simple",'Criterios y fuentes'!$B$25,IF(D13="Medio",'Criterios y fuentes'!$B$26,IF(D13="Complejo",'Criterios y fuentes'!$B$27,"Revisar"))) -> 3 | G13: =IF(E13=0,0,IF(J13="Válido",E13*F13,"Revisar actor")) -> 3 | H13: Incluye food service con iguales permisos. No exige dispositivo al cliente. | I13: SD3 §3.4.2 | J13: =IF(AND(ISNUMBER(E13),OR(E13=0,E13=1),COUNTIF($A$9:$A$100,A13)=1,OR(C13="API",C13="Protocolo",C13="Gráfica")),"Válido","Revisar actor") -> Válido
A14: A06 | B14: Cliente del canal moderno | C14: Gráfica | D14: =IF(C14="API","Simple",IF(C14="Protocolo","Medio",IF(C14="Gráfica","Complejo","Revisar interfaz"))) -> Complejo | E14: 1 | F14: =IF(D14="Simple",'Criterios y fuentes'!$B$25,IF(D14="Medio",'Criterios y fuentes'!$B$26,IF(D14="Complejo",'Criterios y fuentes'!$B$27,"Revisar"))) -> 3 | G14: =IF(E14=0,0,IF(J14="Válido",E14*F14,"Revisar actor")) -> 3 | H14: La identidad EDI se cuenta por separado como sistema. | I14: SD3 §3.4.2 | J14: =IF(AND(ISNUMBER(E14),OR(E14=0,E14=1),COUNTIF($A$9:$A$100,A14)=1,OR(C14="API",C14="Protocolo",C14="Gráfica")),"Válido","Revisar actor") -> Válido
A15: A07 | B15: Empresa transportista | C15: Gráfica | D15: =IF(C15="API","Simple",IF(C15="Protocolo","Medio",IF(C15="Gráfica","Complejo","Revisar interfaz"))) -> Complejo | E15: 1 | F15: =IF(D15="Simple",'Criterios y fuentes'!$B$25,IF(D15="Medio",'Criterios y fuentes'!$B$26,IF(D15="Complejo",'Criterios y fuentes'!$B$27,"Revisar"))) -> 3 | G15: =IF(E15=0,0,IF(J15="Válido",E15*F15,"Revisar actor")) -> 3 | H15: Un rol por empresa, sin multiplicar por diez empresas. | I15: SD3 §3.4.2 | J15: =IF(AND(ISNUMBER(E15),OR(E15=0,E15=1),COUNTIF($A$9:$A$100,A15)=1,OR(C15="API",C15="Protocolo",C15="Gráfica")),"Válido","Revisar actor") -> Válido
A16: A08 | B16: Proveedor | C16: Gráfica | D16: =IF(C16="API","Simple",IF(C16="Protocolo","Medio",IF(C16="Gráfica","Complejo","Revisar interfaz"))) -> Complejo | E16: 1 | F16: =IF(D16="Simple",'Criterios y fuentes'!$B$25,IF(D16="Medio",'Criterios y fuentes'!$B$26,IF(D16="Complejo",'Criterios y fuentes'!$B$27,"Revisar"))) -> 3 | G16: =IF(E16=0,0,IF(J16="Válido",E16*F16,"Revisar actor")) -> 3 | H16: Solo consulta sus documentos, sin aprobar recepción física. | I16: SD3 §3.4.2 | J16: =IF(AND(ISNUMBER(E16),OR(E16=0,E16=1),COUNTIF($A$9:$A$100,A16)=1,OR(C16="API",C16="Protocolo",C16="Gráfica")),"Válido","Revisar actor") -> Válido
A17: A09 | B17: Jefa de Calidad | C17: Gráfica | D17: =IF(C17="API","Simple",IF(C17="Protocolo","Medio",IF(C17="Gráfica","Complejo","Revisar interfaz"))) -> Complejo | E17: 1 | F17: =IF(D17="Simple",'Criterios y fuentes'!$B$25,IF(D17="Medio",'Criterios y fuentes'!$B$26,IF(D17="Complejo",'Criterios y fuentes'!$B$27,"Revisar"))) -> 3 | G17: =IF(E17=0,0,IF(J17="Válido",E17*F17,"Revisar actor")) -> 3 | H17: Decisión sanitaria separada de captura de terreno. | I17: SD3 §3.4.2 | J17: =IF(AND(ISNUMBER(E17),OR(E17=0,E17=1),COUNTIF($A$9:$A$100,A17)=1,OR(C17="API",C17="Protocolo",C17="Gráfica")),"Válido","Revisar actor") -> Válido
A18: A10 | B18: Gerente Comercial | C18: Gráfica | D18: =IF(C18="API","Simple",IF(C18="Protocolo","Medio",IF(C18="Gráfica","Complejo","Revisar interfaz"))) -> Complejo | E18: 1 | F18: =IF(D18="Simple",'Criterios y fuentes'!$B$25,IF(D18="Medio",'Criterios y fuentes'!$B$26,IF(D18="Complejo",'Criterios y fuentes'!$B$27,"Revisar"))) -> 3 | G18: =IF(E18=0,0,IF(J18="Válido",E18*F18,"Revisar actor")) -> 3 | H18: Condiciones comerciales y excepciones de canal. | I18: SD3 §3.4.2 | J18: =IF(AND(ISNUMBER(E18),OR(E18=0,E18=1),COUNTIF($A$9:$A$100,A18)=1,OR(C18="API",C18="Protocolo",C18="Gráfica")),"Válido","Revisar actor") -> Válido
A19: A11 | B19: Gerente de Finanzas | C19: Gráfica | D19: =IF(C19="API","Simple",IF(C19="Protocolo","Medio",IF(C19="Gráfica","Complejo","Revisar interfaz"))) -> Complejo | E19: 1 | F19: =IF(D19="Simple",'Criterios y fuentes'!$B$25,IF(D19="Medio",'Criterios y fuentes'!$B$26,IF(D19="Complejo",'Criterios y fuentes'!$B$27,"Revisar"))) -> 3 | G19: =IF(E19=0,0,IF(J19="Válido",E19*F19,"Revisar actor")) -> 3 | H19: Incluye función de caja habilitada; no incorpora personal nuevo a la dotación. | I19: SD3 §3.4.2 | J19: =IF(AND(ISNUMBER(E19),OR(E19=0,E19=1),COUNTIF($A$9:$A$100,A19)=1,OR(C19="API",C19="Protocolo",C19="Gráfica")),"Válido","Revisar actor") -> Válido
A20: A12 | B20: Planificador de Rutas | C20: Gráfica | D20: =IF(C20="API","Simple",IF(C20="Protocolo","Medio",IF(C20="Gráfica","Complejo","Revisar interfaz"))) -> Complejo | E20: 1 | F20: =IF(D20="Simple",'Criterios y fuentes'!$B$25,IF(D20="Medio",'Criterios y fuentes'!$B$26,IF(D20="Complejo",'Criterios y fuentes'!$B$27,"Revisar"))) -> 3 | G20: =IF(E20=0,0,IF(J20="Válido",E20*F20,"Revisar actor")) -> 3 | H20: No se cuenta un actor por vehículo. | I20: SD3 §3.4.2 | J20: =IF(AND(ISNUMBER(E20),OR(E20=0,E20=1),COUNTIF($A$9:$A$100,A20)=1,OR(C20="API",C20="Protocolo",C20="Gráfica")),"Válido","Revisar actor") -> Válido
... A40: A32 | B40: Proveedor de mapas y geocodificación | C40: API | D40: =IF(C40="API","Simple",IF(C40="Protocolo","Medio",IF(C40="Gráfica","Complejo","Revisar interfaz"))) -> Simple | E40: 1 | F40: =IF(D40="Simple",'Criterios y fuentes'!$B$25,IF(D40="Medio",'Criterios y fuentes'!$B$26,IF(D40="Complejo",'Criterios y fuentes'!$B$27,"Revisar"))) -> 1 | G40: =IF(E40=0,0,IF(J40="Válido",E40*F40,"Revisar actor")) -> 1 | H40: Se integra en planificación; optimizador propio permanece dentro de la frontera. | I40: SD4 Anexo 4-H | J40: =IF(AND(ISNUMBER(E40),OR(E40=0,E40=1),COUNTIF($A$9:$A$100,A40)=1,OR(C40="API",C40="Protocolo",C40="Gráfica")),"Válido","Revisar actor") -> Válido

Sheet Casos UUCW
A2: Peso de los casos de uso sin ajustar
A4: Clase automática: 1–3 transacciones = 5; 4–7 = 10; 8 o más = 15. Las exclusiones aportan cero.
A5: UUCW | B5: =IF(OR(COUNTIF(I9:I500,"Revisar*")>0,COUNTIF('Catalogo CU'!$G$9:$G$500,1)<>COUNTIF(D9:D500,1)),"Revisar cobertura CU",SUM(H9:H500)) -> 790
A8: ID caso | B8: Caso de uso | C8: Etapa | D8: Incluir | E8: Transacciones | F8: Complejidad | G8: Peso | H8: Aporte UUCW | I8: Control
A9: CU-001 | B9: =INDEX('Catalogo CU'!$D$9:$D$500,MATCH(A9,'Catalogo CU'!$A$9:$A$500,0)) -> Registrar recepción de proveedor | C9: =INDEX('Catalogo CU'!$C$9:$C$500,MATCH(A9,'Catalogo CU'!$A$9:$A$500,0)) -> E1 | D9: =INDEX('Catalogo CU'!$G$9:$G$500,MATCH(A9,'Catalogo CU'!$A$9:$A$500,0)) -> 1 | E9: =INDEX('Catalogo CU'!$J$9:$J$500,MATCH(A9,'Catalogo CU'!$A$9:$A$500,0)) -> 6 | F9: =IF(D9=0,"Excluido",IF(I9<>"Válido","Revisar",IF(E9<='Criterios y fuentes'!$F$25,"Simple",IF(E9<='Criterios y fuentes'!$F$26,"Medio","Complejo")))) -> Medio | G9: =IF(F9="Excluido",0,IF(F9="Simple",'Criterios y fuentes'!$G$25,IF(F9="Medio",'Criterios y fuentes'!$G$26,IF(F9="Complejo",'Criterios y fuentes'!$G$27,"Revisar")))) -> 10 | H9: =IF(D9=0,0,IF(I9="Válido",D9*G9,"Revisar CU")) -> 10 | I9: =IF(COUNTIF('Catalogo CU'!$A$9:$A$500,A9)<>1,"Revisar ID",IF(COUNTIF($A$9:$A$500,A9)<>1,"Revisar duplicado",INDEX('Catalogo CU'!$M$9:$M$500,MATCH(A9,'Catalogo CU'!$A$9:$A$500,0)))) -> Válido
A10: CU-002 | B10: =INDEX('Catalogo CU'!$D$9:$D$500,MATCH(A10,'Catalogo CU'!$A$9:$A$500,0)) -> Registrar no conformidad en recepción | C10: =INDEX('Catalogo CU'!$C$9:$C$500,MATCH(A10,'Catalogo CU'!$A$9:$A$500,0)) -> E1 | D10: =INDEX('Catalogo CU'!$G$9:$G$500,MATCH(A10,'Catalogo CU'!$A$9:$A$500,0)) -> 1 | E10: =INDEX('Catalogo CU'!$J$9:$J$500,MATCH(A10,'Catalogo CU'!$A$9:$A$500,0)) -> 4 | F10: =IF(D10=0,"Excluido",IF(I10<>"Válido","Revisar",IF(E10<='Criterios y fuentes'!$F$25,"Simple",IF(E10<='Criterios y fuentes'!$F$26,"Medio","Complejo")))) -> Medio | G10: =IF(F10="Excluido",0,IF(F10="Simple",'Criterios y fuentes'!$G$25,IF(F10="Medio",'Criterios y fuentes'!$G$26,IF(F10="Complejo",'Criterios y fuentes'!$G$27,"Revisar")))) -> 10 | H10: =IF(D10=0,0,IF(I10="Válido",D10*G10,"Revisar CU")) -> 10 | I10: =IF(COUNTIF('Catalogo CU'!$A$9:$A$500,A10)<>1,"Revisar ID",IF(COUNTIF($A$9:$A$500,A10)<>1,"Revisar duplicado",INDEX('Catalogo CU'!$M$9:$M$500,MATCH(A10,'Catalogo CU'!$A$9:$A$500,0)))) -> Válido
A11: CU-003 | B11: =INDEX('Catalogo CU'!$D$9:$D$500,MATCH(A11,'Catalogo CU'!$A$9:$A$500,0)) -> Identificar unidad logística con SSCC | C11: =INDEX('Catalogo CU'!$C$9:$C$500,MATCH(A11,'Catalogo CU'!$A$9:$A$500,0)) -> E1 | D11: =INDEX('Catalogo CU'!$G$9:$G$500,MATCH(A11,'Catalogo CU'!$A$9:$A$500,0)) -> 1 | E11: =INDEX('Catalogo CU'!$J$9:$J$500,MATCH(A11,'Catalogo CU'!$A$9:$A$500,0)) -> 3 | F11: =IF(D11=0,"Excluido",IF(I11<>"Válido","Revisar",IF(E11<='Criterios y fuentes'!$F$25,"Simple",IF(E11<='Criterios y fuentes'!$F$26,"Medio","Complejo")))) -> Simple | G11: =IF(F11="Excluido",0,IF(F11="Simple",'Criterios y fuentes'!$G$25,IF(F11="Medio",'Criterios y fuentes'!$G$26,IF(F11="Complejo",'Criterios y fuentes'!$G$27,"Revisar")))) -> 5 | H11: =IF(D11=0,0,IF(I11="Válido",D11*G11,"Revisar CU")) -> 5 | I11: =IF(COUNTIF('Catalogo CU'!$A$9:$A$500,A11)<>1,"Revisar ID",IF(COUNTIF($A$9:$A$500,A11)<>1,"Revisar duplicado",INDEX('Catalogo CU'!$M$9:$M$500,MATCH(A11,'Catalogo CU'!$A$9:$A$500,0)))) -> Válido
A12: CU-004 | B12: =INDEX('Catalogo CU'!$D$9:$D$500,MATCH(A12,'Catalogo CU'!$A$9:$A$500,0)) -> Ubicar unidad logística en bodega | C12: =INDEX('Catalogo CU'!$C$9:$C$500,MATCH(A12,'Catalogo CU'!$A$9:$A$500,0)) -> E1 | D12: =INDEX('Catalogo CU'!$G$9:$G$500,MATCH(A12,'Catalogo CU'!$A$9:$A$500,0)) -> 1 | E12: =INDEX('Catalogo CU'!$J$9:$J$500,MATCH(A12,'Catalogo CU'!$A$9:$A$500,0)) -> 3 | F12: =IF(D12=0,"Excluido",IF(I12<>"Válido","Revisar",IF(E12<='Criterios y fuentes'!$F$25,"Simple",IF(E12<='Criterios y fuentes'!$F$26,"Medio","Complejo")))) -> Simple | G12: =IF(F12="Excluido",0,IF(F12="Simple",'Criterios y fuentes'!$G$25,IF(F12="Medio",'Criterios y fuentes'!$G$26,IF(F12="Complejo",'Criterios y fuentes'!$G$27,"Revisar")))) -> 5 | H12: =IF(D12=0,0,IF(I12="Válido",D12*G12,"Revisar CU")) -> 5 | I12: =IF(COUNTIF('Catalogo CU'!$A$9:$A$500,A12)<>1,"Revisar ID",IF(COUNTIF($A$9:$A$500,A12)<>1,"Revisar duplicado",INDEX('Catalogo CU'!$M$9:$M$500,MATCH(A12,'Catalogo CU'!$A$9:$A$500,0)))) -> Válido
A13: CU-005 | B13: =INDEX('Catalogo CU'!$D$9:$D$500,MATCH(A13,'Catalogo CU'!$A$9:$A$500,0)) -> Mantener maestro de productos | C13: =INDEX('Catalogo CU'!$C$9:$C$500,MATCH(A13,'Catalogo CU'!$A$9:$A$500,0)) -> E1 | D13: =INDEX('Catalogo CU'!$G$9:$G$500,MATCH(A13,'Catalogo CU'!$A$9:$A$500,0)) -> 1 | E13: =INDEX('Catalogo CU'!$J$9:$J$500,MATCH(A13,'Catalogo CU'!$A$9:$A$500,0)) -> 5 | F13: =IF(D13=0,"Excluido",IF(I13<>"Válido","Revisar",IF(E13<='Criterios y fuentes'!$F$25,"Simple",IF(E13<='Criterios y fuentes'!$F$26,"Medio","Complejo")))) -> Medio | G13: =IF(F13="Excluido",0,IF(F13="Simple",'Criterios y fuentes'!$G$25,IF(F13="Medio",'Criterios y fuentes'!$G$26,IF(F13="Complejo",'Criterios y fuentes'!$G$27,"Revisar")))) -> 10 | H13: =IF(D13=0,0,IF(I13="Válido",D13*G13,"Revisar CU")) -> 10 | I13: =IF(COUNTIF('Catalogo CU'!$A$9:$A$500,A13)<>1,"Revisar ID",IF(COUNTIF($A$9:$A$500,A13)<>1,"Revisar duplicado",INDEX('Catalogo CU'!$M$9:$M$500,MATCH(A13,'Catalogo CU'!$A$9:$A$500,0)))) -> Válido
A14: CU-006 | B14: =INDEX('Catalogo CU'!$D$9:$D$500,MATCH(A14,'Catalogo CU'!$A$9:$A$500,0)) -> Configurar instalaciones y ubicaciones | C14: =INDEX('Catalogo CU'!$C$9:$C$500,MATCH(A14,'Catalogo CU'!$A$9:$A$500,0)) -> E1 | D14: =INDEX('Catalogo CU'!$G$9:$G$500,MATCH(A14,'Catalogo CU'!$A$9:$A$500,0)) -> 1 | E14: =INDEX('Catalogo CU'!$J$9:$J$500,MATCH(A14,'Catalogo CU'!$A$9:$A$500,0)) -> 5 | F14: =IF(D14=0,"Excluido",IF(I14<>"Válido","Revisar",IF(E14<='Criterios y fuentes'!$F$25,"Simple",IF(E14<='Criterios y fuentes'!$F$26,"Medio","Complejo")))) -> Medio | G14: =IF(F14="Excluido",0,IF(F14="Simple",'Criterios y fuentes'!$G$25,IF(F14="Medio",'Criterios y fuentes'!$G$26,IF(F14="Complejo",'Criterios y fuentes'!$G$27,"Revisar")))) -> 10 | H14: =IF(D14=0,0,IF(I14="Válido",D14*G14,"Revisar CU")) -> 10 | I14: =IF(COUNTIF('Catalogo CU'!$A$9:$A$500,A14)<>1,"Revisar ID",IF(COUNTIF($A$9:$A$500,A14)<>1,"Revisar duplicado",INDEX('Catalogo CU'!$M$9:$M$500,MATCH(A14,'Catalogo CU'!$A$9:$A$500,0)))) -> Válido
A15: CU-007 | B15: =INDEX('Catalogo CU'!$D$9:$D$500,MATCH(A15,'Catalogo CU'!$A$9:$A$500,0)) -> Consultar stock y disponibilidad | C15: =INDEX('Catalogo CU'!$C$9:$C$500,MATCH(A15,'Catalogo CU'!$A$9:$A$500,0)) -> E1 | D15: =INDEX('Catalogo CU'!$G$9:$G$500,MATCH(A15,'Catalogo CU'!$A$9:$A$500,0)) -> 1 | E15: =INDEX('Catalogo CU'!$J$9:$J$500,MATCH(A15,'Catalogo CU'!$A$9:$A$500,0)) -> 3 | F15: =IF(D15=0,"Excluido",IF(I15<>"Válido","Revisar",IF(E15<='Criterios y fuentes'!$F$25,"Simple",IF(E15<='Criterios y fuentes'!$F$26,"Medio","Complejo")))) -> Simple | G15: =IF(F15="Excluido",0,IF(F15="Simple",'Criterios y fuentes'!$G$25,IF(F15="Medio",'Criterios y fuentes'!$G$26,IF(F15="Complejo",'Criterios y fuentes'!$G$27,"Revisar")))) -> 5 | H15: =IF(D15=0,0,IF(I15="Válido",D15*G15,"Revisar CU")) -> 5 | I15: =IF(COUNTIF('Catalogo CU'!$A$9:$A$500,A15)<>1,"Revisar ID",IF(COUNTIF($A$9:$A$500,A15)<>1,"Revisar duplicado",INDEX('Catalogo CU'!$M$9:$M$500,MATCH(A15,'Catalogo CU'!$A$9:$A$500,0)))) -> Válido
A16: CU-008 | B16: =INDEX('Catalogo CU'!$D$9:$D$500,MATCH(A16,'Catalogo CU'!$A$9:$A$500,0)) -> Aprobar y ejecutar propuesta de slotting | C16: =INDEX('Catalogo CU'!$C$9:$C$500,MATCH(A16,'Catalogo CU'!$A$9:$A$500,0)) -> E1 | D16: =INDEX('Catalogo CU'!$G$9:$G$500,MATCH(A16,'Catalogo CU'!$A$9:$A$500,0)) -> 1 | E16: =INDEX('Catalogo CU'!$J$9:$J$500,MATCH(A16,'Catalogo CU'!$A$9:$A$500,0)) -> 5 | F16: =IF(D16=0,"Excluido",IF(I16<>"Válido","Revisar",IF(E16<='Criterios y fuentes'!$F$25,"Simple",IF(E16<='Criterios y fuentes'!$F$26,"Medio","Complejo")))) -> Medio | G16: =IF(F16="Excluido",0,IF(F16="Simple",'Criterios y fuentes'!$G$25,IF(F16="Medio",'Criterios y fuentes'!$G$26,IF(F16="Complejo",'Criterios y fuentes'!$G$27,"Revisar")))) -> 10 | H16: =IF(D16=0,0,IF(I16="Válido",D16*G16,"Revisar CU")) -> 10 | I16: =IF(COUNTIF('Catalogo CU'!$A$9:$A$500,A16)<>1,"Revisar ID",IF(COUNTIF($A$9:$A$500,A16)<>1,"Revisar duplicado",INDEX('Catalogo CU'!$M$9:$M$500,MATCH(A16,'Catalogo CU'!$A$9:$A$500,0)))) -> Válido
A17: CU-009 | B17: =INDEX('Catalogo CU'!$D$9:$D$500,MATCH(A17,'Catalogo CU'!$A$9:$A$500,0)) -> Realizar conteo cíclico y ajuste | C17: =INDEX('Catalogo CU'!$C$9:$C$500,MATCH(A17,'Catalogo CU'!$A$9:$A$500,0)) -> E1 | D17: =INDEX('Catalogo CU'!$G$9:$G$500,MATCH(A17,'Catalogo CU'!$A$9:$A$500,0)) -> 1 | E17: =INDEX('Catalogo CU'!$J$9:$J$500,MATCH(A17,'Catalogo CU'!$A$9:$A$500,0)) -> 6 | F17: =IF(D17=0,"Excluido",IF(I17<>"Válido","Revisar",IF(E17<='Criterios y fuentes'!$F$25,"Simple",IF(E17<='Criterios y fuentes'!$F$26,"Medio","Complejo")))) -> Medio | G17: =IF(F17="Excluido",0,IF(F17="Simple",'Criterios y fuentes'!$G$25,IF(F17="Medio",'Criterios y fuentes'!$G$26,IF(F17="Complejo",'Criterios y fuentes'!$G$27,"Revisar")))) -> 10 | H17: =IF(D17=0,0,IF(I17="Válido",D17*G17,"Revisar CU")) -> 10 | I17: =IF(COUNTIF('Catalogo CU'!$A$9:$A$500,A17)<>1,"Revisar ID",IF(COUNTIF($A$9:$A$500,A17)<>1,"Revisar duplicado",INDEX('Catalogo CU'!$M$9:$M$500,MATCH(A17,'Catalogo CU'!$A$9:$A$500,0)))) -> Válido
A18: CU-010 | B18: =INDEX('Catalogo CU'!$D$9:$D$500,MATCH(A18,'Catalogo CU'!$A$9:$A$500,0)) -> Transferir inventario entre sitios | C18: =INDEX('Catalogo CU'!$C$9:$C$500,MATCH(A18,'Catalogo CU'!$A$9:$A$500,0)) -> E1 | D18: =INDEX('Catalogo CU'!$G$9:$G$500,MATCH(A18,'Catalogo CU'!$A$9:$A$500,0)) -> 1 | E18: =INDEX('Catalogo CU'!$J$9:$J$500,MATCH(A18,'Catalogo CU'!$A$9:$A$500,0)) -> 6 | F18: =IF(D18=0,"Excluido",IF(I18<>"Válido","Revisar",IF(E18<='Criterios y fuentes'!$F$25,"Simple",IF(E18<='Criterios y fuentes'!$F$26,"Medio","Complejo")))) -> Medio | G18: =IF(F18="Excluido",0,IF(F18="Simple",'Criterios y fuentes'!$G$25,IF(F18="Medio",'Criterios y fuentes'!$G$26,IF(F18="Complejo",'Criterios y fuentes'!$G$27,"Revisar")))) -> 10 | H18: =IF(D18=0,0,IF(I18="Válido",D18*G18,"Revisar CU")) -> 10 | I18: =IF(COUNTIF('Catalogo CU'!$A$9:$A$500,A18)<>1,"Revisar ID",IF(COUNTIF($A$9:$A$500,A18)<>1,"Revisar duplicado",INDEX('Catalogo CU'!$M$9:$M$500,MATCH(A18,'Catalogo CU'!$A$9:$A$500,0)))) -> Válido
A19: CU-011 | B19: =INDEX('Catalogo CU'!$D$9:$D$500,MATCH(A19,'Catalogo CU'!$A$9:$A$500,0)) -> Consultar ocupación de bodegas | C19: =INDEX('Catalogo CU'!$C$9:$C$500,MATCH(A19,'Catalogo CU'!$A$9:$A$500,0)) -> E1 | D19: =INDEX('Catalogo CU'!$G$9:$G$500,MATCH(A19,'Catalogo CU'!$A$9:$A$500,0)) -> 1 | E19: =INDEX('Catalogo CU'!$J$9:$J$500,MATCH(A19,'Catalogo CU'!$A$9:$A$500,0)) -> 3 | F19: =IF(D19=0,"Excluido",IF(I19<>"Válido","Revisar",IF(E19<='Criterios y fuentes'!$F$25,"Simple",IF(E19<='Criterios y fuentes'!$F$26,"Medio","Complejo")))) -> Simple | G19: =IF(F19="Excluido",0,IF(F19="Simple",'Criterios y fuentes'!$G$25,IF(F19="Medio",'Criterios y fuentes'!$G$26,IF(F19="Complejo",'Criterios y fuentes'!$G$27,"Revisar")))) -> 5 | H19: =IF(D19=0,0,IF(I19="Válido",D19*G19,"Revisar CU")) -> 5 | I19: =IF(COUNTIF('Catalogo CU'!$A$9:$A$500,A19)<>1,"Revisar ID",IF(COUNTIF($A$9:$A$500,A19)<>1,"Revisar duplicado",INDEX('Catalogo CU'!$M$9:$M$500,MATCH(A19,'Catalogo CU'!$A$9:$A$500,0)))) -> Válido
A20: CU-012 | B20: =INDEX('Catalogo CU'!$D$9:$D$500,MATCH(A20,'Catalogo CU'!$A$9:$A$500,0)) -> Gestionar alertas de vencimiento en bodega | C20: =INDEX('Catalogo CU'!$C$9:$C$500,MATCH(A20,'Catalogo CU'!$A$9:$A$500,0)) -> E1 | D20: =INDEX('Catalogo CU'!$G$9:$G$500,MATCH(A20,'Catalogo CU'!$A$9:$A$500,0)) -> 1 | E20: =INDEX('Catalogo CU'!$J$9:$J$500,MATCH(A20,'Catalogo CU'!$A$9:$A$500,0)) -> 3 | F20: =IF(D20=0,"Excluido",IF(I20<>"Válido","Revisar",IF(E20<='Criterios y fuentes'!$F$25,"Simple",IF(E20<='Criterios y fuentes'!$F$26,"Medio","Complejo")))) -> Simple | G20: =IF(F20="Excluido",0,IF(F20="Simple",'Criterios y fuentes'!$G$25,IF(F20="Medio",'Criterios y fuentes'!$G$26,IF(F20="Complejo",'Criterios y fuentes'!$G$27,"Revisar")))) -> 5 | H20: =IF(D20=0,0,IF(I20="Válido",D20*G20,"Revisar CU")) -> 5 | I20: =IF(COUNTIF('Catalogo CU'!$A$9:$A$500,A20)<>1,"Revisar ID",IF(COUNTIF($A$9:$A$500,A20)<>1,"Revisar duplicado",INDEX('Catalogo CU'!$M$9:$M$500,MATCH(A20,'Catalogo CU'!$A$9:$A$500,0)))) -> Válido
... A99: CU-091 | B99: =INDEX('Catalogo CU'!$D$9:$D$500,MATCH(A99,'Catalogo CU'!$A$9:$A$500,0)) -> Clasificar información y aplicar acceso | C99: =INDEX('Catalogo CU'!$C$9:$C$500,MATCH(A99,'Catalogo CU'!$A$9:$A$500,0)) -> E1 | D99: =INDEX('Catalogo CU'!$G$9:$G$500,MATCH(A99,'Catalogo CU'!$A$9:$A$500,0)) -> 1 | E99: =INDEX('Catalogo CU'!$J$9:$J$500,MATCH(A99,'Catalogo CU'!$A$9:$A$500,0)) -> 4 | F99: =IF(D99=0,"Excluido",IF(I99<>"Válido","Revisar",IF(E99<='Criterios y fuentes'!$F$25,"Simple",IF(E99<='Criterios y fuentes'!$F$26,"Medio","Complejo")))) -> Medio | G99: =IF(F99="Excluido",0,IF(F99="Simple",'Criterios y fuentes'!$G$25,IF(F99="Medio",'Criterios y fuentes'!$G$26,IF(F99="Complejo",'Criterios y fuentes'!$G$27,"Revisar")))) -> 10 | H99: =IF(D99=0,0,IF(I99="Válido",D99*G99,"Revisar CU")) -> 10 | I99: =IF(COUNTIF('Catalogo CU'!$A$9:$A$500,A99)<>1,"Revisar ID",IF(COUNTIF($A$9:$A$500,A99)<>1,"Revisar duplicado",INDEX('Catalogo CU'!$M$9:$M$500,MATCH(A99,'Catalogo CU'!$A$9:$A$500,0)))) -> Válido

Sheet Puntos sin ajustar
A2: Puntos de casos de uso sin ajustar
A4: UUCP = UAW + UUCW. Los actores se cuentan una vez; su reparto E1/E2 es proporcional al peso funcional.
A8: Componente | B8: Total | C8: Etapa 1 | D8: Etapa 2 | E8: Criterio
A9: UAW | B9: ='Actores UAW'!B5 -> 75 | C9: =IF(AND(ISNUMBER(B9),ISNUMBER(B10),B10>0),B9*C10/B10,"Revisar alcance") -> 59.810127 | D9: =IF(AND(ISNUMBER(B9),ISNUMBER(C9)),B9-C9,"Revisar alcance") -> 15.189873 | E9: Reparto proporcional a UUCW para distribuir esfuerzo; no son actores adicionales.
A10: UUCW | B10: ='Casos UUCW'!B5 -> 790 | C10: =IF(ISNUMBER(B10),SUMIFS('Casos UUCW'!$H$9:$H$500,'Casos UUCW'!$C$9:$C$500,"E1"),"Revisar casos") -> 630 | D10: =IF(ISNUMBER(B10),SUMIFS('Casos UUCW'!$H$9:$H$500,'Casos UUCW'!$C$9:$C$500,"E2"),"Revisar casos") -> 160 | E10: Suma de aportes de casos incluidos según etapa del Catálogo.
A11: UUCP | B11: =IF(AND(ISNUMBER(B9),ISNUMBER(B10)),SUM(B9:B10),"Revisar conteo") -> 865 | C11: =IF(AND(ISNUMBER(C9),ISNUMBER(C10)),SUM(C9:C10),"Revisar conteo") -> 689.81013 | D11: =IF(AND(ISNUMBER(D9),ISNUMBER(D10)),SUM(D9:D10),"Revisar conteo") -> 175.18987 | E11: Tamaño bruto del alcance completo; etapas aditivas.

Sheet Factores tecnicos
A2: Factor de complejidad técnica
A4: Puntuaciones propuestas y justificadas. Cambie valores enteros de 0 a 5 en las celdas amarillas.
A5: TCF | B5: =IF(ISNUMBER(E5),'Criterios y fuentes'!$B$31+'Criterios y fuentes'!$B$32*E5,"Revisar puntuaciones") -> 1.255 | D5: Suma ponderada | E5: =IF(COUNTIF(H9:H21,"<>Válido")>0,"Revisar factores",SUM(E9:E21)) -> 65.5
A8: ID | B8: Factor técnico | C8: Peso | D8: Puntuación | E8: Peso × valor | F8: Justificación propuesta | G8: Referencia | H8: Control
A9: T1 | B9: Sistema distribuido | C9: 2 | D9: 5 | E9: =IF(H9="Válido",C9*D9,"Revisar valor") -> 10 | F9: Nube, cinco sitios y terminales con autoridad local y reconciliación. | G9: SD3 §§3.3–3.4; SD4 continuidad | H9: =IF(AND(ISNUMBER(D9),D9>=0,D9<=5,MOD(D9,1)=0),"Válido","Revisar puntuación") -> Válido
A10: T2 | B10: Objetivos de desempeño | C10: 1 | D10: 5 | E10: =IF(H10="Válido",C10*D10,"Revisar valor") -> 5 | F10: Hay umbrales exigibles para pedido, picking, stock y planificación en peak. | G10: SD4 dimensionamiento; SD9 pruebas | H10: =IF(AND(ISNUMBER(D10),D10>=0,D10<=5,MOD(D10,1)=0),"Válido","Revisar puntuación") -> Válido
A11: T3 | B11: Eficiencia del usuario final | C11: 1 | D11: 5 | E11: =IF(H11="Válido",C11*D11,"Revisar valor") -> 5 | F11: Picking nocturno, ventana de despacho y trabajo de campo exigen pocos pasos. | G11: SD2 problema; SD3 RF-05; SD9 | H11: =IF(AND(ISNUMBER(D11),D11>=0,D11<=5,MOD(D11,1)=0),"Válido","Revisar puntuación") -> Válido
A12: T4 | B12: Procesamiento interno complejo | C12: 1 | D12: 5 | E12: =IF(H12="Válido",C12*D12,"Revisar valor") -> 5 | F12: FEFO, reservas concurrentes, VRP, reglas sanitarias, EDI y costeo. | G12: SD3 RF; SD4 módulos; SD5 | H12: =IF(AND(ISNUMBER(D12),D12>=0,D12<=5,MOD(D12,1)=0),"Válido","Revisar puntuación") -> Válido
A13: T5 | B13: Código reutilizable | C13: 1 | D13: 3 | E13: =IF(H13="Válido",C13*D13,"Revisar valor") -> 3 | F13: Base compartida reutilizable entre módulos; no se exige producto genérico para otras empresas. | G13: SD4 base compartida | H13: =IF(AND(ISNUMBER(D13),D13>=0,D13<=5,MOD(D13,1)=0),"Válido","Revisar puntuación") -> Válido
A14: T6 | B14: Facilidad de instalación | C14: 0.5 | D14: 4 | E14: =IF(H14="Válido",C14*D14,"Revisar valor") -> 2 | F14: Olas, borde, móviles y reversión con continuidad operacional. | G14: SD4 despliegue; SD6 DevSecOps; SD7 | H14: =IF(AND(ISNUMBER(D14),D14>=0,D14<=5,MOD(D14,1)=0),"Válido","Revisar puntuación") -> Válido
A15: T7 | B15: Facilidad de uso | C15: 0.5 | D15: 5 | E15: =IF(H15="Válido",C15*D15,"Revisar valor") -> 2.5 | F15: Guantes, frío, rotación de preparadores y canal tradicional sin obligación digital. | G15: SD2; SD3 adopción; SD9 accesibilidad | H15: =IF(AND(ISNUMBER(D15),D15>=0,D15<=5,MOD(D15,1)=0),"Válido","Revisar puntuación") -> Válido
A16: T8 | B16: Portabilidad | C16: 2 | D16: 4 | E16: =IF(H16="Válido",C16*D16,"Revisar valor") -> 8 | F16: Navegadores, Android y despliegue híbrido; no se asume portabilidad ilimitada. | G16: SD4 tecnologías y sitios | H16: =IF(AND(ISNUMBER(D16),D16>=0,D16<=5,MOD(D16,1)=0),"Válido","Revisar puntuación") -> Válido
A17: T9 | B17: Facilidad de cambio | C17: 1 | D17: 5 | E17: =IF(H17="Válido",C17*D17,"Revisar valor") -> 5 | F17: Parámetros, flujos, plantillas y doble aprobación sin desarrollo. | G17: SD3 RF-17.02/03/06/09 | H17: =IF(AND(ISNUMBER(D17),D17>=0,D17<=5,MOD(D17,1)=0),"Válido","Revisar puntuación") -> Válido
A18: T10 | B18: Concurrencia | C18: 1 | D18: 5 | E18: =IF(H18="Válido",C18*D18,"Revisar valor") -> 5 | F18: Reserva central, turnos y fuentes concurrentes en peak de septiembre. | G18: SD3 RF-03.03; SD4 carga; SD5 | H18: =IF(AND(ISNUMBER(D18),D18>=0,D18<=5,MOD(D18,1)=0),"Válido","Revisar puntuación") -> Válido
A19: T11 | B19: Objetivos de seguridad | C19: 1 | D19: 5 | E19: =IF(H19="Válido",C19*D19,"Revisar valor") -> 5 | F19: SSO, MFA, segregación, auditoría y protección de datos en campo. | G19: SD3 RF-15; SD4 seguridad; SD9 | H19: =IF(AND(ISNUMBER(D19),D19>=0,D19<=5,MOD(D19,1)=0),"Válido","Revisar puntuación") -> Válido
A20: T12 | B20: Acceso de terceras partes | C20: 1 | D20: 5 | E20: =IF(H20="Válido",C20*D20,"Revisar valor") -> 5 | F20: Portales, ERP, EDI, pagos, mapas, sensores y telemetría. | G20: SD3 actores; SD4 Anexo 4-H | H20: =IF(AND(ISNUMBER(D20),D20>=0,D20<=5,MOD(D20,1)=0),"Válido","Revisar puntuación") -> Válido
A21: T13 | B21: Entrenamiento a usuarios | C21: 1 | D21: 5 | E21: =IF(H21="Válido",C21*D21,"Revisar valor") -> 5 | F21: Varios perfiles y alta rotación requieren UX y ayudas de aprendizaje; ejecución de cursos se estima aparte. | G21: SD2; SD3 §3.4.4; SD7 capacitación | H21: =IF(AND(ISNUMBER(D21),D21>=0,D21<=5,MOD(D21,1)=0),"Válido","Revisar puntuación") -> Válido

Sheet Factores ambiente
A2: Factor de ambiente del equipo
A4: Puntuaciones propuestas. E1–E6: mayor valor favorece al equipo. E7–E8 tienen peso negativo; mayor valor aumenta esfuerzo.
A5: EF | B5: =IF(ISNUMBER(E5),'Criterios y fuentes'!$B$33-'Criterios y fuentes'!$B$34*E5,"Revisar puntuaciones") -> 0.875 | D5: Suma ponderada | E5: =IF(COUNTIF(I9:I16,"<>Válido")>0,"Revisar factores",SUM(E9:E16)) -> 17.5
A6: Adversos | B6: =IF(COUNTIF(I9:I16,"<>Válido")>0,"Revisar ambiente",SUM(H9:H16)) -> 1
A8: ID | B8: Factor de ambiente | C8: Peso | D8: Puntuación | E8: Peso × valor | F8: Justificación propuesta | G8: Referencia | H8: Desfavorable | I8: Control
A9: E1 | B9: Experiencia en el modelo de proyecto | C9: 1.5 | D9: 4 | E9: =IF(I9="Válido",C9*D9,"Revisar valor") -> 6 | F9: Propuesto: la organización declara RUP iterativo y DevSecOps, con gobierno formal. | G9: SD1 gobierno; SD6 §6.2 | H9: =IF(I9<>"Válido","Revisar",IF(C9>0,IF(D9<3,1,0),IF(D9>3,1,0))) -> 0 | I9: =IF(AND(ISNUMBER(D9),D9>=0,D9<=5,MOD(D9,1)=0),"Válido","Revisar puntuación") -> Válido
A10: E2 | B10: Experiencia en el negocio | C10: 0.5 | D10: 3 | E10: =IF(I10="Válido",C10*D10,"Revisar valor") -> 1.5 | F10: Propuesto: experiencia sectorial declarada, pero debe validarse con usuarios y particularidades de Puelche. | G10: SD1 experiencia; SD2; SD3 supuestos | H10: =IF(I10<>"Válido","Revisar",IF(C10>0,IF(D10<3,1,0),IF(D10>3,1,0))) -> 0 | I10: =IF(AND(ISNUMBER(D10),D10>=0,D10<=5,MOD(D10,1)=0),"Válido","Revisar puntuación") -> Válido
A11: E3 | B11: Experiencia en orientación a objetos | C11: 1 | D11: 4 | E11: =IF(I11="Válido",C11*D11,"Revisar valor") -> 4 | F11: Propuesto: equipo especializado en PHP/Laravel y Kotlin; no existe medición individual aportada. | G11: SD1 dotación; SD4 tecnologías | H11: =IF(I11<>"Válido","Revisar",IF(C11>0,IF(D11<3,1,0),IF(D11>3,1,0))) -> 0 | I11: =IF(AND(ISNUMBER(D11),D11>=0,D11<=5,MOD(D11,1)=0),"Válido","Revisar puntuación") -> Válido
A12: E4 | B12: Capacidad del analista líder | C12: 0.5 | D12: 4 | E12: =IF(I12="Válido",C12*D12,"Revisar valor") -> 2 | F12: Propuesto: roles de arquitectura/datos identificados; validar desempeño del analista asignado. | G12: SD1 estructura; SD6; SD9 | H12: =IF(I12<>"Válido","Revisar",IF(C12>0,IF(D12<3,1,0),IF(D12>3,1,0))) -> 0 | I12: =IF(AND(ISNUMBER(D12),D12>=0,D12<=5,MOD(D12,1)=0),"Válido","Revisar puntuación") -> Válido
A13: E5 | B13: Motivación | C13: 1 | D13: 4 | E13: =IF(I13="Válido",C13*D13,"Revisar valor") -> 4 | F13: Propuesto para planificación; requiere consenso del equipo, no se presenta como dato observado. | G13: Supuesto de estimación autorizado por el usuario | H13: =IF(I13<>"Válido","Revisar",IF(C13>0,IF(D13<3,1,0),IF(D13>3,1,0))) -> 0 | I13: =IF(AND(ISNUMBER(D13),D13>=0,D13<=5,MOD(D13,1)=0),"Válido","Revisar puntuación") -> Válido
A14: E6 | B14: Estabilidad de requisitos | C14: 2 | D14: 2 | E14: =IF(I14="Válido",C14*D14,"Revisar valor") -> 4 | F14: Propuesto conservador: contratos externos, reglas térmicas y consultas pendientes pueden cambiar el alcance. | G14: SD3 supuestos y vacíos; SD8 riesgos | H14: =IF(I14<>"Válido","Revisar",IF(C14>0,IF(D14<3,1,0),IF(D14>3,1,0))) -> 1 | I14: =IF(AND(ISNUMBER(D14),D14>=0,D14<=5,MOD(D14,1)=0),"Válido","Revisar puntuación") -> Válido
A15: E7 | B15: Personal a tiempo parcial | C15: -1 | D15: 2 | E15: =IF(I15="Válido",C15*D15,"Revisar valor") -> -2 | F15: Propuesto: núcleo de construcción concentrado con especialistas compartidos y etapas solapadas; validar dedicación real. | G15: SD1 dedicaciones; SD7 T-15 | H15: =IF(I15<>"Válido","Revisar",IF(C15>0,IF(D15<3,1,0),IF(D15>3,1,0))) -> 0 | I15: =IF(AND(ISNUMBER(D15),D15>=0,D15<=5,MOD(D15,1)=0),"Válido","Revisar puntuación") -> Válido
A16: E8 | B16: Dificultad del lenguaje y herramientas | C16: -1 | D16: 2 | E16: =IF(I16="Válido",C16*D16,"Revisar valor") -> -2 | F16: Propuesto: tecnologías conocidas por la empresa; la complejidad distribuida ya se valora en TCF. | G16: SD1 PHP/Laravel/Kotlin; SD4; SD6 | H16: =IF(I16<>"Válido","Revisar",IF(C16>0,IF(D16<3,1,0),IF(D16>3,1,0))) -> 0 | I16: =IF(AND(ISNUMBER(D16),D16>=0,D16<=5,MOD(D16,1)=0),"Válido","Revisar puntuación") -> Válido

Sheet Puntos ajustados
A2: Puntos de casos de uso ajustados
A4: UCP = UUCP × TCF × EF. Se conserva precisión en las fórmulas y solo se formatea la presentación.
A8: Componente | B8: Total | C8: Etapa 1 | D8: Etapa 2 | E8: Interpretación
A9: UUCP | B9: ='Puntos sin ajustar'!B11 -> 865 | C9: ='Puntos sin ajustar'!C11 -> 689.81013 | D9: ='Puntos sin ajustar'!D11 -> 175.18987 | E9: Tamaño bruto del inventario de actores y objetivos.
A10: TCF | B10: ='Factores tecnicos'!B5 -> 1.255 | C10: ='Factores tecnicos'!B5 -> 1.255 | D10: ='Factores tecnicos'!B5 -> 1.255 | E10: Ajuste por exigencias del producto.
A11: EF | B11: ='Factores ambiente'!B5 -> 0.875 | C11: ='Factores ambiente'!B5 -> 0.875 | D11: ='Factores ambiente'!B5 -> 0.875 | E11: Ajuste por equipo y contexto.
A12: UCP | B12: =IF(AND(ISNUMBER(B9),ISNUMBER(B10),ISNUMBER(B11)),B9*B10*B11,"Revisar factores o conteo") -> 949.87812 | C12: =IF(AND(ISNUMBER(C9),ISNUMBER(C10),ISNUMBER(C11)),C9*C10*C11,"Revisar factores o conteo") -> 757.49775 | D12: =IF(AND(ISNUMBER(D9),ISNUMBER(D10),ISNUMBER(D11)),D9*D10*D11,"Revisar factores o conteo") -> 192.38038 | E12: Puntos ajustados que alimentan programación.

Sheet Esfuerzo
A2: Estimación de esfuerzo de desarrollo
A4: Lectura B del curso: UCP × CF son horas de programación; el total se obtiene dividiendo por la participación de programación.
A5: Total de desarrollo (HH) | B5: =B14 -> 47493.906
A8: Paso | B8: Valor | C8: Unidad | D8: Etapa 1 | E8: Etapa 2 | F8: Criterio
A9: Puntos ajustados | B9: ='Puntos ajustados'!B12 -> 949.87812 | C9: UCP | D9: ='Puntos ajustados'!C12 -> 757.49775 | E9: ='Puntos ajustados'!D12 -> 192.38038 | F9: Provienen de la hoja de puntos ajustados.
A10: Factores desfavorables | B10: ='Factores ambiente'!B6 -> 1 | C10: cantidad | F10: E1–E6 menores que 3; E7–E8 mayores que 3.
A11: Factor de conversión | B11: =IF(ISNUMBER(B10),IF(B10>='Criterios y fuentes'!$E$33,"Replantear",IF(B10<='Criterios y fuentes'!$E$31,'Criterios y fuentes'!$F$31,'Criterios y fuentes'!$F$32)),"Revisar ambiente") -> 20 | C11: HH/UCP | F11: Hasta 2: 20; 3–4: 28; desde 5: replantear y no emitir horas.
A12: Esfuerzo de programación | B12: =IF(AND(ISNUMBER(B9),ISNUMBER(B11)),B9*B11,IF(B11="Replantear","Replantear","Revisar entradas")) -> 18997.562 | C12: HH | D12: =IF(AND(ISNUMBER(D9),ISNUMBER($B$11)),D9*$B$11,$B$12) -> 15149.955 | E12: =IF(AND(ISNUMBER(E9),ISNUMBER($B$11)),E9*$B$11,$B$12) -> 3847.6076 | F12: Producto UCP × CF sin redondeo intermedio.
A13: Participación de programación | B13: =B22 -> 0.4 | C13: proporción | F13: Se enlaza al porcentaje editable de la actividad Programación.
A14: Esfuerzo total de desarrollo | B14: =IF(B11="Replantear","Replantear",IF(NOT(ISNUMBER(B12)),"Revisar entradas",IF(AND(COUNT(B20:B24)=5,MIN(B20:B24)>=0,MAX(B20:B24)<=1,ABS(SUM(B20:B24)-1)<0.000000001,B22>0),B12/B22,"Revisar porcentajes"))) -> 47493.906 | C14: HH | D14: =IF(AND(ISNUMBER(D12),ISNUMBER($B$14)),D12/$B$22,$B$14) -> 37874.887 | E14: =IF(AND(ISNUMBER(E12),ISNUMBER($B$14)),E12/$B$22,$B$14) -> 9619.019 | F14: Programación dividida por su participación en el total.
A15: Estado del cálculo | B15: =IF(B11="Replantear","Replantear: 5 o más factores desfavorables",IF(ISNUMBER(B14),"Calculado con valores propuestos",B14)) -> Calculado con valores propuestos | F15: Las horas no se presentan como cero cuando faltan factores o se debe replantear.
A19: Actividad | B19: Participación | C19: Horas totales | D19: Horas E1 | E19: Horas E2 | F19: Incluye
A20: Análisis | B20: 0.1 | C20: =IF(ISNUMBER($B$14),$B$14*$B20,$B$14) -> 4749.3906 | D20: =IF(ISNUMBER($D$14),$D$14*$B20,$D$14) -> 3787.4887 | E20: =IF(ISNUMBER($E$14),$E$14*$B20,$E$14) -> 961.9019 | F20: Levantamiento, casos de uso y especificación funcional.
A21: Diseño | B21: 0.2 | C21: =IF(ISNUMBER($B$14),$B$14*$B21,$B$14) -> 9498.7812 | D21: =IF(ISNUMBER($D$14),$D$14*$B21,$D$14) -> 7574.9775 | E21: =IF(ISNUMBER($E$14),$E$14*$B21,$E$14) -> 1923.8038 | F21: Arquitectura, datos, diseño detallado y experiencia de usuario.
A22: Programación | B22: 0.4 | C22: =IF(ISNUMBER($B$14),$B$14*$B22,$B$14) -> 18997.562 | D22: =IF(ISNUMBER($D$14),$D$14*$B22,$D$14) -> 15149.955 | E22: =IF(ISNUMBER($E$14),$E$14*$B22,$E$14) -> 3847.6076 | F22: Construcción, integraciones y pruebas unitarias.
A23: Pruebas | B23: 0.15 | C23: =IF(ISNUMBER($B$14),$B$14*$B23,$B$14) -> 7124.0859 | D23: =IF(ISNUMBER($D$14),$D$14*$B23,$D$14) -> 5681.2331 | E23: =IF(ISNUMBER($E$14),$E$14*$B23,$E$14) -> 1442.8528 | F23: Integración, sistema, aceptación y corrección de defectos.
A24: Sobrecarga | B24: 0.15 | C24: =IF(ISNUMBER($B$14),$B$14*$B24,$B$14) -> 7124.0859 | D24: =IF(ISNUMBER($D$14),$D$14*$B24,$D$14) -> 5681.2331 | E24: =IF(ISNUMBER($E$14),$E$14*$B24,$E$14) -> 1442.8528 | F24: Gestión, aseguramiento, documentación y coordinación del desarrollo.
A25: Total | B25: =SUM(B20:B24) -> 1 | C25: =IF(ISNUMBER($B$14),SUM(C20:C24),$B$14) -> 47493.906 | D25: =IF(ISNUMBER($B$14),SUM(D20:D24),$B$14) -> 37874.887 | E25: =IF(ISNUMBER($B$14),SUM(E20:E24),$B$14) -> 9619.019 | F25: La suma de participaciones debe ser 100 %.
A28: No incluye operación, infraestructura, migración, capacitación ejecutada ni reservas.
A30: Las actividades de desarrollo no son las etapas contractuales E1/E2. El reparto por etapa usa la regla visible en UUCP.
A32: Sin histórico medido de productividad: se utiliza la regla de conversión del PDF; las puntuaciones del equipo son propuestas.

Sheet Cobertura
A2: Cobertura de requisitos e innovaciones
A4: Control independiente: 180 requisitos de SD3 y cinco innovaciones. Los entregables o servicios se justifican sin inflar casos de uso.
A8: ID fuente | B8: Requisito u objetivo | C8: Prioridad / etapa | D8: Casos de uso | E8: Tratamiento | F8: Estado de selección | G8: Fundamento
A9: RF-01.01 | B9: El sistema debe registrar la recepción física de un proveedor validando las cantidades recibidas por SKU contra la OC y generando una alerta por cada discrepancia, sin bloquear el cierre. | C9: Crítica / E1 | D9: CU-001 | E9: Funcional | F9: =IF(AND(COUNTIF('Catalogo CU'!$A$9:$A$500,"CU-001")=1),IF(SUMIF('Catalogo CU'!$A$9:$A$500,"CU-001",'Catalogo CU'!$G$9:$G$500)=1,"Incluido",IF(SUMIF('Catalogo CU'!$A$9:$A$500,"CU-001",'Catalogo CU'!$G$9:$G$500)>0,"Parcial por selección","Fuera por selección")),"Revisar vínculo") -> Incluido | G9: Cubierto por los objetivos indicados; los pasos internos no se suman como transacciones.
A10: RF-01.02 | B10: El sistema debe exigir el número de lote del proveedor en campo estructurado para todo SKU con trazabilidad obligatoria, capturándolo por escaneo GS1 (AI 10) o ingreso manual, y bloqueando el avance si el campo está vacío. | C10: Crítica / E1 | D10: CU-001 | E10: Funcional | F10: =IF(AND(COUNTIF('Catalogo CU'!$A$9:$A$500,"CU-001")=1),IF(SUMIF('Catalogo CU'!$A$9:$A$500,"CU-001",'Catalogo CU'!$G$9:$G$500)=1,"Incluido",IF(SUMIF('Catalogo CU'!$A$9:$A$500,"CU-001",'Catalogo CU'!$G$9:$G$500)>0,"Parcial por selección","Fuera por selección")),"Revisar vínculo") -> Incluido | G10: Cubierto por los objetivos indicados; los pasos internos no se suman como transacciones.
A11: RF-01.03 | B11: El sistema debe registrar la fecha de vencimiento en formato DD/MM/AAAA para todo SKU con control de vencimiento habilitado, vinculándola al lote y a la ubicación asignada como entrada para la lógica FEFO. | C11: Crítica / E1 | D11: CU-001 | E11: Funcional | F11: =IF(AND(COUNTIF('Catalogo CU'!$A$9:$A$500,"CU-001")=1),IF(SUMIF('Catalogo CU'!$A$9:$A$500,"CU-001",'Catalogo CU'!$G$9:$G$500)=1,"Incluido",IF(SUMIF('Catalogo CU'!$A$9:$A$500,"CU-001",'Catalogo CU'!$G$9:$G$500)>0,"Parcial por selección","Fuera por selección")),"Revisar vínculo") -> Incluido | G11: Cubierto por los objetivos indicados; los pasos internos no se suman como transacciones.
